Workbook

Sheet results_v1
A1: country | B1: cluster_id | C1: M4+ | D1: M5+ | E1: M6+ | F1: M7+ | G1: M8+
A2: Japan | B2: 1 | C2: =IF(ISBLANK(VLOOKUP(A2&" "&B2,'LSP-M4'!$A$2:$D$100,4,FALSE))," ",_xlfn.IFNA(VLOOKUP(A2&" "&B2,'LSP-M4'!$A$2:$D$100,4,FALSE)," ")) -> 0.977 | D2: =IF(ISBLANK(VLOOKUP(A2&" "&B2,'LSP-M5'!$A$2:$D$100,4,FALSE))," ",_xlfn.IFNA(VLOOKUP(A2&" "&B2,'LSP-M5'!$A$2:$D$100,4,FALSE)," ")) -> 0.977 | E2: =IF(ISBLANK(VLOOKUP(A2&" "&B2,'LSP-M6'!$A$2:$D$100,4,FALSE))," ",_xlfn.IFNA(VLOOKUP(A2&" "&B2,'LSP-M6'!$A$2:$D$100,4,FALSE)," ")) -> 0.975 | F2: =IF(ISBLANK(VLOOKUP(A2&" "&B2,'LSP-M7'!$A$2:$D$100,4,FALSE))," ",_xlfn.IFNA(VLOOKUP(A2&" "&B2,'LSP-M7'!$A$2:$D$100,4,FALSE)," ")) -> 3.528 | G2: =IF(ISBLANK(VLOOKUP(A2&" "&B2,'LSP-M8'!$A$2:$D$100,4,FALSE))," ",_xlfn.IFNA(VLOOKUP(A2&" "&B2,'LSP-M8'!$A$2:$D$100,4,FALSE)," "))
A3: Japan | B3: 2 | C3: =IF(ISBLANK(VLOOKUP(A3&" "&B3,'LSP-M4'!$A$2:$D$100,4,FALSE))," ",_xlfn.IFNA(VLOOKUP(A3&" "&B3,'LSP-M4'!$A$2:$D$100,4,FALSE)," ")) -> 2.282 | D3: =IF(ISBLANK(VLOOKUP(A3&" "&B3,'LSP-M5'!$A$2:$D$100,4,FALSE))," ",_xlfn.IFNA(VLOOKUP(A3&" "&B3,'LSP-M5'!$A$2:$D$100,4,FALSE)," ")) -> 2.282 | E3: =IF(ISBLANK(VLOOKUP(A3&" "&B3,'LSP-M6'!$A$2:$D$100,4,FALSE))," ",_xlfn.IFNA(VLOOKUP(A3&" "&B3,'LSP-M6'!$A$2:$D$100,4,FALSE)," ")) -> 1.503 | F3: =IF(ISBLANK(VLOOKUP(A3&" "&B3,'LSP-M7'!$A$2:$D$100,4,FALSE))," ",_xlfn.IFNA(VLOOKUP(A3&" "&B3,'LSP-M7'!$A$2:$D$100,4,FALSE)," ")) -> 11.833 | G3: =IF(ISBLANK(VLOOKUP(A3&" "&B3,'LSP-M8'!$A$2:$D$100,4,FALSE))," ",_xlfn.IFNA(VLOOKUP(A3&" "&B3,'LSP-M8'!$A$2:$D$100,4,FALSE)," "))
A4: Japan | B4: 3 | C4: =IF(ISBLANK(VLOOKUP(A4&" "&B4,'LSP-M4'!$A$2:$D$100,4,FALSE))," ",_xlfn.IFNA(VLOOKUP(A4&" "&B4,'LSP-M4'!$A$2:$D$100,4,FALSE)," ")) -> 6.092 | D4: =IF(ISBLANK(VLOOKUP(A4&" "&B4,'LSP-M5'!$A$2:$D$100,4,FALSE))," ",_xlfn.IFNA(VLOOKUP(A4&" "&B4,'LSP-M5'!$A$2:$D$100,4,FALSE)," ")) -> 7.199 | E4: =IF(ISBLANK(VLOOKUP(A4&" "&B4,'LSP-M6'!$A$2:$D$100,4,FALSE))," ",_xlfn.IFNA(VLOOKUP(A4&" "&B4,'LSP-M6'!$A$2:$D$100,4,FALSE)," ")) | F4: =IF(ISBLANK(VLOOKUP(A4&" "&B4,'LSP-M7'!$A$2:$D$100,4,FALSE))," ",_xlfn.IFNA(VLOOKUP(A4&" "&B4,'LSP-M7'!$A$2:$D$100,4,FALSE)," ")) | G4: =IF(ISBLANK(VLOOKUP(A4&" "&B4,'LSP-M8'!$A$2:$D$100,4,FALSE))," ",_xlfn.IFNA(VLOOKUP(A4&" "&B4,'LSP-M8'!$A$2:$D$100,4,FALSE)," "))
A5: Papua New Guinea | B5: 1 | C5: =IF(ISBLANK(VLOOKUP(A5&" "&B5,'LSP-M4'!$A$2:$D$100,4,FALSE))," ",_xlfn.IFNA(VLOOKUP(A5&" "&B5,'LSP-M4'!$A$2:$D$100,4,FALSE)," ")) -> 1.528 | D5: =IF(ISBLANK(VLOOKUP(A5&" "&B5,'LSP-M5'!$A$2:$D$100,4,FALSE))," ",_xlfn.IFNA(VLOOKUP(A5&" "&B5,'LSP-M5'!$A$2:$D$100,4,FALSE)," ")) -> 1.528 | E5: =IF(ISBLANK(VLOOKUP(A5&" "&B5,'LSP-M6'!$A$2:$D$100,4,FALSE))," ",_xlfn.IFNA(VLOOKUP(A5&" "&B5,'LSP-M6'!$A$2:$D$100,4,FALSE)," ")) -> 1.528 | F5: =IF(ISBLANK(VLOOKUP(A5&" "&B5,'LSP-M7'!$A$2:$D$100,4,FALSE))," ",_xlfn.IFNA(VLOOKUP(A5&" "&B5,'LSP-M7'!$A$2:$D$100,4,FALSE)," ")) -> 2.014 | G5: =IF(ISBLANK(VLOOKUP(A5&" "&B5,'LSP-M8'!$A$2:$D$100,4,FALSE))," ",_xlfn.IFNA(VLOOKUP(A5&" "&B5,'LSP-M8'!$A$2:$D$100,4,FALSE)," "))
A6: Papua New Guinea | B6: 2 | C6: =IF(ISBLANK(VLOOKUP(A6&" "&B6,'LSP-M4'!$A$2:$D$100,4,FALSE))," ",_xlfn.IFNA(VLOOKUP(A6&" "&B6,'LSP-M4'!$A$2:$D$100,4,FALSE)," ")) -> 2.073 | D6: =IF(ISBLANK(VLOOKUP(A6&" "&B6,'LSP-M5'!$A$2:$D$100,4,FALSE))," ",_xlfn.IFNA(VLOOKUP(A6&" "&B6,'LSP-M5'!$A$2:$D$100,4,FALSE)," ")) -> 1.582 | E6: =IF(ISBLANK(VLOOKUP(A6&" "&B6,'LSP-M6'!$A$2:$D$100,4,FALSE))," ",_xlfn.IFNA(VLOOKUP(A6&" "&B6,'LSP-M6'!$A$2:$D$100,4,FALSE)," ")) -> 11.668 | F6: =IF(ISBLANK(VLOOKUP(A6&" "&B6,'LSP-M7'!$A$2:$D$100,4,FALSE))," ",_xlfn.IFNA(VLOOKUP(A6&" "&B6,'LSP-M7'!$A$2:$D$100,4,FALSE)," ")) | G6: =IF(ISBLANK(VLOOKUP(A6&" "&B6,'LSP-M8'!$A$2:$D$100,4,FALSE))," ",_xlfn.IFNA(VLOOKUP(A6&" "&B6,'LSP-M8'!$A$2:$D$100,4,FALSE)," "))
A7: Papua New Guinea | B7: 3 | C7: =IF(ISBLANK(VLOOKUP(A7&" "&B7,'LSP-M4'!$A$2:$D$100,4,FALSE))," ",_xlfn.IFNA(VLOOKUP(A7&" "&B7,'LSP-M4'!$A$2:$D$100,4,FALSE)," ")) -> 2.516 | D7: =IF(ISBLANK(VLOOKUP(A7&" "&B7,'LSP-M5'!$A$2:$D$100,4,FALSE))," ",_xlfn.IFNA(VLOOKUP(A7&" "&B7,'LSP-M5'!$A$2:$D$100,4,FALSE)," ")) -> 4.154 | E7: =IF(ISBLANK(VLOOKUP(A7&" "&B7,'LSP-M6'!$A$2:$D$100,4,FALSE))," ",_xlfn.IFNA(VLOOKUP(A7&" "&B7,'LSP-M6'!$A$2:$D$100,4,FALSE)," ")) | F7: =IF(ISBLANK(VLOOKUP(A7&" "&B7,'LSP-M7'!$A$2:$D$100,4,FALSE))," ",_xlfn.IFNA(VLOOKUP(A7&" "&B7,'LSP-M7'!$A$2:$D$100,4,FALSE)," ")) | G7: =IF(ISBLANK(VLOOKUP(A7&" "&B7,'LSP-M8'!$A$2:$D$100,4,FALSE))," ",_xlfn.IFNA(VLOOKUP(A7&" "&B7,'LSP-M8'!$A$2:$D$100,4,FALSE)," "))
A8: Philippines | B8: 1 | C8: =IF(ISBLANK(VLOOKUP(A8&" "&B8,'LSP-M4'!$A$2:$D$100,4,FALSE))," ",_xlfn.IFNA(VLOOKUP(A8&" "&B8,'LSP-M4'!$A$2:$D$100,4,FALSE)," ")) -> 1.104 | D8: =IF(ISBLANK(VLOOKUP(A8&" "&B8,'LSP-M5'!$A$2:$D$100,4,FALSE))," ",_xlfn.IFNA(VLOOKUP(A8&" "&B8,'LSP-M5'!$A$2:$D$100,4,FALSE)," ")) -> 1.104 | E8: =IF(ISBLANK(VLOOKUP(A8&" "&B8,'LSP-M6'!$A$2:$D$100,4,FALSE))," ",_xlfn.IFNA(VLOOKUP(A8&" "&B8,'LSP-M6'!$A$2:$D$100,4,FALSE)," ")) -> 2.192 | F8: =IF(ISBLANK(VLOOKUP(A8&" "&B8,'LSP-M7'!$A$2:$D$100,4,FALSE))," ",_xlfn.IFNA(VLOOKUP(A8&" "&B8,'LSP-M7'!$A$2:$D$100,4,FALSE)," ")) -> 2.965 | G8: =IF(ISBLANK(VLOOKUP(A8&" "&B8,'LSP-M8'!$A$2:$D$100,4,FALSE))," ",_xlfn.IFNA(VLOOKUP(A8&" "&B8,'LSP-M8'!$A$2:$D$100,4,FALSE)," "))
A9: Philippines | B9: 2 | C9: =IF(ISBLANK(VLOOKUP(A9&" "&B9,'LSP-M4'!$A$2:$D$100,4,FALSE))," ",_xlfn.IFNA(VLOOKUP(A9&" "&B9,'LSP-M4'!$A$2:$D$100,4,FALSE)," ")) | D9: =IF(ISBLANK(VLOOKUP(A9&" "&B9,'LSP-M5'!$A$2:$D$100,4,FALSE))," ",_xlfn.IFNA(VLOOKUP(A9&" "&B9,'LSP-M5'!$A$2:$D$100,4,FALSE)," ")) | E9: =IF(ISBLANK(VLOOKUP(A9&" "&B9,'LSP-M6'!$A$2:$D$100,4,FALSE))," ",_xlfn.IFNA(VLOOKUP(A9&" "&B9,'LSP-M6'!$A$2:$D$100,4,FALSE)," ")) | F9: =IF(ISBLANK(VLOOKUP(A9&" "&B9,'LSP-M7'!$A$2:$D$100,4,FALSE))," ",_xlfn.IFNA(VLOOKUP(A9&" "&B9,'LSP-M7'!$A$2:$D$100,4,FALSE)," ")) | G9: =IF(ISBLANK(VLOOKUP(A9&" "&B9,'LSP-M8'!$A$2:$D$100,4,FALSE))," ",_xlfn.IFNA(VLOOKUP(A9&" "&B9,'LSP-M8'!$A$2:$D$100,4,FALSE)," "))
A10: Tonga | B10: 1 | C10: =IF(ISBLANK(VLOOKUP(A10&" "&B10,'LSP-M4'!$A$2:$D$100,4,FALSE))," ",_xlfn.IFNA(VLOOKUP(A10&" "&B10,'LSP-M4'!$A$2:$D$100,4,FALSE)," ")) -> 1.004 | D10: =IF(ISBLANK(VLOOKUP(A10&" "&B10,'LSP-M5'!$A$2:$D$100,4,FALSE))," ",_xlfn.IFNA(VLOOKUP(A10&" "&B10,'LSP-M5'!$A$2:$D$100,4,FALSE)," ")) -> 1.004 | E10: =IF(ISBLANK(VLOOKUP(A10&" "&B10,'LSP-M6'!$A$2:$D$100,4,FALSE))," ",_xlfn.IFNA(VLOOKUP(A10&" "&B10,'LSP-M6'!$A$2:$D$100,4,FALSE)," ")) -> 1.004 | F10: =IF(ISBLANK(VLOOKUP(A10&" "&B10,'LSP-M7'!$A$2:$D$100,4,FALSE))," ",_xlfn.IFNA(VLOOKUP(A10&" "&B10,'LSP-M7'!$A$2:$D$100,4,FALSE)," ")) -> 3.95 | G10: =IF(ISBLANK(VLOOKUP(A10&" "&B10,'LSP-M8'!$A$2:$D$100,4,FALSE))," ",_xlfn.IFNA(VLOOKUP(A10&" "&B10,'LSP-M8'!$A$2:$D$100,4,FALSE)," "))
A11: USA | B11: 1 | C11: =IF(ISBLANK(VLOOKUP(A11&" "&B11,'LSP-M4'!$A$2:$D$100,4,FALSE))," ",_xlfn.IFNA(VLOOKUP(A11&" "&B11,'LSP-M4'!$A$2:$D$100,4,FALSE)," ")) -> 1.802 | D11: =IF(ISBLANK(VLOOKUP(A11&" "&B11,'LSP-M5'!$A$2:$D$100,4,FALSE))," ",_xlfn.IFNA(VLOOKUP(A11&" "&B11,'LSP-M5'!$A$2:$D$100,4,FALSE)," ")) -> 1.802 | E11: =IF(ISBLANK(VLOOKUP(A11&" "&B11,'LSP-M6'!$A$2:$D$100,4,FALSE))," ",_xlfn.IFNA(VLOOKUP(A11&" "&B11,'LSP-M6'!$A$2:$D$100,4,FALSE)," ")) -> 1.792 | F11: =IF(ISBLANK(VLOOKUP(A11&" "&B11,'LSP-M7'!$A$2:$D$100,4,FALSE))," ",_xlfn.IFNA(VLOOKUP(A11&" "&B11,'LSP-M7'!$A$2:$D$100,4,FALSE)," ")) -> 4.727 | G11: =IF(ISBLANK(VLOOKUP(A11&" "&B11,'LSP-M8'!$A$2:$D$100,4,FALSE))," ",_xlfn.IFNA(VLOOKUP(A11&" "&B11,'LSP-M8'!$A$2:$D$100,4,FALSE)," "))
A12: USA | B12: 2 | C12: =IF(ISBLANK(VLOOKUP(A12&" "&B12,'LSP-M4'!$A$2:$D$100,4,FALSE))," ",_xlfn.IFNA(VLOOKUP(A12&" "&B12,'LSP-M4'!$A$2:$D$100,4,FALSE)," ")) -> 1.911 | D12: =IF(ISBLANK(VLOOKUP(A12&" "&B12,'LSP-M5'!$A$2:$D$100,4,FALSE))," ",_xlfn.IFNA(VLOOKUP(A12&" "&B12,'LSP-M5'!$A$2:$D$100,4,FALSE)," ")) -> 1.35 | E12: =IF(ISBLANK(VLOOKUP(A12&" "&B12,'LSP-M6'!$A$2:$D$100,4,FALSE))," ",_xlfn.IFNA(VLOOKUP(A12&" "&B12,'LSP-M6'!$A$2:$D$100,4,FALSE)," ")) -> 2.866 | F12: =IF(ISBLANK(VLOOKUP(A12&" "&B12,'LSP-M7'!$A$2:$D$100,4,FALSE))," ",_xlfn.IFNA(VLOOKUP(A12&" "&B12,'LSP-M7'!$A$2:$D$100,4,FALSE)," ")) | G12: =IF(ISBLANK(VLOOKUP(A12&" "&B12,'LSP-M8'!$A$2:$D$100,4,FALSE))," ",_xlfn.IFNA(VLOOKUP(A12&" "&B12,'LSP-M8'!$A$2:$D$100,4,FALSE)," "))
A13: USA | B13: 3 | C13: =IF(ISBLANK(VLOOKUP(A13&" "&B13,'LSP-M4'!$A$2:$D$100,4,FALSE))," ",_xlfn.IFNA(VLOOKUP(A13&" "&B13,'LSP-M4'!$A$2:$D$100,4,FALSE)," ")) -> 1.202 | D13: =IF(ISBLANK(VLOOKUP(A13&" "&B13,'LSP-M5'!$A$2:$D$100,4,FALSE))," ",_xlfn.IFNA(VLOOKUP(A13&" "&B13,'LSP-M5'!$A$2:$D$100,4,FALSE)," ")) -> 1.967 | E13: =IF(ISBLANK(VLOOKUP(A13&" "&B13,'LSP-M6'!$A$2:$D$100,4,FALSE))," ",_xlfn.IFNA(VLOOKUP(A13&" "&B13,'LSP-M6'!$A$2:$D$100,4,FALSE)," ")) -> 4.565 | F13: =IF(ISBLANK(VLOOKUP(A13&" "&B13,'LSP-M7'!$A$2:$D$100,4,FALSE))," ",_xlfn.IFNA(VLOOKUP(A13&" "&B13,'LSP-M7'!$A$2:$D$100,4,FALSE)," ")) | G13: =IF(ISBLANK(VLOOKUP(A13&" "&B13,'LSP-M8'!$A$2:$D$100,4,FALSE))," ",_xlfn.IFNA(VLOOKUP(A13&" "&B13,'LSP-M8'!$A$2:$D$100,4,FALSE)," "))
... A69: Saint Helena | B69: 2 | C69: =IF(ISBLANK(VLOOKUP(A69&" "&B69,'LSP-M4'!$A$2:$D$100,4,FALSE))," ",_xlfn.IFNA(VLOOKUP(A69&" "&B69,'LSP-M4'!$A$2:$D$100,4,FALSE)," ")) -> 4.01 | D69: =IF(ISBLANK(VLOOKUP(A69&" "&B69,'LSP-M5'!$A$2:$D$100,4,FALSE))," ",_xlfn.IFNA(VLOOKUP(A69&" "&B69,'LSP-M5'!$A$2:$D$100,4,FALSE)," ")) -> 7.542 | E69: =IF(ISBLANK(VLOOKUP(A69&" "&B69,'LSP-M6'!$A$2:$D$100,4,FALSE))," ",_xlfn.IFNA(VLOOKUP(A69&" "&B69,'LSP-M6'!$A$2:$D$100,4,FALSE)," ")) | F69: =IF(ISBLANK(VLOOKUP(A69&" "&B69,'LSP-M7'!$A$2:$D$100,4,FALSE))," ",_xlfn.IFNA(VLOOKUP(A69&" "&B69,'LSP-M7'!$A$2:$D$100,4,FALSE)," ")) | G69: =IF(ISBLANK(VLOOKUP(A69&" "&B69,'LSP-M8'!$A$2:$D$100,4,FALSE))," ",_xlfn.IFNA(VLOOKUP(A69&" "&B69,'LSP-M8'!$A$2:$D$100,4,FALSE)," "))

Sheet LSP-M4
B1: country | C1: cluster | D1: return_p_years | E1: best_frequency | F1: best_power | G1: num_records | H1: Number of the day | I1: time_span_days
A2: =LSP_M4[[#This Row],[country]]&" "&LSP_M4[[#This Row],[cluster]] -> Japan 1 | B2: Japan | C2: 1 | D2: 0.977 | E2: 129.23585 | F2: 0.068859703 | G2: 144 | H2: 46080 | I2: 46080
A3: =LSP_M4[[#This Row],[country]]&" "&LSP_M4[[#This Row],[cluster]] -> Japan 2 | B3: Japan | C3: 2 | D3: 2.282 | E3: 54.820962 | F3: 0.068970503 | G3: 130 | H3: 45665 | I3: 45665
A4: =LSP_M4[[#This Row],[country]]&" "&LSP_M4[[#This Row],[cluster]] -> Japan 3 | B4: Japan | C4: 3 | D4: 6.092 | E4: 15.613121 | F4: 0.23497532 | G4: 28 | H4: 34716 | I4: 34716
A5: =LSP_M4[[#This Row],[country]]&" "&LSP_M4[[#This Row],[cluster]] -> Papua New Guinea 1 | B5: Papua New Guinea | C5: 1 | D5: 1.528 | E5: 82.826563 | F5: 0.069434335 | G5: 141 | H5: 46204 | I5: 46204
A6: =LSP_M4[[#This Row],[country]]&" "&LSP_M4[[#This Row],[cluster]] -> Papua New Guinea 2 | B6: Papua New Guinea | C6: 2 | D6: 2.073 | E6: 34.816961 | F6: 0.13020822 | G6: 59 | H6: 26346 | I6: 26346
A7: =LSP_M4[[#This Row],[country]]&" "&LSP_M4[[#This Row],[cluster]] -> Papua New Guinea 3 | B7: Papua New Guinea | C7: 3 | D7: 2.516 | E7: 43.218642 | F7: 0.25590255 | G7: 49 | H7: 39695 | I7: 39695
A8: =LSP_M4[[#This Row],[country]]&" "&LSP_M4[[#This Row],[cluster]] -> Philippines 1 | B8: Philippines | C8: 1 | D8: 1.104 | E8: 112.83256 | F8: 0.05045673 | G8: 145 | H8: 45466 | I8: 45466
A9: =LSP_M4[[#This Row],[country]]&" "&LSP_M4[[#This Row],[cluster]] -> Philippines 2 | B9: Philippines | C9: 2 | E9: 0 | F9: 0 | G9: 0 | H9: 0 | I9: 0
A10: =LSP_M4[[#This Row],[country]]&" "&LSP_M4[[#This Row],[cluster]] -> Tonga 1 | B10: Tonga | C10: 1 | D10: 1.004 | E10: 122.83456 | F10: 0.061804044 | G10: 130 | H10: 45005 | I10: 45005
A11: =LSP_M4[[#This Row],[country]]&" "&LSP_M4[[#This Row],[cluster]] -> USA 1 | B11: USA | C11: 1 | D11: 1.802 | E11: 69.623923 | F11: 0.063434979 | G11: 141 | H11: 45802 | I11: 45802
A12: =LSP_M4[[#This Row],[country]]&" "&LSP_M4[[#This Row],[cluster]] -> USA 2 | B12: USA | C12: 2 | D12: 1.911 | E12: 66.023203 | F12: 0.056853527 | G12: 145 | H12: 46055 | I12: 46055
A13: =LSP_M4[[#This Row],[country]]&" "&LSP_M4[[#This Row],[cluster]] -> USA 3 | B13: USA | C13: 3 | D13: 1.202 | E13: 102.83056 | F13: 0.066935602 | G13: 130 | H13: 45102 | I13: 45102
A14: =LSP_M4[[#This Row],[country]]&" "&LSP_M4[[#This Row],[cluster]] -> Mexico 1 | B14: Mexico | C14: 1 | D14: 1.479 | E14: 85.227043 | F14: 0.064883404 | G14: 127 | H14: 46003 | I14: 46003
A15: =LSP_M4[[#This Row],[country]]&" "&LSP_M4[[#This Row],[cluster]] -> Mexico 2 | B15: Mexico | C15: 2 | D15: 2.341 | E15: 52.820562 | F15: 0.082251252 | G15: 123 | H15: 45126 | I15: 45126
A16: =LSP_M4[[#This Row],[country]]&" "&LSP_M4[[#This Row],[cluster]] -> Mexico 3 | B16: Mexico | C16: 3 | D16: 3.189 | E16: 30.816161 | F16: 0.094812534 | G16: 65 | H16: 35864 | I16: 35864
A17: =LSP_M4[[#This Row],[country]]&" "&LSP_M4[[#This Row],[cluster]] -> Canada 1 | B17: Canada | C17: 1 | D17: 2.647 | E17: 43.618722 | F17: 0.093641529 | G17: 99 | H17: 42143 | I17: 42143
A18: =LSP_M4[[#This Row],[country]]&" "&LSP_M4[[#This Row],[cluster]] -> Canada 2 | B18: Canada | C18: 2 | D18: 2.442 | E18: 34.416881 | F18: 0.073945814 | G18: 47 | H18: 30678 | I18: 30678
A19: =LSP_M4[[#This Row],[country]]&" "&LSP_M4[[#This Row],[cluster]] -> Canada 3 | B19: Canada | C19: 3 | D19: 3.904 | E19: 12.41248 | F19: 0.19073075 | G19: 20 | H19: 17689 | I19: 17689
A20: =LSP_M4[[#This Row],[country]]&" "&LSP_M4[[#This Row],[cluster]] -> Guatemala 1 | B20: Guatemala | C20: 1 | D20: 1.344 | E20: 92.428484 | F20: 0.10210369 | G20: 100 | H20: 45355 | I20: 45355
A21: =LSP_M4[[#This Row],[country]]&" "&LSP_M4[[#This Row],[cluster]] -> Guatemala 2 | B21: Guatemala | C21: 2 | D21: 8.363 | E21: 13.612721 | F21: 0.30247722 | G21: 20 | H21: 41552 | I21: 41552
... A69: =LSP_M4[[#This Row],[country]]&" "&LSP_M4[[#This Row],[cluster]] -> Saint Helena 2 | B69: Saint Helena | C69: 2 | D69: 4.01 | E69: 12.812561 | F69: 0.16467058 | G69: 13 | H69: 18751 | I69: 18751

Sheet LSP-M5
B1: country | C1: cluster | D1: return_p_years | E1: best_frequency | F1: best_power | G1: num_records | H1: Number of the day | I1: time_span_days
A2: =LSP_M5[[#This Row],[country]]&" "&LSP_M5[[#This Row],[cluster]] -> Japan 1 | B2: Japan | C2: 1 | D2: 0.977 | E2: 129.23585 | F2: 0.068859703 | G2: 144 | H2: 46080 | I2: 46080
A3: =LSP_M5[[#This Row],[country]]&" "&LSP_M5[[#This Row],[cluster]] -> Japan 2 | B3: Japan | C3: 2 | D3: 2.282 | E3: 54.820962 | F3: 0.068970503 | G3: 130 | H3: 45665 | I3: 45665
A4: =LSP_M5[[#This Row],[country]]&" "&LSP_M5[[#This Row],[cluster]] -> Japan 3 | B4: Japan | C4: 3 | D4: 7.199 | E4: 13.212641 | F4: 0.29260269 | G4: 16 | H4: 34716 | I4: 34716
A5: =LSP_M5[[#This Row],[country]]&" "&LSP_M5[[#This Row],[cluster]] -> Papua New Guinea 1 | B5: Papua New Guinea | C5: 1 | D5: 1.528 | E5: 82.826563 | F5: 0.069434335 | G5: 141 | H5: 46204 | I5: 46204
A6: =LSP_M5[[#This Row],[country]]&" "&LSP_M5[[#This Row],[cluster]] -> Papua New Guinea 2 | B6: Papua New Guinea | C6: 2 | D6: 1.582 | E6: 45.619122 | F6: 0.14576775 | G6: 47 | H6: 26346 | I6: 26346
A7: =LSP_M5[[#This Row],[country]]&" "&LSP_M5[[#This Row],[cluster]] -> Papua New Guinea 3 | B7: Papua New Guinea | C7: 3 | D7: 4.154 | E7: 25.215041 | F7: 0.19903229 | G7: 33 | H7: 38230 | I7: 38230
A8: =LSP_M5[[#This Row],[country]]&" "&LSP_M5[[#This Row],[cluster]] -> Philippines 1 | B8: Philippines | C8: 1 | D8: 1.104 | E8: 112.83256 | F8: 0.05045673 | G8: 145 | H8: 45466 | I8: 45466
A9: =LSP_M5[[#This Row],[country]]&" "&LSP_M5[[#This Row],[cluster]] -> Philippines 2 | B9: Philippines | C9: 2 | E9: 0 | F9: 0 | G9: 0 | H9: 0 | I9: 0
A10: =LSP_M5[[#This Row],[country]]&" "&LSP_M5[[#This Row],[cluster]] -> Tonga 1 | B10: Tonga | C10: 1 | D10: 1.004 | E10: 122.83456 | F10: 0.061804044 | G10: 130 | H10: 45005 | I10: 45005
A11: =LSP_M5[[#This Row],[country]]&" "&LSP_M5[[#This Row],[cluster]] -> USA 1 | B11: USA | C11: 1 | D11: 1.802 | E11: 69.623923 | F11: 0.063434979 | G11: 141 | H11: 45802 | I11: 45802
A12: =LSP_M5[[#This Row],[country]]&" "&LSP_M5[[#This Row],[cluster]] -> USA 2 | B12: USA | C12: 2 | D12: 1.35 | E12: 92.828564 | F12: 0.090271669 | G12: 125 | H12: 45748 | I12: 45748
A13: =LSP_M5[[#This Row],[country]]&" "&LSP_M5[[#This Row],[cluster]] -> USA 3 | B13: USA | C13: 3 | D13: 1.967 | E13: 62.422482 | F13: 0.10440159 | G13: 74 | H13: 44821 | I13: 44821
A14: =LSP_M5[[#This Row],[country]]&" "&LSP_M5[[#This Row],[cluster]] -> Mexico 1 | B14: Mexico | C14: 1 | D14: 1.479 | E14: 85.227043 | F14: 0.064883404 | G14: 127 | H14: 46003 | I14: 46003
A15: =LSP_M5[[#This Row],[country]]&" "&LSP_M5[[#This Row],[cluster]] -> Mexico 2 | B15: Mexico | C15: 2 | D15: 1.216 | E15: 101.63032 | F15: 0.10611083 | G15: 111 | H15: 45126 | I15: 45126
A16: =LSP_M5[[#This Row],[country]]&" "&LSP_M5[[#This Row],[cluster]] -> Mexico 3 | B16: Mexico | C16: 3 | D16: 3.591 | E16: 27.215441 | F16: 0.16693909 | G16: 50 | H16: 35672 | I16: 35672
A17: =LSP_M5[[#This Row],[country]]&" "&LSP_M5[[#This Row],[cluster]] -> Canada 1 | B17: Canada | C17: 1 | D17: 2.661 | E17: 42.818562 | F17: 0.067724406 | G17: 92 | H17: 41587 | I17: 41587
A18: =LSP_M5[[#This Row],[country]]&" "&LSP_M5[[#This Row],[cluster]] -> Canada 2 | B18: Canada | C18: 2 | D18: 7.177 | E18: 10.81216 | F18: 0.27265575 | G18: 18 | H18: 28324 | I18: 28324
A19: =LSP_M5[[#This Row],[country]]&" "&LSP_M5[[#This Row],[cluster]] -> Canada 3 | B19: Canada | C19: 3 | E19: 0 | F19: 0 | G19: 0 | H19: 0 | I19: 0
A20: =LSP_M5[[#This Row],[country]]&" "&LSP_M5[[#This Row],[cluster]] -> Guatemala 1 | B20: Guatemala | C20: 1 | D20: 1.344 | E20: 92.428484 | F20: 0.10210369 | G20: 100 | H20: 45355 | I20: 45355
A21: =LSP_M5[[#This Row],[country]]&" "&LSP_M5[[#This Row],[cluster]] -> Guatemala 2 | B21: Guatemala | C21: 2 | E21: 0 | F21: 0 | G21: 0 | H21: 0 | I21: 0
A22: =LSP_M5[[#This Row],[country]]&" "&LSP_M5[[#This Row],[cluster]] -> Russia 1 | B22: Russia | C22: 1 | D22: 1.069 | E22: 117.23344 | F22: 0.06926981 | G22: 150 | H22: 45731 | I22: 45731
A23: =LSP_M5[[#This Row],[country]]&" "&LSP_M5[[#This Row],[cluster]] -> Russia 2 | B23: Russia | C23: 2 | D23: 2.072 | E23: 60.822162 | F23: 0.15231002 | G23: 66 | H23: 46002 | I23: 46002
A24: =LSP_M5[[#This Row],[country]]&" "&LSP_M5[[#This Row],[cluster]] -> Russia 3 | B24: Russia | C24: 3 | D24: 3.517 | E24: 34.016801 | F24: 0.19902629 | G24: 38 | H24: 43665 | I24: 43665
A25: =LSP_M5[[#This Row],[country]]&" "&LSP_M5[[#This Row],[cluster]] -> China 1 | B25: China | C25: 1 | D25: 2.658 | E25: 46.419282 | F25: 0.092386356 | G25: 102 | H25: 45030 | I25: 45030
A26: =LSP_M5[[#This Row],[country]]&" "&LSP_M5[[#This Row],[cluster]] -> China 2 | B26: China | C26: 2 | D26: 1.866 | E26: 58.421682 | F26: 0.10121733 | G26: 68 | H26: 39787 | I26: 39787
A27: =LSP_M5[[#This Row],[country]]&" "&LSP_M5[[#This Row],[cluster]] -> China 3 | B27: China | C27: 3 | D27: 1.832 | E27: 55.221042 | F27: 0.1454498 | G27: 62 | H27: 36934 | I27: 36934
A28: =LSP_M5[[#This Row],[country]]&" "&LSP_M5[[#This Row],[cluster]] -> India 1 | B28: India | C28: 1 | D28: 1.224 | E28: 98.029604 | F28: 0.084336018 | G28: 102 | H28: 43801 | I28: 43801
A29: =LSP_M5[[#This Row],[country]]&" "&LSP_M5[[#This Row],[cluster]] -> India 2 | B29: India | C29: 2 | D29: 1.793 | E29: 66.423283 | F29: 0.073470498 | G29: 103 | H29: 43479 | I29: 43479
A30: =LSP_M5[[#This Row],[country]]&" "&LSP_M5[[#This Row],[cluster]] -> India 3 | B30: India | C30: 3 | D30: 1.674 | E30: 72.424483 | F30: 0.09972673 | G30: 78 | H30: 44257 | I30: 44257
A31: =LSP_M5[[#This Row],[country]]&" "&LSP_M5[[#This Row],[cluster]] -> Iran 1 | B31: Iran | C31: 1 | D31: 1.585 | E31: 76.425283 | F31: 0.086415214 | G31: 115 | H31: 44209 | I31: 44209
A32: =LSP_M5[[#This Row],[country]]&" "&LSP_M5[[#This Row],[cluster]] -> Iran 2 | B32: Iran | C32: 2 | D32: 1.944 | E32: 52.420482 | F32: 0.19843609 | G32: 56 | H32: 37196 | I32: 37196
A33: =LSP_M5[[#This Row],[country]]&" "&LSP_M5[[#This Row],[cluster]] -> Iran 3 | B33: Iran | C33: 3 | D33: 3.606 | E33: 31.616321 | F33: 0.11514872 | G33: 41 | H33: 41614 | I33: 41614
... A37: =LSP_M5[[#This Row],[country]]&" "&LSP_M5[[#This Row],[cluster]] -> Dominican 1 | B37: Dominican | C37: 1 | D37: 2.263 | E37: 49.219842 | F37: 0.073807299 | G37: 73 | H37: 40659 | I37: 40659
A38: =LSP_M5[[#This Row],[country]]&" "&LSP_M5[[#This Row],[cluster]] -> Dominican 2 | B38: Dominican | C38: 2 | E38: 0 | F38: 0 | G38: 0 | H38: 0 | I38: 0
A39: =LSP_M5[[#This Row],[country]]&" "&LSP_M5[[#This Row],[cluster]] -> Chile 1 | B39: Chile | C39: 1 | D39: 1.015 | E39: 120.43408 | F39: 0.10305901 | G39: 130 | H39: 44627 | I39: 44627
A40: =LSP_M5[[#This Row],[country]]&" "&LSP_M5[[#This Row],[cluster]] -> Chile 2 | B40: Chile | C40: 2 | D40: 1.661 | E40: 55.221042 | F40: 0.097074186 | G40: 80 | H40: 33487 | I40: 33487
A41: =LSP_M5[[#This Row],[country]]&" "&LSP_M5[[#This Row],[cluster]] -> Chile 3 | B41: Chile | C41: 3 | D41: 3.194 | E41: 31.216241 | F41: 0.068395107 | G41: 68 | H41: 36395 | I41: 36395
A42: =LSP_M5[[#This Row],[country]]&" "&LSP_M5[[#This Row],[cluster]] -> Argentina 1 | B42: Argentina | C42: 1 | D42: 1.801 | E42: 58.821762 | F42: 0.14786747 | G42: 78 | H42: 38657 | I42: 38657
A43: =LSP_M5[[#This Row],[country]]&" "&LSP_M5[[#This Row],[cluster]] -> Argentina 2 | B43: Argentina | C43: 2 | D43: 2.857 | E43: 34.816961 | F43: 0.13632764 | G43: 70 | H43: 36305 | I43: 36305
...

Sheet LSP-M6
B1: country | C1: cluster | D1: return_p_years | E1: best_frequency | F1: best_power | G1: num_records | H1: Number of the day | I1: time_span_days
A2: =LSP_M6[[#This Row],[country]]&" "&LSP_M6[[#This Row],[cluster]] -> Japan 1 | B2: Japan | C2: 1 | D2: 0.975 | E2: 128.83577 | F2: 0.077680253 | G2: 141 | H2: 45867 | I2: 45867
A3: =LSP_M6[[#This Row],[country]]&" "&LSP_M6[[#This Row],[cluster]] -> Japan 2 | B3: Japan | C3: 2 | D3: 1.503 | E3: 83.226643 | F3: 0.055371909 | G3: 115 | H3: 45665 | I3: 45665
A4: =LSP_M6[[#This Row],[country]]&" "&LSP_M6[[#This Row],[cluster]] -> Japan 3 | B4: Japan | C4: 3 | E4: 0 | F4: 0 | G4: 0 | H4: 0 | I4: 0
A5: =LSP_M6[[#This Row],[country]]&" "&LSP_M6[[#This Row],[cluster]] -> Papua New Guinea 1 | B5: Papua New Guinea | C5: 1 | D5: 1.528 | E5: 82.826563 | F5: 0.069434335 | G5: 141 | H5: 46204 | I5: 46204
A6: =LSP_M6[[#This Row],[country]]&" "&LSP_M6[[#This Row],[cluster]] -> Papua New Guinea 2 | B6: Papua New Guinea | C6: 2 | D6: 11.668 | E6: 5.6111202 | F6: 0.51731189 | G6: 12 | H6: 23897 | I6: 23897
A7: =LSP_M6[[#This Row],[country]]&" "&LSP_M6[[#This Row],[cluster]] -> Papua New Guinea 3 | B7: Papua New Guinea | C7: 3 | E7: 0 | F7: 0 | G7: 0 | H7: 0 | I7: 0
A8: =LSP_M6[[#This Row],[country]]&" "&LSP_M6[[#This Row],[cluster]] -> Philippines 1 | B8: Philippines | C8: 1 | D8: 2.192 | E8: 56.821362 | F8: 0.061676909 | G8: 139 | H8: 45466 | I8: 45466
A9: =LSP_M6[[#This Row],[country]]&" "&LSP_M6[[#This Row],[cluster]] -> Tonga 1 | B9: Tonga | C9: 1 | D9: 1.004 | E9: 122.83456 | F9: 0.07849203 | G9: 125 | H9: 45005 | I9: 45005
A10: =LSP_M6[[#This Row],[country]]&" "&LSP_M6[[#This Row],[cluster]] -> USA 1 | B10: USA | C10: 1 | D10: 1.792 | E10: 70.024003 | F10: 0.069670186 | G10: 139 | H10: 45802 | I10: 45802
A11: =LSP_M6[[#This Row],[country]]&" "&LSP_M6[[#This Row],[cluster]] -> USA 2 | B11: USA | C11: 2 | D11: 2.866 | E11: 43.218642 | F11: 0.10108869 | G11: 60 | H11: 45203 | I11: 45203
A12: =LSP_M6[[#This Row],[country]]&" "&LSP_M6[[#This Row],[cluster]] -> USA 3 | B12: USA | C12: 3 | D12: 4.565 | E12: 24.814961 | F12: 0.23297315 | G12: 25 | H12: 41351 | I12: 41351
A13: =LSP_M6[[#This Row],[country]]&" "&LSP_M6[[#This Row],[cluster]] -> Mexico 1 | B13: Mexico | C13: 1 | D13: 1.472 | E13: 85.627123 | F13: 0.073344504 | G13: 110 | H13: 46003 | I13: 46003
A14: =LSP_M6[[#This Row],[country]]&" "&LSP_M6[[#This Row],[cluster]] -> Mexico 2 | B14: Mexico | C14: 2 | D14: 2.734 | E14: 45.219042 | F14: 0.086188431 | G14: 69 | H14: 45126 | I14: 45126
A15: =LSP_M6[[#This Row],[country]]&" "&LSP_M6[[#This Row],[cluster]] -> Mexico 3 | B15: Mexico | C15: 3 | E15: 0 | F15: 0 | G15: 0 | H15: 0 | I15: 0
A16: =LSP_M6[[#This Row],[country]]&" "&LSP_M6[[#This Row],[cluster]] -> Canada 1 | B16: Canada | C16: 1 | D16: 3.559 | E16: 32.016401 | F16: 0.11283282 | G16: 61 | H16: 41587 | I16: 41587
A17: =LSP_M6[[#This Row],[country]]&" "&LSP_M6[[#This Row],[cluster]] -> Canada 2 | B17: Canada | C17: 2 | E17: 0 | F17: 0 | G17: 0 | H17: 0 | I17: 0
A18: =LSP_M6[[#This Row],[country]]&" "&LSP_M6[[#This Row],[cluster]] -> Canada 3 | B18: Canada | C18: 3 | E18: 0 | F18: 0 | G18: 0 | H18: 0 | I18: 0
A19: =LSP_M6[[#This Row],[country]]&" "&LSP_M6[[#This Row],[cluster]] -> Guatemala 1 | B19: Guatemala | C19: 1 | D19: 2.73 | E19: 44.818962 | F19: 0.17939264 | G19: 50 | H19: 44654 | I19: 44654
A20: =LSP_M6[[#This Row],[country]]&" "&LSP_M6[[#This Row],[cluster]] -> Guatemala 2 | B20: Guatemala | C20: 2 | E20: 0 | F20: 0 | G20: 0 | H20: 0 | I20: 0
A21: =LSP_M6[[#This Row],[country]]&" "&LSP_M6[[#This Row],[cluster]] -> Russia 1 | B21: Russia | C21: 1 | D21: 1.069 | E21: 117.23344 | F21: 0.065989542 | G21: 146 | H21: 45731 | I21: 45731
A22: =LSP_M6[[#This Row],[country]]&" "&LSP_M6[[#This Row],[cluster]] -> Russia 2 | B22: Russia | C22: 2 | D22: 22.207 | E22: 5.6111202 | F22: 0.59985808 | G22: 13 | H22: 45482 | I22: 45482
A23: =LSP_M6[[#This Row],[country]]&" "&LSP_M6[[#This Row],[cluster]] -> Russia 3 | B23: Russia | C23: 3 | E23: 0 | F23: 0 | G23: 0 | H23: 0 | I23: 0
A24: =LSP_M6[[#This Row],[country]]&" "&LSP_M6[[#This Row],[cluster]] -> China 1 | B24: China | C24: 1 | D24: 3.006 | E24: 40.418082 | F24: 0.17126932 | G24: 44 | H24: 44348 | I24: 44348
A25: =LSP_M6[[#This Row],[country]]&" "&LSP_M6[[#This Row],[cluster]] -> China 2 | B25: China | C25: 2 | D25: 9.057 | E25: 11.61232 | F25: 0.61492703 | G25: 15 | H25: 38388 | I25: 38388
A26: =LSP_M6[[#This Row],[country]]&" "&LSP_M6[[#This Row],[cluster]] -> China 3 | B26: China | C26: 3 | D26: 8.902 | E26: 10.81216 | F26: 0.3770104 | G26: 16 | H26: 35130 | I26: 35130
A27: =LSP_M6[[#This Row],[country]]&" "&LSP_M6[[#This Row],[cluster]] -> India 1 | B27: India | C27: 1 | D27: 3.425 | E27: 32.016401 | F27: 0.18276773 | G27: 42 | H27: 40025 | I27: 40025
A28: =LSP_M6[[#This Row],[country]]&" "&LSP_M6[[#This Row],[cluster]] -> India 2 | B28: India | C28: 2 | D28: 5.972 | E28: 19.213841 | F28: 0.26895301 | G28: 33 | H28: 41879 | I28: 41879
A29: =LSP_M6[[#This Row],[country]]&" "&LSP_M6[[#This Row],[cluster]] -> India 3 | B29: India | C29: 3 | E29: 0 | F29: 0 | G29: 0 | H29: 0 | I29: 0
A30: =LSP_M6[[#This Row],[country]]&" "&LSP_M6[[#This Row],[cluster]] -> Iran 1 | B30: Iran | C30: 1 | D30: 4.196 | E30: 28.015601 | F30: 0.14533266 | G30: 39 | H30: 42907 | I30: 42907
A31: =LSP_M6[[#This Row],[country]]&" "&LSP_M6[[#This Row],[cluster]] -> Iran 2 | B31: Iran | C31: 2 | E31: 0 | F31: 0 | G31: 0 | H31: 0 | I31: 0
A32: =LSP_M6[[#This Row],[country]]&" "&LSP_M6[[#This Row],[cluster]] -> Iran 3 | B32: Iran | C32: 3 | D32: 10.657 | E32: 10.012 | F32: 0.64119043 | G32: 10 | H32: 38944 | I32: 38944
A33: =LSP_M6[[#This Row],[country]]&" "&LSP_M6[[#This Row],[cluster]] -> Nicaragua 1 | B33: Nicaragua | C33: 1 | D33: 5.686 | E33: 21.214241 | F33: 0.15077544 | G33: 53 | H33: 44025 | I33: 44025
A34: =LSP_M6[[#This Row],[country]]&" "&LSP_M6[[#This Row],[cluster]] -> El Salvador 1 | B34: El Salvador | C34: 1 | D34: 7.09 | E34: 17.613521 | F34: 0.27504798 | G34: 35 | H34: 45578 | I34: 45578
A35: =LSP_M6[[#This Row],[country]]&" "&LSP_M6[[#This Row],[cluster]] -> Costa Rica 1 | B35: Costa Rica | C35: 1 | D35: 6.094 | E35: 20.414081 | F35: 0.20150226 | G35: 45 | H35: 45404 | I35: 45404
A36: =LSP_M6[[#This Row],[country]]&" "&LSP_M6[[#This Row],[cluster]] -> Dominican 1 | B36: Dominican | C36: 1 | D36: 4.867 | E36: 18.413681 | F36: 0.20092712 | G36: 22 | H36: 32713 | I36: 32713
A37: =LSP_M6[[#This Row],[country]]&" "&LSP_M6[[#This Row],[cluster]] -> Chile 1 | B37: Chile | C37: 1 | D37: 1.012 | E37: 120.83416 | F37: 0.12147768 | G37: 123 | H37: 44627 | I37: 44627
A38: =LSP_M6[[#This Row],[country]]&" "&LSP_M6[[#This Row],[cluster]] -> Chile 2 | B38: Chile | C38: 2 | D38: 4.14 | E38: 21.614321 | F38: 0.17320662 | G38: 38 | H38: 32664 | I38: 32664
A39: =LSP_M6[[#This Row],[country]]&" "&LSP_M6[[#This Row],[cluster]] -> Chile 3 | B39: Chile | C39: 3 | E39: 0 | F39: 0 | G39: 0 | H39: 0 | I39: 0
A40: =LSP_M6[[#This Row],[country]]&" "&LSP_M6[[#This Row],[cluster]] -> Argentina 1 | B40: Argentina | C40: 1 | D40: 9.638 | E40: 10.81216 | F40: 0.22242233 | G40: 23 | H40: 38035 | I40: 38035
...

Sheet LSP-M7
B1: country | C1: cluster | D1: return_p_years | E1: best_frequency | F1: best_power | G1: num_records | H1: Number of the day | I1: time_span_days
A2: =LSP_M7[[#This Row],[country]]&" "&LSP_M7[[#This Row],[cluster]] -> Japan 1 | B2: Japan | C2: 1 | D2: 3.528 | E2: 35.617121 | F2: 0.14634547 | G2: 71 | H2: 45867 | I2: 45867
A3: =LSP_M7[[#This Row],[country]]&" "&LSP_M7[[#This Row],[cluster]] -> Japan 2 | B3: Japan | C3: 2 | D3: 11.833 | E3: 10.41208 | F3: 0.16293624 | G3: 23 | H3: 44971 | I3: 44971
A4: =LSP_M7[[#This Row],[country]]&" "&LSP_M7[[#This Row],[cluster]] -> Papua New Guinea 1 | B4: Papua New Guinea | C4: 1 | D4: 2.014 | E4: 61.222242 | F4: 0.08293788 | G4: 69 | H4: 45006 | I4: 45006
A5: =LSP_M7[[#This Row],[country]]&" "&LSP_M7[[#This Row],[cluster]] -> Philippines 1 | B5: Philippines | C5: 1 | D5: 2.965 | E5: 42.018402 | F5: 0.1136905 | G5: 64 | H5: 45466 | I5: 45466
A6: =LSP_M7[[#This Row],[country]]&" "&LSP_M7[[#This Row],[cluster]] -> Tonga 1 | B6: Tonga | C6: 1 | D6: 3.95 | E6: 31.216241 | F6: 0.28164579 | G6: 34 | H6: 45005 | I6: 45005
A7: =LSP_M7[[#This Row],[country]]&" "&LSP_M7[[#This Row],[cluster]] -> USA 1 | B7: USA | C7: 1 | D7: 4.727 | E7: 26.415281 | F7: 0.21255286 | G7: 48 | H7: 45571 | I7: 45571
A8: =LSP_M7[[#This Row],[country]]&" "&LSP_M7[[#This Row],[cluster]] -> USA 2 | B8: USA | C8: 2 | E8: 0 | F8: 0 | G8: 0 | H8: 0 | I8: 0
A9: =LSP_M7[[#This Row],[country]]&" "&LSP_M7[[#This Row],[cluster]] -> USA 3 | B9: USA | C9: 3 | E9: 0 | F9: 0 | G9: 0 | H9: 0 | I9: 0
A10: =LSP_M7[[#This Row],[country]]&" "&LSP_M7[[#This Row],[cluster]] -> Mexico 1 | B10: Mexico | C10: 1 | D10: 3.882 | E10: 31.616321 | F10: 0.15517786 | G10: 43 | H10: 44802 | I10: 44802
A11: =LSP_M7[[#This Row],[country]]&" "&LSP_M7[[#This Row],[cluster]] -> Mexico 2 | B11: Mexico | C11: 2 | E11: 0 | F11: 0 | G11: 0 | H11: 0 | I11: 0
A12: =LSP_M7[[#This Row],[country]]&" "&LSP_M7[[#This Row],[cluster]] -> Canada 1 | B12: Canada | C12: 1 | E12: 0 | F12: 0 | G12: 0 | H12: 0 | I12: 0
A13: =LSP_M7[[#This Row],[country]]&" "&LSP_M7[[#This Row],[cluster]] -> Guatemala 1 | B13: Guatemala | C13: 1 | E13: 0 | F13: 0 | G13: 0 | H13: 0 | I13: 0
A14: =LSP_M7[[#This Row],[country]]&" "&LSP_M7[[#This Row],[cluster]] -> Russia 1 | B14: Russia | C14: 1 | D14: 2.448 | E14: 50.820162 | F14: 0.15165468 | G14: 56 | H14: 45406 | I14: 45406
A15: =LSP_M7[[#This Row],[country]]&" "&LSP_M7[[#This Row],[cluster]] -> Russia 2 | B15: Russia | C15: 2 | E15: 0 | F15: 0 | G15: 0 | H15: 0 | I15: 0
A16: =LSP_M7[[#This Row],[country]]&" "&LSP_M7[[#This Row],[cluster]] -> Russia 3 | B16: Russia | C16: 3 | E16: 0 | F16: 0 | G16: 0 | H16: 0 | I16: 0
A17: =LSP_M7[[#This Row],[country]]&" "&LSP_M7[[#This Row],[cluster]] -> China 1 | B17: China | C17: 1 | E17: 0 | F17: 0 | G17: 0 | H17: 0 | I17: 0
A18: =LSP_M7[[#This Row],[country]]&" "&LSP_M7[[#This Row],[cluster]] -> China 2 | B18: China | C18: 2 | E18: 0 | F18: 0 | G18: 0 | H18: 0 | I18: 0
A19: =LSP_M7[[#This Row],[country]]&" "&LSP_M7[[#This Row],[cluster]] -> India 1 | B19: India | C19: 1 | E19: 0 | F19: 0 | G19: 0 | H19: 0 | I19: 0
A20: =LSP_M7[[#This Row],[country]]&" "&LSP_M7[[#This Row],[cluster]] -> India 2 | B20: India | C20: 2 | E20: 0 | F20: 0 | G20: 0 | H20: 0 | I20: 0
A21: =LSP_M7[[#This Row],[country]]&" "&LSP_M7[[#This Row],[cluster]] -> Iran 1 | B21: Iran | C21: 1 | E21: 0 | F21: 0 | G21: 0 | H21: 0 | I21: 0
A22: =LSP_M7[[#This Row],[country]]&" "&LSP_M7[[#This Row],[cluster]] -> Iran 2 | B22: Iran | C22: 2 | E22: 0 | F22: 0 | G22: 0 | H22: 0 | I22: 0
A23: =LSP_M7[[#This Row],[country]]&" "&LSP_M7[[#This Row],[cluster]] -> Iran 3 | B23: Iran | C23: 3 | E23: 0 | F23: 0 | G23: 1 | H23: 0 | I23: 0
A24: =LSP_M7[[#This Row],[country]]&" "&LSP_M7[[#This Row],[cluster]] -> Nicaragua 1 | B24: Nicaragua | C24: 1 | E24: 0 | F24: 0 | G24: 0 | H24: 0 | I24: 0
A25: =LSP_M7[[#This Row],[country]]&" "&LSP_M7[[#This Row],[cluster]] -> El Salvador 1 | B25: El Salvador | C25: 1 | E25: 0 | F25: 0 | G25: 0 | H25: 0 | I25: 0
A26: =LSP_M7[[#This Row],[country]]&" "&LSP_M7[[#This Row],[cluster]] -> Costa Rica 1 | B26: Costa Rica | C26: 1 | D26: 11.682 | E26: 9.6119204 | F26: 0.39001993 | G26: 11 | H26: 40984 | I26: 40984
A27: =LSP_M7[[#This Row],[country]]&" "&LSP_M7[[#This Row],[cluster]] -> Dominican 1 | B27: Dominican | C27: 1 | E27: 0 | F27: 0 | G27: 0 | H27: 0 | I27: 0
A28: =LSP_M7[[#This Row],[country]]&" "&LSP_M7[[#This Row],[cluster]] -> Chile 1 | B28: Chile | C28: 1 | D28: 3.582 | E28: 33.616721 | F28: 0.11568178 | G28: 44 | H28: 43952 | I28: 43952
A29: =LSP_M7[[#This Row],[country]]&" "&LSP_M7[[#This Row],[cluster]] -> Argentina 1 | B29: Argentina | C29: 1 | E29: 0 | F29: 0 | G29: 0 | H29: 0 | I29: 0
A30: =LSP_M7[[#This Row],[country]]&" "&LSP_M7[[#This Row],[cluster]] -> Argentina 2 | B30: Argentina | C30: 2 | E30: 0 | F30: 0 | G30: 0 | H30: 0 | I30: 0
A31: =LSP_M7[[#This Row],[country]]&" "&LSP_M7[[#This Row],[cluster]] -> Argentina 3 | B31: Argentina | C31: 3 | E31: 0 | F31: 0 | G31: 0 | H31: 0 | I31: 0
A32: =LSP_M7[[#This Row],[country]]&" "&LSP_M7[[#This Row],[cluster]] -> Peru 1 | B32: Peru | C32: 1 | D32: 3.68 | E32: 32.016401 | F32: 0.14306836 | G32: 33 | H32: 43008 | I32: 43008
A33: =LSP_M7[[#This Row],[country]]&" "&LSP_M7[[#This Row],[cluster]] -> Colombia 1 | B33: Colombia | C33: 1 | E33: 0 | F33: 0 | G33: 0 | H33: 0 | I33: 0
A34: =LSP_M7[[#This Row],[country]]&" "&LSP_M7[[#This Row],[cluster]] -> Colombia 2 | B34: Colombia | C34: 2 | E34: 0 | F34: 0 | G34: 0 | H34: 0 | I34: 0
A35: =LSP_M7[[#This Row],[country]]&" "&LSP_M7[[#This Row],[cluster]] -> Indonesia 1 | B35: Indonesia | C35: 1 | D35: 1.455 | E35: 86.827363 | F35: 0.11278463 | G35: 89 | H35: 46107 | I35: 46107
A36: =LSP_M7[[#This Row],[country]]&" "&LSP_M7[[#This Row],[cluster]] -> Timor Leste 1 | B36: Timor Leste | C36: 1 | E36: 0 | F36: 0 | G36: 0 | H36: 0 | I36: 0
A37: =LSP_M7[[#This Row],[country]]&" "&LSP_M7[[#This Row],[cluster]] -> Australia 3 | B37: Australia | C37: 3 | E37: 0 | F37: 0 | G37: 0 | H37: 0 | I37: 0
A38: =LSP_M7[[#This Row],[country]]&" "&LSP_M7[[#This Row],[cluster]] -> New Zealand 1 | B38: New Zealand | C38: 1 | D38: 3.761 | E38: 30.016001 | F38: 0.20884369 | G38: 35 | H38: 41207 | I38: 41207
A39: =LSP_M7[[#This Row],[country]]&" "&LSP_M7[[#This Row],[cluster]] -> New Zealand 2 | B39: New Zealand | C39: 2 | D39: 16.012 | E39: 4.4108802 | F39: 0.67653641 | G39: 11 | H39: 25779 | I39: 25779
A40: =LSP_M7[[#This Row],[country]]&" "&LSP_M7[[#This Row],[cluster]] -> Algeria 1 | B40: Algeria | C40: 1 | E40: 0 | F40: 0 | G40: 0 | H40: 0 | I40: 0
...

Sheet LSP-M8
B1: country | C1: cluster | D1: return_p_years | E1: best_frequency | F1: best_power | G1: num_records | H1: Number of the day | I1: time_span_days
A2: =LSP_M8[[#This Row],[country]]&" "&LSP_M8[[#This Row],[cluster]] -> Japan 1 | B2: Japan | C2: 1 | E2: 0 | F2: 0 | G2: 0 | H2: 0 | I2: 0
A3: =LSP_M8[[#This Row],[country]]&" "&LSP_M8[[#This Row],[cluster]] -> Japan 2 | B3: Japan | C3: 2 | E3: 0 | F3: 0 | G3: 0 | H3: 0 | I3: 0
A4: =LSP_M8[[#This Row],[country]]&" "&LSP_M8[[#This Row],[cluster]] -> Papua New Guinea 1 | B4: Papua New Guinea | C4: 1 | E4: 0 | F4: 0 | G4: 0 | H4: 0 | I4: 0
A5: =LSP_M8[[#This Row],[country]]&" "&LSP_M8[[#This Row],[cluster]] -> Philippines 1 | B5: Philippines | C5: 1 | E5: 0 | F5: 0 | G5: 0 | H5: 0 | I5: 0
A6: =LSP_M8[[#This Row],[country]]&" "&LSP_M8[[#This Row],[cluster]] -> Tonga 1 | B6: Tonga | C6: 1 | E6: 0 | F6: 0 | G6: 0 | H6: 0 | I6: 0
A7: =LSP_M8[[#This Row],[country]]&" "&LSP_M8[[#This Row],[cluster]] -> USA 1 | B7: USA | C7: 1 | E7: 0 | F7: 0 | G7: 0 | H7: 0 | I7: 0
A8: =LSP_M8[[#This Row],[country]]&" "&LSP_M8[[#This Row],[cluster]] -> Mexico 1 | B8: Mexico | C8: 1 | E8: 0 | F8: 0 | G8: 0 | H8: 0 | I8: 0
A9: =LSP_M8[[#This Row],[country]]&" "&LSP_M8[[#This Row],[cluster]] -> Canada 1 | B9: Canada | C9: 1 | E9: 0 | F9: 0 | G9: 0 | H9: 0 | I9: 0
A10: =LSP_M8[[#This Row],[country]]&" "&LSP_M8[[#This Row],[cluster]] -> Guatemala 1 | B10: Guatemala | C10: 1 | E10: 0 | F10: 0 | G10: 0 | H10: 0 | I10: 0
A11: =LSP_M8[[#This Row],[country]]&" "&LSP_M8[[#This Row],[cluster]] -> Russia 1 | B11: Russia | C11: 1 | E11: 0 | F11: 0 | G11: 0 | H11: 0 | I11: 0
A12: =LSP_M8[[#This Row],[country]]&" "&LSP_M8[[#This Row],[cluster]] -> China 1 | B12: China | C12: 1 | E12: 0 | F12: 0 | G12: 0 | H12: 0 | I12: 0
A13: =LSP_M8[[#This Row],[country]]&" "&LSP_M8[[#This Row],[cluster]] -> China 2 | B13: China | C13: 2 | E13: 0 | F13: 0 | G13: 0 | H13: 0 | I13: 0
... A22: =LSP_M8[[#This Row],[country]]&" "&LSP_M8[[#This Row],[cluster]] -> Dominican 1 | B22: Dominican | C22: 1 | E22: 0 | F22: 0 | G22: 0 | H22: 0 | I22: 0
A23: =LSP_M8[[#This Row],[country]]&" "&LSP_M8[[#This Row],[cluster]] -> Chile 1 | B23: Chile | C23: 1 | D23: 18.159 | E23: 6.0112002 | F23: 0.43841982 | G23: 11 | H23: 39842 | I23: 39842
A24: =LSP_M8[[#This Row],[country]]&" "&LSP_M8[[#This Row],[cluster]] -> Argentina 1 | B24: Argentina | C24: 1 | E24: 0 | F24: 0 | G24: 0 | H24: 0 | I24: 0
A25: =LSP_M8[[#This Row],[country]]&" "&LSP_M8[[#This Row],[cluster]] -> Argentina 2 | B25: Argentina | C25: 2 | E25: 0 | F25: 0 | G25: 0 | H25: 0 | I25: 0
A26: =LSP_M8[[#This Row],[country]]&" "&LSP_M8[[#This Row],[cluster]] -> Argentina 3 | B26: Argentina | C26: 3 | E26: 0 | F26: 0 | G26: 0 | H26: 0 | I26: 0
A27: =LSP_M8[[#This Row],[country]]&" "&LSP_M8[[#This Row],[cluster]] -> Peru 1 | B27: Peru | C27: 1 | E27: 0 | F27: 0 | G27: 0 | H27: 0 | I27: 0
A28: =LSP_M8[[#This Row],[country]]&" "&LSP_M8[[#This Row],[cluster]] -> Colombia 1 | B28: Colombia | C28: 1 | E28: 0 | F28: 0 | G28: 0 | H28: 0 | I28: 0
A29: =LSP_M8[[#This Row],[country]]&" "&LSP_M8[[#This Row],[cluster]] -> Colombia 2 | B29: Colombia | C29: 2 | E29: 0 | F29: 0 | G29: 0 | H29: 0 | I29: 0
A30: =LSP_M8[[#This Row],[country]]&" "&LSP_M8[[#This Row],[cluster]] -> Indonesia 1 | B30: Indonesia | C30: 1 | D30: 11.978 | E30: 8.4116803 | F30: 0.42476527 | G30: 10 | H30: 36776 | I30: 36776
A31: =LSP_M8[[#This Row],[country]]&" "&LSP_M8[[#This Row],[cluster]] -> Timor Leste 1 | B31: Timor Leste | C31: 1 | E31: 0 | F31: 0 | G31: 0 | H31: 0 | I31: 0
A32: =LSP_M8[[#This Row],[country]]&" "&LSP_M8[[#This Row],[cluster]] -> Australia 3 | B32: Australia | C32: 3 | E32: 0 | F32: 0 | G32: 0 | H32: 0 | I32: 0
A33: =LSP_M8[[#This Row],[country]]&" "&LSP_M8[[#This Row],[cluster]] -> New Zealand 1 | B33: New Zealand | C33: 1 | E33: 0 | F33: 0 | G33: 0 | H33: 0 | I33: 0
A34: =LSP_M8[[#This Row],[country]]&" "&LSP_M8[[#This Row],[cluster]] -> Algeria 1 | B34: Algeria | C34: 1 | E34: 0 | F34: 0 | G34: 0 | H34: 0 | I34: 0
A35: =LSP_M8[[#This Row],[country]]&" "&LSP_M8[[#This Row],[cluster]] -> Algeria 2 | B35: Algeria | C35: 2 | E35: 0 | F35: 0 | G35: 0 | H35: 0 | I35: 0
A36: =LSP_M8[[#This Row],[country]]&" "&LSP_M8[[#This Row],[cluster]] -> Somalia 1 | B36: Somalia | C36: 1 | E36: 0 | F36: 0 | G36: 0 | H36: 0 | I36: 0
A37: =LSP_M8[[#This Row],[country]]&" "&LSP_M8[[#This Row],[cluster]] -> Somalia 2 | B37: Somalia | C37: 2 | E37: 0 | F37: 0 | G37: 0 | H37: 0 | I37: 0
A38: =LSP_M8[[#This Row],[country]]&" "&LSP_M8[[#This Row],[cluster]] -> South Africa 1 | B38: South Africa | C38: 1 | E38: 0 | F38: 0 | G38: 0 | H38: 0 | I38: 0
A39: =LSP_M8[[#This Row],[country]]&" "&LSP_M8[[#This Row],[cluster]] -> South Africa 2 | B39: South Africa | C39: 2 | E39: 0 | F39: 0 | G39: 0 | H39: 0 | I39: 0
A40: =LSP_M8[[#This Row],[country]]&" "&LSP_M8[[#This Row],[cluster]] -> South Africa 3 | B40: South Africa | C40: 3 | E40: 0 | F40: 0 | G40: 0 | H40: 0 | I40: 0
A41: =LSP_M8[[#This Row],[country]]&" "&LSP_M8[[#This Row],[cluster]] -> Saint Helena 1 | B41: Saint Helena | C41: 1 | E41: 0 | F41: 0 | G41: 0 | H41: 0 | I41: 0

Sheet Sheet1
