Workbook

Sheet Table 7
C1: M4+ | D1: M5+ | E1: M6+ | F1: M7+ | G1: M8+
A2: Pacific Plate | B2: statistical mean | C2: =ROUND(AVERAGE('statistics-M4'!$I$2:$I$13)/365,3) -> 1.718 | D2: =ROUND(AVERAGE('statistics-M5'!$I$2:$I$13)/365,3) -> 2.193 | E2: =ROUND(AVERAGE('statistics-M6'!$I$2:$I$13)/365,3) -> 10.64 | F2: =ROUND(AVERAGE('statistics-M7'!$I$2:$I$13)/365,3) -> 2.984 | G2: =ROUND(AVERAGE('statistics-M8'!$I$2:$I$13)/365,3) -> 23.026
B3: statistical mode | C3: =ROUND(AVERAGE('statistics-M4'!$F$2:$F$13)/365,3) -> 0.646 | D3: =ROUND(AVERAGE('statistics-M5'!$F$2:$F$13)/365,3) -> 0.713 | E3: =ROUND(AVERAGE('statistics-M6'!$F$2:$F$13)/365,3) -> 6.724 | F3: =ROUND(AVERAGE('statistics-M7'!$F$2:$F$13)/365,3) -> 0.67 | G3: =ROUND(AVERAGE('statistics-M8'!$F$2:$F$13)/365,3) -> 9.585
B4: statistical median | C4: =ROUND(AVERAGE('statistics-M4'!$J$2:$J$13)/365,3) -> 1.123 | D4: =ROUND(AVERAGE('statistics-M5'!$J$2:$J$13)/365,3) -> 1.575 | E4: =ROUND(AVERAGE('statistics-M6'!$J$2:$J$13)/365,3) -> 9.165 | F4: =ROUND(AVERAGE('statistics-M7'!$J$2:$J$13)/365,3) -> 2 | G4: =ROUND(AVERAGE('statistics-M8'!$J$2:$J$13)/365,3) -> 17.24
B5: NFFT | C5: =ROUND(AVERAGE(NFFT_All!$C$2:$C$10),3) -> 1.685 | D5: =ROUND(AVERAGE(NFFT_All!$D$2:$D$10),3) -> 2.357 | E5: =ROUND(AVERAGE(NFFT_All!$E$2:$E$10),3) -> 1.988 | F5: =ROUND(AVERAGE(NFFT_All!$F$2:$F$10),3) -> 3.016 | G5: =ROUND(AVERAGE(NFFT_All!$G$2:$G$10),3) -> #DIV/0!
B6: LSP | C6: =ROUND(AVERAGE(LSP_All!$C$2:$C$10),3) -> 2.197 | D6: =ROUND(AVERAGE(LSP_All!$D$2:$D$10),3) -> 2.479 | E6: =ROUND(AVERAGE(LSP_All!$E$2:$E$10),3) -> 3.145 | F6: =ROUND(AVERAGE(LSP_All!$F$2:$F$10),3) -> 4.858 | G6: =ROUND(AVERAGE(LSP_All!$G$2:$G$10),3) -> #DIV/0!
A7: North American Plate | B7: statistical mean | C7: =ROUND(AVERAGE('statistics-M4'!$I$14:$I$25)/365,3) -> 1.735 | D7: =ROUND(AVERAGE('statistics-M5'!$I$14:$I$25)/365,3) -> 2.957 | E7: =ROUND(AVERAGE('statistics-M6'!$I$14:$I$25)/365,3) -> 8.657 | F7: =ROUND(AVERAGE('statistics-M7'!$I$14:$I$25)/365,3) -> 17.185 | G7: =ROUND(AVERAGE('statistics-M8'!$I$14:$I$25)/365,3) -> 22.498
B8: statistical mode | C8: =ROUND(AVERAGE('statistics-M4'!$F$14:$F$25)/365,3) -> 0.644 | D8: =ROUND(AVERAGE('statistics-M5'!$F$14:$F$25)/365,3) -> 0.624 | E8: =ROUND(AVERAGE('statistics-M6'!$F$14:$F$25)/365,3) -> 4.557 | F8: =ROUND(AVERAGE('statistics-M7'!$F$14:$F$25)/365,3) -> 8.783 | G8: =ROUND(AVERAGE('statistics-M8'!$F$14:$F$25)/365,3) -> 8.559
B9: statistical median | C9: =ROUND(AVERAGE('statistics-M4'!$J$14:$J$25)/365,3) -> 1.086 | D9: =ROUND(AVERAGE('statistics-M5'!$J$14:$J$25)/365,3) -> 2.072 | E9: =ROUND(AVERAGE('statistics-M6'!$J$14:$J$25)/365,3) -> 8.272 | F9: =ROUND(AVERAGE('statistics-M7'!$J$14:$J$25)/365,3) -> 15.028 | G9: =ROUND(AVERAGE('statistics-M8'!$J$14:$J$25)/365,3) -> 16.438
B10: NFFT | C10: =ROUND(AVERAGE(NFFT_All!$C$11:$C$21),3) -> 2.136 | D10: =ROUND(AVERAGE(NFFT_All!$D$11:$D$21),3) -> 2.383 | E10: =ROUND(AVERAGE(NFFT_All!$E$11:$E$21),3) -> 2.805 | F10: =ROUND(AVERAGE(NFFT_All!$F$11:$F$21),3) -> 7.293 | G10: =ROUND(AVERAGE(NFFT_All!$G$11:$G$21),3) -> #DIV/0!
B11: LSP | C11: =ROUND(AVERAGE(LSP_All!$C$11:$C$21),3) -> 2.784 | D11: =ROUND(AVERAGE(LSP_All!$D$11:$D$21),3) -> 2.51 | E11: =ROUND(AVERAGE(LSP_All!$E$11:$E$21),3) -> 2.817 | F11: =ROUND(AVERAGE(LSP_All!$F$11:$F$21),3) -> 4.305 | G11: =ROUND(AVERAGE(LSP_All!$G$11:$G$21),3) -> #DIV/0!
A12: Eurasian Plate | B12: statistical mean | C12: =ROUND(AVERAGE('statistics-M4'!$I$26:$I$37)/365,3) -> 1.393 | D12: =ROUND(AVERAGE('statistics-M5'!$I$26:$I$37)/365,3) -> 1.685 | E12: =ROUND(AVERAGE('statistics-M6'!$I$26:$I$37)/365,3) -> 7.134 | F12: =ROUND(AVERAGE('statistics-M7'!$I$26:$I$37)/365,3) -> 24.69 | G12: =ROUND(AVERAGE('statistics-M8'!$I$26:$I$37)/365,3) -> 14.754
B13: statistical mode | C13: =ROUND(AVERAGE('statistics-M4'!$F$26:$F$37)/365,3) -> 0.631 | D13: =ROUND(AVERAGE('statistics-M5'!$F$26:$F$37)/365,3) -> 0.637 | E13: =ROUND(AVERAGE('statistics-M6'!$F$26:$F$37)/365,3) -> 1.528 | F13: =ROUND(AVERAGE('statistics-M7'!$F$26:$F$37)/365,3) -> 8.331 | G13: =ROUND(AVERAGE('statistics-M8'!$F$26:$F$37)/365,3) -> 4.411
B14: statistical median | C14: =ROUND(AVERAGE('statistics-M4'!$J$26:$J$37)/365,3) -> 0.871 | D14: =ROUND(AVERAGE('statistics-M5'!$J$26:$J$37)/365,3) -> 1.014 | E14: =ROUND(AVERAGE('statistics-M6'!$J$26:$J$37)/365,3) -> 5.3 | F14: =ROUND(AVERAGE('statistics-M7'!$J$26:$J$37)/365,3) -> 21.125 | G14: =ROUND(AVERAGE('statistics-M8'!$J$26:$J$37)/365,3) -> 11.595
B15: NFFT | C15: =ROUND(AVERAGE(NFFT_All!$C$22:$C$33),3) -> 2.274 | D15: =ROUND(AVERAGE(NFFT_All!$D$22:$D$33),3) -> 2.911 | E15: =ROUND(AVERAGE(NFFT_All!$E$22:$E$33),3) -> 4.322 | F15: =ROUND(AVERAGE(NFFT_All!$F$22:$F$33),3) -> 2.488 | G15: =ROUND(AVERAGE(NFFT_All!$G$22:$G$33),3) -> #DIV/0!
B16: LSP | C16: =ROUND(AVERAGE(LSP_All!$C$22:$C$33),3) -> 1.899 | D16: =ROUND(AVERAGE(LSP_All!$D$22:$D$33),3) -> 2.07 | E16: =ROUND(AVERAGE(LSP_All!$E$22:$E$33),3) -> 7.61 | F16: =ROUND(AVERAGE(LSP_All!$F$22:$F$33),3) -> 2.448 | G16: =ROUND(AVERAGE(LSP_All!$G$22:$G$33),3) -> #DIV/0!
A17: Caribbean Plate | B17: statistical mean | C17: =ROUND(AVERAGE('statistics-M4'!$I$38:$I$45)/365,3) -> 1.842 | D17: =ROUND(AVERAGE('statistics-M5'!$I$38:$I$45)/365,3) -> 3.022 | E17: =ROUND(AVERAGE('statistics-M6'!$I$38:$I$45)/365,3) -> 3.272 | F17: =ROUND(AVERAGE('statistics-M7'!$I$38:$I$45)/365,3) -> 10.989 | G17: =ROUND(AVERAGE('statistics-M8'!$I$38:$I$45)/365,3) -> #DIV/0!
B18: statistical mode | C18: =ROUND(AVERAGE('statistics-M4'!$F$38:$F$45)/365,3) -> 0.611 | D18: =ROUND(AVERAGE('statistics-M5'!$F$38:$F$45)/365,3) -> 0.742 | E18: =ROUND(AVERAGE('statistics-M6'!$F$38:$F$45)/365,3) -> 0.697 | F18: =ROUND(AVERAGE('statistics-M7'!$F$38:$F$45)/365,3) -> 1.355 | G18: =ROUND(AVERAGE('statistics-M8'!$F$38:$F$45)/365,3) -> #DIV/0!
B19: statistical median | C19: =ROUND(AVERAGE('statistics-M4'!$J$38:$J$45)/365,3) -> 1.014 | D19: =ROUND(AVERAGE('statistics-M5'!$J$38:$J$45)/365,3) -> 2.66 | E19: =ROUND(AVERAGE('statistics-M6'!$J$38:$J$45)/365,3) -> 2.418 | F19: =ROUND(AVERAGE('statistics-M7'!$J$38:$J$45)/365,3) -> 8.34 | G19: =ROUND(AVERAGE('statistics-M8'!$J$38:$J$45)/365,3) -> #DIV/0!
B20: NFFT | C20: =ROUND(AVERAGE(NFFT_All!$C$34:$C$38),3) -> 2.42 | D20: =ROUND(AVERAGE(NFFT_All!$D$34:$D$38),3) -> 2.699 | E20: =ROUND(AVERAGE(NFFT_All!$E$34:$E$38),3) -> 3.986 | F20: =ROUND(AVERAGE(NFFT_All!$F$34:$F$38),3) -> #DIV/0! | G20: =ROUND(AVERAGE(NFFT_All!$G$34:$G$38),3) -> #DIV/0!
B21: LSP | C21: =ROUND(AVERAGE(LSP_All!$C$34:$C$38),3) -> 2.579 | D21: =ROUND(AVERAGE(LSP_All!$D$34:$D$38),3) -> 2.011 | E21: =ROUND(AVERAGE(LSP_All!$E$34:$E$38),3) -> 5.934 | F21: =ROUND(AVERAGE(LSP_All!$F$34:$F$38),3) -> 11.682 | G21: =ROUND(AVERAGE(LSP_All!$G$34:$G$38),3) -> #DIV/0!
A22: South American Plate | B22: statistical mean | C22: =ROUND(AVERAGE('statistics-M4'!$I$46:$I$57)/365,3) -> 2.225 | D22: =ROUND(AVERAGE('statistics-M5'!$I$46:$I$57)/365,3) -> 4.025 | E22: =ROUND(AVERAGE('statistics-M6'!$I$46:$I$57)/365,3) -> 4.156 | F22: =ROUND(AVERAGE('statistics-M7'!$I$46:$I$57)/365,3) -> 20.455 | G22: =ROUND(AVERAGE('statistics-M8'!$I$46:$I$57)/365,3) -> 14.234
B23: statistical mode | C23: =ROUND(AVERAGE('statistics-M4'!$F$46:$F$57)/365,3) -> 0.738 | D23: =ROUND(AVERAGE('statistics-M5'!$F$46:$F$57)/365,3) -> 0.779 | E23: =ROUND(AVERAGE('statistics-M6'!$F$46:$F$57)/365,3) -> 0.955 | F23: =ROUND(AVERAGE('statistics-M7'!$F$46:$F$57)/365,3) -> 17.139 | G23: =ROUND(AVERAGE('statistics-M8'!$F$46:$F$57)/365,3) -> 1.856
B24: statistical median | C24: =ROUND(AVERAGE('statistics-M4'!$J$46:$J$57)/365,3) -> 1.15 | D24: =ROUND(AVERAGE('statistics-M5'!$J$46:$J$57)/365,3) -> 2.251 | E24: =ROUND(AVERAGE('statistics-M6'!$J$46:$J$57)/365,3) -> 2.43 | F24: =ROUND(AVERAGE('statistics-M7'!$J$46:$J$57)/365,3) -> 19.73 | G24: =ROUND(AVERAGE('statistics-M8'!$J$46:$J$57)/365,3) -> 13.955
B25: NFFT | C25: =ROUND(AVERAGE(NFFT_All!$C$39:$C$50),3) -> 2.1 | D25: =ROUND(AVERAGE(NFFT_All!$D$39:$D$50),3) -> 2.749 | E25: =ROUND(AVERAGE(NFFT_All!$E$39:$E$50),3) -> 3.236 | F25: =ROUND(AVERAGE(NFFT_All!$F$39:$F$50),3) -> 4.883 | G25: =ROUND(AVERAGE(NFFT_All!$G$39:$G$50),3) -> #DIV/0!
B26: LSP | C26: =ROUND(AVERAGE(LSP_All!$C$39:$C$50),3) -> 3.353 | D26: =ROUND(AVERAGE(LSP_All!$D$39:$D$50),3) -> 2.415 | E26: =ROUND(AVERAGE(LSP_All!$E$39:$E$50),3) -> 4.784 | F26: =ROUND(AVERAGE(LSP_All!$F$39:$F$50),3) -> 3.631 | G26: =ROUND(AVERAGE(LSP_All!$G$39:$G$50),3) -> 18.159
A27: Indo-Australian Plate | B27: statistical mean | C27: =ROUND(AVERAGE('statistics-M4'!$I$58:$I$69)/365,3) -> 1.414 | D27: =ROUND(AVERAGE('statistics-M5'!$I$58:$I$69)/365,3) -> 1.668 | E27: =ROUND(AVERAGE('statistics-M6'!$I$58:$I$69)/365,3) -> 7.156 | F27: =ROUND(AVERAGE('statistics-M7'!$I$58:$I$69)/365,3) -> 7.852 | G27: =ROUND(AVERAGE('statistics-M8'!$I$58:$I$69)/365,3) -> 31.576
B28: statistical mode | C28: =ROUND(AVERAGE('statistics-M4'!$F$58:$F$69)/365,3) -> 0.61 | D28: =ROUND(AVERAGE('statistics-M5'!$F$58:$F$69)/365,3) -> 0.663 | E28: =ROUND(AVERAGE('statistics-M6'!$F$58:$F$69)/365,3) -> 4.149 | F28: =ROUND(AVERAGE('statistics-M7'!$F$58:$F$69)/365,3) -> 1.652 | G28: =ROUND(AVERAGE('statistics-M8'!$F$58:$F$69)/365,3) -> 23.196
B29: statistical median | C29: =ROUND(AVERAGE('statistics-M4'!$J$58:$J$69)/365,3) -> 0.953 | D29: =ROUND(AVERAGE('statistics-M5'!$J$58:$J$69)/365,3) -> 1.07 | E29: =ROUND(AVERAGE('statistics-M6'!$J$58:$J$69)/365,3) -> 6.148 | F29: =ROUND(AVERAGE('statistics-M7'!$J$58:$J$69)/365,3) -> 7.171 | G29: =ROUND(AVERAGE('statistics-M8'!$J$58:$J$69)/365,3) -> 30.41
B30: NFFT | C30: =ROUND(AVERAGE(NFFT_All!$C$51:$C$59),3) -> 2.03 | D30: =ROUND(AVERAGE(NFFT_All!$D$51:$D$59),3) -> 2.201 | E30: =ROUND(AVERAGE(NFFT_All!$E$51:$E$59),3) -> 2.844 | F30: =ROUND(AVERAGE(NFFT_All!$F$51:$F$59),3) -> 3.862 | G30: =ROUND(AVERAGE(NFFT_All!$G$51:$G$59),3) -> #DIV/0!
B31: LSP | C31: =ROUND(AVERAGE(LSP_All!$C$51:$C$59),3) -> 2.106 | D31: =ROUND(AVERAGE(LSP_All!$D$51:$D$59),3) -> 2.196 | E31: =ROUND(AVERAGE(LSP_All!$E$51:$E$59),3) -> 4.663 | F31: =ROUND(AVERAGE(LSP_All!$F$51:$F$59),3) -> 7.076 | G31: =ROUND(AVERAGE(LSP_All!$G$51:$G$59),3) -> 11.978
A32: African Plate | B32: statistical mean | C32: =ROUND(AVERAGE('statistics-M4'!$I$70:$I$80)/365,3) -> 2.45 | D32: =ROUND(AVERAGE('statistics-M5'!$I$70:$I$80)/365,3) -> 4.454 | E32: =ROUND(AVERAGE('statistics-M6'!$I$70:$I$80)/365,3) -> 13.791 | F32: =ROUND(AVERAGE('statistics-M7'!$I$70:$I$80)/365,3) -> #DIV/0! | G32: =ROUND(AVERAGE('statistics-M8'!$I$70:$I$80)/365,3) -> #DIV/0!
B33: statistical mode | C33: =ROUND(AVERAGE('statistics-M4'!$F$70:$F$80)/365,3) -> 0.626 | D33: =ROUND(AVERAGE('statistics-M5'!$F$70:$F$80)/365,3) -> 0.781 | E33: =ROUND(AVERAGE('statistics-M6'!$F$70:$F$80)/365,3) -> 4.335 | F33: =ROUND(AVERAGE('statistics-M7'!$F$70:$F$80)/365,3) -> #DIV/0! | G33: =ROUND(AVERAGE('statistics-M8'!$F$70:$F$80)/365,3) -> #DIV/0!
B34: statistical median | C34: =ROUND(AVERAGE('statistics-M4'!$J$70:$J$80)/365,3) -> 1.438 | D34: =ROUND(AVERAGE('statistics-M5'!$J$70:$J$80)/365,3) -> 2.603 | E34: =ROUND(AVERAGE('statistics-M6'!$J$70:$J$80)/365,3) -> 11.581 | F34: =ROUND(AVERAGE('statistics-M7'!$J$70:$J$80)/365,3) -> #DIV/0! | G34: =ROUND(AVERAGE('statistics-M8'!$J$70:$J$80)/365,3) -> #DIV/0!
B35: NFFT | C35: =ROUND(AVERAGE(NFFT_All!$C$60:$C$69),3) -> 2.133 | D35: =ROUND(AVERAGE(NFFT_All!$D$60:$D$69),3) -> 1.766 | E35: =ROUND(AVERAGE(NFFT_All!$E$60:$E$69),3) -> #DIV/0! | F35: =ROUND(AVERAGE(NFFT_All!$F$60:$F$69),3) -> #DIV/0! | G35: =ROUND(AVERAGE(NFFT_All!$G$60:$G$69),3) -> #DIV/0!
B36: LSP | C36: =ROUND(AVERAGE(LSP_All!$C$60:$C$69),3) -> 3.927 | D36: =ROUND(AVERAGE(LSP_All!$D$60:$D$69),3) -> 5.456 | E36: =ROUND(AVERAGE(LSP_All!$E$60:$E$69),3) -> #DIV/0! | F36: =ROUND(AVERAGE(LSP_All!$F$60:$F$69),3) -> #DIV/0! | G36: =ROUND(AVERAGE(LSP_All!$G$60:$G$69),3) -> #DIV/0!

Sheet LSP_All
A1: country | B1: cluster_id | C1: M4+ | D1: M5+ | E1: M6+ | F1: M7+ | G1: M8+ | I1: M4-LSP-mean | J1: M5-LSP-mean | K1: M6-LSP-mean | L1: M7-LSP-mean | M1: M8-LSP-mean | O1: M4-LSP-mode | P1: M5-LSP-mode | Q1: M6-LSP-mode | R1: M7-LSP-mode | S1: M8-LSP-mode | U1: M4-LSP-med | V1: M5-LSP-med | W1: M6-LSP-med | X1: M7-LSP-med | Y1: M8-LSP-med
A2: Japan | B2: 1 | C2: 0.977 | D2: 0.977 | E2: 0.975 | F2: 3.528 | I2: =IF(ISBLANK(LSP_All[[#This Row],[M4+]]),"",ABS(LSP_All[[#This Row],[M4+]]-(statistics_M4[[#This Row],[mean_gap]]/365))) -> 0.094156816 | J2: =IF(ISBLANK(LSP_All[[#This Row],[M5+]]),"",ABS(LSP_All[[#This Row],[M5+]]-(statistics_M5[[#This Row],[mean_gap]]/365))) -> 0.094156816 | K2: =IF(ISBLANK(LSP_All[[#This Row],[M6+]]),"",ABS(LSP_All[[#This Row],[M6+]]-(statistics_M6[[#This Row],[mean_gap]]/365))) -> 0.077407045 | L2: =IF(ISBLANK(LSP_All[[#This Row],[M7+]]),"",ABS(LSP_All[[#This Row],[M7+]]-(statistics_M7[[#This Row],[mean_gap]]/365))) -> 1.7328141 | M2: =IF(ISBLANK(LSP_All[[#This Row],[M8+]]),"",ABS(LSP_All[[#This Row],[M8+]]-(statistics_M8[[#This Row],[mean_gap]]/365))) | O2: =IF(ISBLANK(LSP_All[[#This Row],[M4+]]),"",ABS(LSP_All[[#This Row],[M4+]]-(statistics_M4[[#This Row],[exact_mode]]/365))) -> 0.44549315 | P2: =IF(ISBLANK(LSP_All[[#This Row],[M5+]]),"",ABS(LSP_All[[#This Row],[M5+]]-(statistics_M5[[#This Row],[exact_mode]]/365))) -> 0.44549315 | Q2: =IF(ISBLANK(LSP_All[[#This Row],[M6+]]),"",ABS(LSP_All[[#This Row],[M6+]]-(statistics_M6[[#This Row],[exact_mode]]/365))) -> 0.44349315 | R2: =IF(ISBLANK(LSP_All[[#This Row],[M7+]]),"",ABS(LSP_All[[#This Row],[M7+]]-(statistics_M7[[#This Row],[exact_mode]]/365))) -> 2.9937534 | S2: =IF(ISBLANK(LSP_All[[#This Row],[M8+]]),"",ABS(LSP_All[[#This Row],[M8+]]-(statistics_M8[[#This Row],[exact_mode]]/365))) | U2: =IF(ISBLANK(LSP_All[[#This Row],[M4+]]),"",ABS(LSP_All[[#This Row],[M4+]]-(statistics_M4[[#This Row],[median_gap]]/365))) -> 0.1660411 | V2: =IF(ISBLANK(LSP_All[[#This Row],[M5+]]),"",ABS(LSP_All[[#This Row],[M5+]]-(statistics_M5[[#This Row],[median_gap]]/365))) -> 0.1660411 | W2: =IF(ISBLANK(LSP_All[[#This Row],[M6+]]),"",ABS(LSP_All[[#This Row],[M6+]]-(statistics_M6[[#This Row],[median_gap]]/365))) -> 0.15034247 | X2: =IF(ISBLANK(LSP_All[[#This Row],[M7+]]),"",ABS(LSP_All[[#This Row],[M7+]]-(statistics_M7[[#This Row],[median_gap]]/365))) -> 2.2293699 | Y2: =IF(ISBLANK(LSP_All[[#This Row],[M8+]]),"",ABS(LSP_All[[#This Row],[M8+]]-(statistics_M8[[#This Row],[median_gap]]/365)))
A3: Japan | B3: 2 | C3: 2.282 | D3: 2.282 | E3: 1.503 | F3: 11.833 | I3: =IF(ISBLANK(LSP_All[[#This Row],[M4+]]),"",ABS(LSP_All[[#This Row],[M4+]]-(statistics_M4[[#This Row],[mean_gap]]/365))) -> 1.3121582 | J3: =IF(ISBLANK(LSP_All[[#This Row],[M5+]]),"",ABS(LSP_All[[#This Row],[M5+]]-(statistics_M5[[#This Row],[mean_gap]]/365))) -> 1.3121582 | K3: =IF(ISBLANK(LSP_All[[#This Row],[M6+]]),"",ABS(LSP_All[[#This Row],[M6+]]-(statistics_M6[[#This Row],[mean_gap]]/365))) -> 0.40554746 | L3: =IF(ISBLANK(LSP_All[[#This Row],[M7+]]),"",ABS(LSP_All[[#This Row],[M7+]]-(statistics_M7[[#This Row],[mean_gap]]/365))) -> 6.2326264 | M3: =IF(ISBLANK(LSP_All[[#This Row],[M8+]]),"",ABS(LSP_All[[#This Row],[M8+]]-(statistics_M8[[#This Row],[mean_gap]]/365))) | O3: =IF(ISBLANK(LSP_All[[#This Row],[M4+]]),"",ABS(LSP_All[[#This Row],[M4+]]-(statistics_M4[[#This Row],[exact_mode]]/365))) -> 1.7395342 | P3: =IF(ISBLANK(LSP_All[[#This Row],[M5+]]),"",ABS(LSP_All[[#This Row],[M5+]]-(statistics_M5[[#This Row],[exact_mode]]/365))) -> 1.7395342 | Q3: =IF(ISBLANK(LSP_All[[#This Row],[M6+]]),"",ABS(LSP_All[[#This Row],[M6+]]-(statistics_M6[[#This Row],[exact_mode]]/365))) -> 0.96053425 | R3: =IF(ISBLANK(LSP_All[[#This Row],[M7+]]),"",ABS(LSP_All[[#This Row],[M7+]]-(statistics_M7[[#This Row],[exact_mode]]/365))) -> 11.326151 | S3: =IF(ISBLANK(LSP_All[[#This Row],[M8+]]),"",ABS(LSP_All[[#This Row],[M8+]]-(statistics_M8[[#This Row],[exact_mode]]/365))) | U3: =IF(ISBLANK(LSP_All[[#This Row],[M4+]]),"",ABS(LSP_All[[#This Row],[M4+]]-(statistics_M4[[#This Row],[median_gap]]/365))) -> 1.4546027 | V3: =IF(ISBLANK(LSP_All[[#This Row],[M5+]]),"",ABS(LSP_All[[#This Row],[M5+]]-(statistics_M5[[#This Row],[median_gap]]/365))) -> 1.4546027 | W3: =IF(ISBLANK(LSP_All[[#This Row],[M6+]]),"",ABS(LSP_All[[#This Row],[M6+]]-(statistics_M6[[#This Row],[median_gap]]/365))) -> 0.50847945 | X3: =IF(ISBLANK(LSP_All[[#This Row],[M7+]]),"",ABS(LSP_All[[#This Row],[M7+]]-(statistics_M7[[#This Row],[median_gap]]/365))) -> 8.5261507 | Y3: =IF(ISBLANK(LSP_All[[#This Row],[M8+]]),"",ABS(LSP_All[[#This Row],[M8+]]-(statistics_M8[[#This Row],[median_gap]]/365)))
A4: Japan | B4: 3 | C4: 6.092 | D4: 7.199 | I4: =IF(ISBLANK(LSP_All[[#This Row],[M4+]]),"",ABS(LSP_All[[#This Row],[M4+]]-(statistics_M4[[#This Row],[mean_gap]]/365))) -> 2.5693212 | J4: =IF(ISBLANK(LSP_All[[#This Row],[M5+]]),"",ABS(LSP_All[[#This Row],[M5+]]-(statistics_M5[[#This Row],[mean_gap]]/365))) -> 0.85817808 | K4: =IF(ISBLANK(LSP_All[[#This Row],[M6+]]),"",ABS(LSP_All[[#This Row],[M6+]]-(statistics_M6[[#This Row],[mean_gap]]/365))) | L4: =IF(ISBLANK(LSP_All[[#This Row],[M7+]]),"",ABS(LSP_All[[#This Row],[M7+]]-(statistics_M7[[#This Row],[mean_gap]]/365))) | M4: =IF(ISBLANK(LSP_All[[#This Row],[M8+]]),"",ABS(LSP_All[[#This Row],[M8+]]-(statistics_M8[[#This Row],[mean_gap]]/365))) | O4: =IF(ISBLANK(LSP_All[[#This Row],[M4+]]),"",ABS(LSP_All[[#This Row],[M4+]]-(statistics_M4[[#This Row],[exact_mode]]/365))) -> 5.5714521 | P4: =IF(ISBLANK(LSP_All[[#This Row],[M5+]]),"",ABS(LSP_All[[#This Row],[M5+]]-(statistics_M5[[#This Row],[exact_mode]]/365))) -> 6.6784521 | Q4: =IF(ISBLANK(LSP_All[[#This Row],[M6+]]),"",ABS(LSP_All[[#This Row],[M6+]]-(statistics_M6[[#This Row],[exact_mode]]/365))) | R4: =IF(ISBLANK(LSP_All[[#This Row],[M7+]]),"",ABS(LSP_All[[#This Row],[M7+]]-(statistics_M7[[#This Row],[exact_mode]]/365))) | S4: =IF(ISBLANK(LSP_All[[#This Row],[M8+]]),"",ABS(LSP_All[[#This Row],[M8+]]-(statistics_M8[[#This Row],[exact_mode]]/365))) | U4: =IF(ISBLANK(LSP_All[[#This Row],[M4+]]),"",ABS(LSP_All[[#This Row],[M4+]]-(statistics_M4[[#This Row],[median_gap]]/365))) -> 4.7906301 | V4: =IF(ISBLANK(LSP_All[[#This Row],[M5+]]),"",ABS(LSP_All[[#This Row],[M5+]]-(statistics_M5[[#This Row],[median_gap]]/365))) -> 2.2784521 | W4: =IF(ISBLANK(LSP_All[[#This Row],[M6+]]),"",ABS(LSP_All[[#This Row],[M6+]]-(statistics_M6[[#This Row],[median_gap]]/365))) | X4: =IF(ISBLANK(LSP_All[[#This Row],[M7+]]),"",ABS(LSP_All[[#This Row],[M7+]]-(statistics_M7[[#This Row],[median_gap]]/365))) | Y4: =IF(ISBLANK(LSP_All[[#This Row],[M8+]]),"",ABS(LSP_All[[#This Row],[M8+]]-(statistics_M8[[#This Row],[median_gap]]/365)))
A5: Papua New Guinea | B5: 1 | C5: 1.528 | D5: 1.528 | E5: 1.528 | F5: 2.014 | I5: =IF(ISBLANK(LSP_All[[#This Row],[M4+]]),"",ABS(LSP_All[[#This Row],[M4+]]-(statistics_M4[[#This Row],[mean_gap]]/365))) -> 0.62381213 | J5: =IF(ISBLANK(LSP_All[[#This Row],[M5+]]),"",ABS(LSP_All[[#This Row],[M5+]]-(statistics_M5[[#This Row],[mean_gap]]/365))) -> 0.62381213 | K5: =IF(ISBLANK(LSP_All[[#This Row],[M6+]]),"",ABS(LSP_All[[#This Row],[M6+]]-(statistics_M6[[#This Row],[mean_gap]]/365))) -> 0.62381213 | L5: =IF(ISBLANK(LSP_All[[#This Row],[M7+]]),"",ABS(LSP_All[[#This Row],[M7+]]-(statistics_M7[[#This Row],[mean_gap]]/365))) -> 0.20070427 | M5: =IF(ISBLANK(LSP_All[[#This Row],[M8+]]),"",ABS(LSP_All[[#This Row],[M8+]]-(statistics_M8[[#This Row],[mean_gap]]/365))) | O5: =IF(ISBLANK(LSP_All[[#This Row],[M4+]]),"",ABS(LSP_All[[#This Row],[M4+]]-(statistics_M4[[#This Row],[exact_mode]]/365))) -> 0.93621918 | P5: =IF(ISBLANK(LSP_All[[#This Row],[M5+]]),"",ABS(LSP_All[[#This Row],[M5+]]-(statistics_M5[[#This Row],[exact_mode]]/365))) -> 0.93621918 | Q5: =IF(ISBLANK(LSP_All[[#This Row],[M6+]]),"",ABS(LSP_All[[#This Row],[M6+]]-(statistics_M6[[#This Row],[exact_mode]]/365))) -> 0.93621918 | R5: =IF(ISBLANK(LSP_All[[#This Row],[M7+]]),"",ABS(LSP_All[[#This Row],[M7+]]-(statistics_M7[[#This Row],[exact_mode]]/365))) -> 0.9509863 | S5: =IF(ISBLANK(LSP_All[[#This Row],[M8+]]),"",ABS(LSP_All[[#This Row],[M8+]]-(statistics_M8[[#This Row],[exact_mode]]/365))) | U5: =IF(ISBLANK(LSP_All[[#This Row],[M4+]]),"",ABS(LSP_All[[#This Row],[M4+]]-(statistics_M4[[#This Row],[median_gap]]/365))) -> 0.74443836 | V5: =IF(ISBLANK(LSP_All[[#This Row],[M5+]]),"",ABS(LSP_All[[#This Row],[M5+]]-(statistics_M5[[#This Row],[median_gap]]/365))) -> 0.74443836 | W5: =IF(ISBLANK(LSP_All[[#This Row],[M6+]]),"",ABS(LSP_All[[#This Row],[M6+]]-(statistics_M6[[#This Row],[median_gap]]/365))) -> 0.74443836 | X5: =IF(ISBLANK(LSP_All[[#This Row],[M7+]]),"",ABS(LSP_All[[#This Row],[M7+]]-(statistics_M7[[#This Row],[median_gap]]/365))) -> 0.7249589 | Y5: =IF(ISBLANK(LSP_All[[#This Row],[M8+]]),"",ABS(LSP_All[[#This Row],[M8+]]-(statistics_M8[[#This Row],[median_gap]]/365)))
A6: Papua New Guinea | B6: 2 | C6: 2.073 | D6: 1.582 | E6: 11.668 | I6: =IF(ISBLANK(LSP_All[[#This Row],[M4+]]),"",ABS(LSP_All[[#This Row],[M4+]]-(statistics_M4[[#This Row],[mean_gap]]/365))) -> 0.82850307 | J6: =IF(ISBLANK(LSP_All[[#This Row],[M5+]]),"",ABS(LSP_All[[#This Row],[M5+]]-(statistics_M5[[#This Row],[mean_gap]]/365))) -> 0.012851697 | K6: =IF(ISBLANK(LSP_All[[#This Row],[M6+]]),"",ABS(LSP_All[[#This Row],[M6+]]-(statistics_M6[[#This Row],[mean_gap]]/365))) -> 5.7160697 | L6: =IF(ISBLANK(LSP_All[[#This Row],[M7+]]),"",ABS(LSP_All[[#This Row],[M7+]]-(statistics_M7[[#This Row],[mean_gap]]/365))) | M6: =IF(ISBLANK(LSP_All[[#This Row],[M8+]]),"",ABS(LSP_All[[#This Row],[M8+]]-(statistics_M8[[#This Row],[mean_gap]]/365))) | O6: =IF(ISBLANK(LSP_All[[#This Row],[M4+]]),"",ABS(LSP_All[[#This Row],[M4+]]-(statistics_M4[[#This Row],[exact_mode]]/365))) -> 1.5743699 | P6: =IF(ISBLANK(LSP_All[[#This Row],[M5+]]),"",ABS(LSP_All[[#This Row],[M5+]]-(statistics_M5[[#This Row],[exact_mode]]/365))) -> 1.0148767 | Q6: =IF(ISBLANK(LSP_All[[#This Row],[M6+]]),"",ABS(LSP_All[[#This Row],[M6+]]-(statistics_M6[[#This Row],[exact_mode]]/365))) -> 10.985808 | R6: =IF(ISBLANK(LSP_All[[#This Row],[M7+]]),"",ABS(LSP_All[[#This Row],[M7+]]-(statistics_M7[[#This Row],[exact_mode]]/365))) | S6: =IF(ISBLANK(LSP_All[[#This Row],[M8+]]),"",ABS(LSP_All[[#This Row],[M8+]]-(statistics_M8[[#This Row],[exact_mode]]/365))) | U6: =IF(ISBLANK(LSP_All[[#This Row],[M4+]]),"",ABS(LSP_All[[#This Row],[M4+]]-(statistics_M4[[#This Row],[median_gap]]/365))) -> 1.082589 | V6: =IF(ISBLANK(LSP_All[[#This Row],[M5+]]),"",ABS(LSP_All[[#This Row],[M5+]]-(statistics_M5[[#This Row],[median_gap]]/365))) -> 0.34090411 | W6: =IF(ISBLANK(LSP_All[[#This Row],[M6+]]),"",ABS(LSP_All[[#This Row],[M6+]]-(statistics_M6[[#This Row],[median_gap]]/365))) -> 8.4762192 | X6: =IF(ISBLANK(LSP_All[[#This Row],[M7+]]),"",ABS(LSP_All[[#This Row],[M7+]]-(statistics_M7[[#This Row],[median_gap]]/365))) | Y6: =IF(ISBLANK(LSP_All[[#This Row],[M8+]]),"",ABS(LSP_All[[#This Row],[M8+]]-(statistics_M8[[#This Row],[median_gap]]/365)))
A7: Papua New Guinea | B7: 3 | C7: 2.516 | D7: 4.154 | I7: =IF(ISBLANK(LSP_All[[#This Row],[M4+]]),"",ABS(LSP_All[[#This Row],[M4+]]-(statistics_M4[[#This Row],[mean_gap]]/365))) -> 0.25030365 | J7: =IF(ISBLANK(LSP_All[[#This Row],[M5+]]),"",ABS(LSP_All[[#This Row],[M5+]]-(statistics_M5[[#This Row],[mean_gap]]/365))) -> 0.88088356 | K7: =IF(ISBLANK(LSP_All[[#This Row],[M6+]]),"",ABS(LSP_All[[#This Row],[M6+]]-(statistics_M6[[#This Row],[mean_gap]]/365))) | L7: =IF(ISBLANK(LSP_All[[#This Row],[M7+]]),"",ABS(LSP_All[[#This Row],[M7+]]-(statistics_M7[[#This Row],[mean_gap]]/365))) | M7: =IF(ISBLANK(LSP_All[[#This Row],[M8+]]),"",ABS(LSP_All[[#This Row],[M8+]]-(statistics_M8[[#This Row],[mean_gap]]/365))) | O7: =IF(ISBLANK(LSP_All[[#This Row],[M4+]]),"",ABS(LSP_All[[#This Row],[M4+]]-(statistics_M4[[#This Row],[exact_mode]]/365))) -> 1.9023014 | P7: =IF(ISBLANK(LSP_All[[#This Row],[M5+]]),"",ABS(LSP_All[[#This Row],[M5+]]-(statistics_M5[[#This Row],[exact_mode]]/365))) -> 3.0033151 | Q7: =IF(ISBLANK(LSP_All[[#This Row],[M6+]]),"",ABS(LSP_All[[#This Row],[M6+]]-(statistics_M6[[#This Row],[exact_mode]]/365))) | R7: =IF(ISBLANK(LSP_All[[#This Row],[M7+]]),"",ABS(LSP_All[[#This Row],[M7+]]-(statistics_M7[[#This Row],[exact_mode]]/365))) | S7: =IF(ISBLANK(LSP_All[[#This Row],[M8+]]),"",ABS(LSP_All[[#This Row],[M8+]]-(statistics_M8[[#This Row],[exact_mode]]/365))) | U7: =IF(ISBLANK(LSP_All[[#This Row],[M4+]]),"",ABS(LSP_All[[#This Row],[M4+]]-(statistics_M4[[#This Row],[median_gap]]/365))) -> 1.3831233 | V7: =IF(ISBLANK(LSP_All[[#This Row],[M5+]]),"",ABS(LSP_All[[#This Row],[M5+]]-(statistics_M5[[#This Row],[median_gap]]/365))) -> 2.6690685 | W7: =IF(ISBLANK(LSP_All[[#This Row],[M6+]]),"",ABS(LSP_All[[#This Row],[M6+]]-(statistics_M6[[#This Row],[median_gap]]/365))) | X7: =IF(ISBLANK(LSP_All[[#This Row],[M7+]]),"",ABS(LSP_All[[#This Row],[M7+]]-(statistics_M7[[#This Row],[median_gap]]/365))) | Y7: =IF(ISBLANK(LSP_All[[#This Row],[M8+]]),"",ABS(LSP_All[[#This Row],[M8+]]-(statistics_M8[[#This Row],[median_gap]]/365)))
A8: Philippines | B8: 1 | C8: 1.104 | D8: 1.104 | E8: 2.192 | F8: 2.965 | I8: =IF(ISBLANK(LSP_All[[#This Row],[M4+]]),"",ABS(LSP_All[[#This Row],[M4+]]-(statistics_M4[[#This Row],[mean_gap]]/365))) -> 0.23896956 | J8: =IF(ISBLANK(LSP_All[[#This Row],[M5+]]),"",ABS(LSP_All[[#This Row],[M5+]]-(statistics_M5[[#This Row],[mean_gap]]/365))) -> 0.23896956 | K8: =IF(ISBLANK(LSP_All[[#This Row],[M6+]]),"",ABS(LSP_All[[#This Row],[M6+]]-(statistics_M6[[#This Row],[mean_gap]]/365))) -> 1.2893595 | L8: =IF(ISBLANK(LSP_All[[#This Row],[M7+]]),"",ABS(LSP_All[[#This Row],[M7+]]-(statistics_M7[[#This Row],[mean_gap]]/365))) -> 0.98778756 | M8: =IF(ISBLANK(LSP_All[[#This Row],[M8+]]),"",ABS(LSP_All[[#This Row],[M8+]]-(statistics_M8[[#This Row],[mean_gap]]/365))) | O8: =IF(ISBLANK(LSP_All[[#This Row],[M4+]]),"",ABS(LSP_All[[#This Row],[M4+]]-(statistics_M4[[#This Row],[exact_mode]]/365))) -> 0.60263014 | P8: =IF(ISBLANK(LSP_All[[#This Row],[M5+]]),"",ABS(LSP_All[[#This Row],[M5+]]-(statistics_M5[[#This Row],[exact_mode]]/365))) -> 0.60263014 | Q8: =IF(ISBLANK(LSP_All[[#This Row],[M6+]]),"",ABS(LSP_All[[#This Row],[M6+]]-(statistics_M6[[#This Row],[exact_mode]]/365))) -> 1.6906301 | R8: =IF(ISBLANK(LSP_All[[#This Row],[M7+]]),"",ABS(LSP_All[[#This Row],[M7+]]-(statistics_M7[[#This Row],[exact_mode]]/365))) -> 2.3704795 | S8: =IF(ISBLANK(LSP_All[[#This Row],[M8+]]),"",ABS(LSP_All[[#This Row],[M8+]]-(statistics_M8[[#This Row],[exact_mode]]/365))) | U8: =IF(ISBLANK(LSP_All[[#This Row],[M4+]]),"",ABS(LSP_All[[#This Row],[M4+]]-(statistics_M4[[#This Row],[median_gap]]/365))) -> 0.35742466 | V8: =IF(ISBLANK(LSP_All[[#This Row],[M5+]]),"",ABS(LSP_All[[#This Row],[M5+]]-(statistics_M5[[#This Row],[median_gap]]/365))) -> 0.35742466 | W8: =IF(ISBLANK(LSP_All[[#This Row],[M6+]]),"",ABS(LSP_All[[#This Row],[M6+]]-(statistics_M6[[#This Row],[median_gap]]/365))) -> 1.4440548 | X8: =IF(ISBLANK(LSP_All[[#This Row],[M7+]]),"",ABS(LSP_All[[#This Row],[M7+]]-(statistics_M7[[#This Row],[median_gap]]/365))) -> 1.3814384 | Y8: =IF(ISBLANK(LSP_All[[#This Row],[M8+]]),"",ABS(LSP_All[[#This Row],[M8+]]-(statistics_M8[[#This Row],[median_gap]]/365)))
A9: Philippines | B9: 2 | I9: =IF(ISBLANK(LSP_All[[#This Row],[M4+]]),"",ABS(LSP_All[[#This Row],[M4+]]-(statistics_M4[[#This Row],[mean_gap]]/365))) | J9: =IF(ISBLANK(LSP_All[[#This Row],[M5+]]),"",ABS(LSP_All[[#This Row],[M5+]]-(statistics_M5[[#This Row],[mean_gap]]/365))) | K9: =IF(ISBLANK(LSP_All[[#This Row],[M6+]]),"",ABS(LSP_All[[#This Row],[M6+]]-(statistics_M6[[#This Row],[mean_gap]]/365))) | L9: =IF(ISBLANK(LSP_All[[#This Row],[M7+]]),"",ABS(LSP_All[[#This Row],[M7+]]-(statistics_M7[[#This Row],[mean_gap]]/365))) | M9: =IF(ISBLANK(LSP_All[[#This Row],[M8+]]),"",ABS(LSP_All[[#This Row],[M8+]]-(statistics_M8[[#This Row],[mean_gap]]/365))) | O9: =IF(ISBLANK(LSP_All[[#This Row],[M4+]]),"",ABS(LSP_All[[#This Row],[M4+]]-(statistics_M4[[#This Row],[exact_mode]]/365))) | P9: =IF(ISBLANK(LSP_All[[#This Row],[M5+]]),"",ABS(LSP_All[[#This Row],[M5+]]-(statistics_M5[[#This Row],[exact_mode]]/365))) | Q9: =IF(ISBLANK(LSP_All[[#This Row],[M6+]]),"",ABS(LSP_All[[#This Row],[M6+]]-(statistics_M6[[#This Row],[exact_mode]]/365))) | R9: =IF(ISBLANK(LSP_All[[#This Row],[M7+]]),"",ABS(LSP_All[[#This Row],[M7+]]-(statistics_M7[[#This Row],[exact_mode]]/365))) | S9: =IF(ISBLANK(LSP_All[[#This Row],[M8+]]),"",ABS(LSP_All[[#This Row],[M8+]]-(statistics_M8[[#This Row],[exact_mode]]/365))) | U9: =IF(ISBLANK(LSP_All[[#This Row],[M4+]]),"",ABS(LSP_All[[#This Row],[M4+]]-(statistics_M4[[#This Row],[median_gap]]/365))) | V9: =IF(ISBLANK(LSP_All[[#This Row],[M5+]]),"",ABS(LSP_All[[#This Row],[M5+]]-(statistics_M5[[#This Row],[median_gap]]/365))) | W9: =IF(ISBLANK(LSP_All[[#This Row],[M6+]]),"",ABS(LSP_All[[#This Row],[M6+]]-(statistics_M6[[#This Row],[median_gap]]/365))) | X9: =IF(ISBLANK(LSP_All[[#This Row],[M7+]]),"",ABS(LSP_All[[#This Row],[M7+]]-(statistics_M7[[#This Row],[median_gap]]/365))) | Y9: =IF(ISBLANK(LSP_All[[#This Row],[M8+]]),"",ABS(LSP_All[[#This Row],[M8+]]-(statistics_M8[[#This Row],[median_gap]]/365)))
A10: Tonga | B10: 1 | C10: 1.004 | D10: 1.004 | E10: 1.004 | F10: 3.95 | I10: =IF(ISBLANK(LSP_All[[#This Row],[M4+]]),"",ABS(LSP_All[[#This Row],[M4+]]-('statistics-M4'!$I11/365))) -> 0.048175427 | J10: =IF(ISBLANK(LSP_All[[#This Row],[M5+]]),"",ABS(LSP_All[[#This Row],[M5+]]-('statistics-M5'!$I11/365))) -> 0.048175427 | K10: =IF(ISBLANK(LSP_All[[#This Row],[M6+]]),"",ABS(LSP_All[[#This Row],[M6+]]-('statistics-M6'!$I11/365))) -> 0.009634114 | L10: =IF(ISBLANK(LSP_All[[#This Row],[M7+]]),"",ABS(LSP_All[[#This Row],[M7+]]-('statistics-M7'!$I11/365))) -> 0.21359485 | M10: =IF(ISBLANK(LSP_All[[#This Row],[M8+]]),"",ABS(LSP_All[[#This Row],[M8+]]-('statistics-M8'!$I11/365))) | O10: =IF(ISBLANK(LSP_All[[#This Row],[M4+]]),"",ABS(LSP_All[[#This Row],[M4+]]-('statistics-M4'!$F11/365))) -> 0.39578082 | P10: =IF(ISBLANK(LSP_All[[#This Row],[M5+]]),"",ABS(LSP_All[[#This Row],[M5+]]-('statistics-M5'!$F11/365))) -> 0.39578082 | Q10: =IF(ISBLANK(LSP_All[[#This Row],[M6+]]),"",ABS(LSP_All[[#This Row],[M6+]]-('statistics-M6'!$F11/365))) -> 0.39578082 | R10: =IF(ISBLANK(LSP_All[[#This Row],[M7+]]),"",ABS(LSP_All[[#This Row],[M7+]]-('statistics-M7'!$F11/365))) -> 3.2979452 | S10: =IF(ISBLANK(LSP_All[[#This Row],[M8+]]),"",ABS(LSP_All[[#This Row],[M8+]]-('statistics-M8'!$F11/365))) | U10: =IF(ISBLANK(LSP_All[[#This Row],[M4+]]),"",ABS(LSP_All[[#This Row],[M4+]]-('statistics-M4'!$J11/365))) -> 0.13824658 | V10: =IF(ISBLANK(LSP_All[[#This Row],[M5+]]),"",ABS(LSP_All[[#This Row],[M5+]]-('statistics-M5'!$J11/365))) -> 0.13824658 | W10: =IF(ISBLANK(LSP_All[[#This Row],[M6+]]),"",ABS(LSP_All[[#This Row],[M6+]]-('statistics-M6'!$J11/365))) -> 0.09030137 | X10: =IF(ISBLANK(LSP_All[[#This Row],[M7+]]),"",ABS(LSP_All[[#This Row],[M7+]]-('statistics-M7'!$J11/365))) -> 1.4267123 | Y10: =IF(ISBLANK(LSP_All[[#This Row],[M8+]]),"",ABS(LSP_All[[#This Row],[M8+]]-('statistics-M8'!$J11/365)))
A11: USA | B11: 1 | C11: 1.802 | D11: 1.802 | E11: 1.792 | F11: 4.727 | I11: =IF(ISBLANK(LSP_All[[#This Row],[M4+]]),"",ABS(LSP_All[[#This Row],[M4+]]-('statistics-M4'!$I14/365))) -> 0.90567906 | J11: =IF(ISBLANK(LSP_All[[#This Row],[M5+]]),"",ABS(LSP_All[[#This Row],[M5+]]-('statistics-M5'!$I14/365))) -> 0.90567906 | K11: =IF(ISBLANK(LSP_All[[#This Row],[M6+]]),"",ABS(LSP_All[[#This Row],[M6+]]-('statistics-M6'!$I14/365))) -> 0.8826889 | L11: =IF(ISBLANK(LSP_All[[#This Row],[M7+]]),"",ABS(LSP_All[[#This Row],[M7+]]-('statistics-M7'!$I14/365))) -> 2.0705733 | M11: =IF(ISBLANK(LSP_All[[#This Row],[M8+]]),"",ABS(LSP_All[[#This Row],[M8+]]-('statistics-M8'!$I14/365))) | O11: =IF(ISBLANK(LSP_All[[#This Row],[M4+]]),"",ABS(LSP_All[[#This Row],[M4+]]-('statistics-M4'!$F14/365))) -> 1.3061096 | P11: =IF(ISBLANK(LSP_All[[#This Row],[M5+]]),"",ABS(LSP_All[[#This Row],[M5+]]-('statistics-M5'!$F14/365))) -> 1.3061096 | Q11: =IF(ISBLANK(LSP_All[[#This Row],[M6+]]),"",ABS(LSP_All[[#This Row],[M6+]]-('statistics-M6'!$F14/365))) -> 1.2961096 | R11: =IF(ISBLANK(LSP_All[[#This Row],[M7+]]),"",ABS(LSP_All[[#This Row],[M7+]]-('statistics-M7'!$F14/365))) -> 4.1653562 | S11: =IF(ISBLANK(LSP_All[[#This Row],[M8+]]),"",ABS(LSP_All[[#This Row],[M8+]]-('statistics-M8'!$F14/365))) | U11: =IF(ISBLANK(LSP_All[[#This Row],[M4+]]),"",ABS(LSP_All[[#This Row],[M4+]]-('statistics-M4'!$J14/365))) -> 0.95953425 | V11: =IF(ISBLANK(LSP_All[[#This Row],[M5+]]),"",ABS(LSP_All[[#This Row],[M5+]]-('statistics-M5'!$J14/365))) -> 0.95953425 | W11: =IF(ISBLANK(LSP_All[[#This Row],[M6+]]),"",ABS(LSP_All[[#This Row],[M6+]]-('statistics-M6'!$J14/365))) -> 0.94131507 | X11: =IF(ISBLANK(LSP_All[[#This Row],[M7+]]),"",ABS(LSP_All[[#This Row],[M7+]]-('statistics-M7'!$J14/365))) -> 2.8722055 | Y11: =IF(ISBLANK(LSP_All[[#This Row],[M8+]]),"",ABS(LSP_All[[#This Row],[M8+]]-('statistics-M8'!$J14/365)))
A12: USA | B12: 2 | C12: 1.911 | D12: 1.35 | E12: 2.866 | I12: =IF(ISBLANK(LSP_All[[#This Row],[M4+]]),"",ABS(LSP_All[[#This Row],[M4+]]-('statistics-M4'!$I15/365))) -> 1.0347633 | J12: =IF(ISBLANK(LSP_All[[#This Row],[M5+]]),"",ABS(LSP_All[[#This Row],[M5+]]-('statistics-M5'!$I15/365))) -> 0.33921785 | K12: =IF(ISBLANK(LSP_All[[#This Row],[M6+]]),"",ABS(LSP_All[[#This Row],[M6+]]-('statistics-M6'!$I15/365))) -> 0.76695194 | L12: =IF(ISBLANK(LSP_All[[#This Row],[M7+]]),"",ABS(LSP_All[[#This Row],[M7+]]-('statistics-M7'!$I15/365))) | M12: =IF(ISBLANK(LSP_All[[#This Row],[M8+]]),"",ABS(LSP_All[[#This Row],[M8+]]-('statistics-M8'!$I15/365))) | O12: =IF(ISBLANK(LSP_All[[#This Row],[M4+]]),"",ABS(LSP_All[[#This Row],[M4+]]-('statistics-M4'!$F15/365))) -> 1.4096301 | P12: =IF(ISBLANK(LSP_All[[#This Row],[M5+]]),"",ABS(LSP_All[[#This Row],[M5+]]-('statistics-M5'!$F15/365))) -> 0.84863014 | Q12: =IF(ISBLANK(LSP_All[[#This Row],[M6+]]),"",ABS(LSP_All[[#This Row],[M6+]]-('statistics-M6'!$F15/365))) -> 2.1235342 | R12: =IF(ISBLANK(LSP_All[[#This Row],[M7+]]),"",ABS(LSP_All[[#This Row],[M7+]]-('statistics-M7'!$F15/365))) | S12: =IF(ISBLANK(LSP_All[[#This Row],[M8+]]),"",ABS(LSP_All[[#This Row],[M8+]]-('statistics-M8'!$F15/365))) | U12: =IF(ISBLANK(LSP_All[[#This Row],[M4+]]),"",ABS(LSP_All[[#This Row],[M4+]]-('statistics-M4'!$J15/365))) -> 1.101411 | V12: =IF(ISBLANK(LSP_All[[#This Row],[M5+]]),"",ABS(LSP_All[[#This Row],[M5+]]-('statistics-M5'!$J15/365))) -> 0.50342466 | W12: =IF(ISBLANK(LSP_All[[#This Row],[M6+]]),"",ABS(LSP_All[[#This Row],[M6+]]-('statistics-M6'!$J15/365))) -> 1.1838082 | X12: =IF(ISBLANK(LSP_All[[#This Row],[M7+]]),"",ABS(LSP_All[[#This Row],[M7+]]-('statistics-M7'!$J15/365))) | Y12: =IF(ISBLANK(LSP_All[[#This Row],[M8+]]),"",ABS(LSP_All[[#This Row],[M8+]]-('statistics-M8'!$J15/365)))
A13: USA | B13: 3 | C13: 1.202 | D13: 1.967 | E13: 4.565 | I13: =IF(ISBLANK(LSP_All[[#This Row],[M4+]]),"",ABS(LSP_All[[#This Row],[M4+]]-('statistics-M4'!$I16/365))) -> 0.24411532 | J13: =IF(ISBLANK(LSP_All[[#This Row],[M5+]]),"",ABS(LSP_All[[#This Row],[M5+]]-('statistics-M5'!$I16/365))) -> 0.28484575 | K13: =IF(ISBLANK(LSP_All[[#This Row],[M6+]]),"",ABS(LSP_All[[#This Row],[M6+]]-('statistics-M6'!$I16/365))) -> 0.15543379 | L13: =IF(ISBLANK(LSP_All[[#This Row],[M7+]]),"",ABS(LSP_All[[#This Row],[M7+]]-('statistics-M7'!$I16/365))) | M13: =IF(ISBLANK(LSP_All[[#This Row],[M8+]]),"",ABS(LSP_All[[#This Row],[M8+]]-('statistics-M8'!$I16/365))) | O13: =IF(ISBLANK(LSP_All[[#This Row],[M4+]]),"",ABS(LSP_All[[#This Row],[M4+]]-('statistics-M4'!$F16/365))) -> 0.43213699 | P13: =IF(ISBLANK(LSP_All[[#This Row],[M5+]]),"",ABS(LSP_All[[#This Row],[M5+]]-('statistics-M5'!$F16/365))) -> 1.3259041 | Q13: =IF(ISBLANK(LSP_All[[#This Row],[M6+]]),"",ABS(LSP_All[[#This Row],[M6+]]-('statistics-M6'!$F16/365))) -> 3.9430822 | R13: =IF(ISBLANK(LSP_All[[#This Row],[M7+]]),"",ABS(LSP_All[[#This Row],[M7+]]-('statistics-M7'!$F16/365))) | S13: =IF(ISBLANK(LSP_All[[#This Row],[M8+]]),"",ABS(LSP_All[[#This Row],[M8+]]-('statistics-M8'!$F16/365))) | U13: =IF(ISBLANK(LSP_All[[#This Row],[M4+]]),"",ABS(LSP_All[[#This Row],[M4+]]-('statistics-M4'!$J16/365))) -> 0.36912329 | V13: =IF(ISBLANK(LSP_All[[#This Row],[M5+]]),"",ABS(LSP_All[[#This Row],[M5+]]-('statistics-M5'!$J16/365))) -> 0.54508219 | W13: =IF(ISBLANK(LSP_All[[#This Row],[M6+]]),"",ABS(LSP_All[[#This Row],[M6+]]-('statistics-M6'!$J16/365))) -> 1.7307534 | X13: =IF(ISBLANK(LSP_All[[#This Row],[M7+]]),"",ABS(LSP_All[[#This Row],[M7+]]-('statistics-M7'!$J16/365))) | Y13: =IF(ISBLANK(LSP_All[[#This Row],[M8+]]),"",ABS(LSP_All[[#This Row],[M8+]]-('statistics-M8'!$J16/365)))
A14: Mexico | B14: 1 | C14: 1.479 | D14: 1.479 | E14: 1.472 | F14: 3.882 | I14: =IF(ISBLANK(LSP_All[[#This Row],[M4+]]),"",ABS(LSP_All[[#This Row],[M4+]]-('statistics-M4'!$I17/365))) -> 0.47871733 | J14: =IF(ISBLANK(LSP_All[[#This Row],[M5+]]),"",ABS(LSP_All[[#This Row],[M5+]]-('statistics-M5'!$I17/365))) -> 0.47871733 | K14: =IF(ISBLANK(LSP_All[[#This Row],[M6+]]),"",ABS(LSP_All[[#This Row],[M6+]]-('statistics-M6'!$I17/365))) -> 0.31570994 | L14: =IF(ISBLANK(LSP_All[[#This Row],[M7+]]),"",ABS(LSP_All[[#This Row],[M7+]]-('statistics-M7'!$I17/365))) -> 0.95949511 | M14: =IF(ISBLANK(LSP_All[[#This Row],[M8+]]),"",ABS(LSP_All[[#This Row],[M8+]]-('statistics-M8'!$I17/365))) | O14: =IF(ISBLANK(LSP_All[[#This Row],[M4+]]),"",ABS(LSP_All[[#This Row],[M4+]]-('statistics-M4'!$F17/365))) -> 0.96667123 | P14: =IF(ISBLANK(LSP_All[[#This Row],[M5+]]),"",ABS(LSP_All[[#This Row],[M5+]]-('statistics-M5'!$F17/365))) -> 0.96667123 | Q14: =IF(ISBLANK(LSP_All[[#This Row],[M6+]]),"",ABS(LSP_All[[#This Row],[M6+]]-('statistics-M6'!$F17/365))) -> 0.95967123 | R14: =IF(ISBLANK(LSP_All[[#This Row],[M7+]]),"",ABS(LSP_All[[#This Row],[M7+]]-('statistics-M7'!$F17/365))) -> 1.8025479 | S14: =IF(ISBLANK(LSP_All[[#This Row],[M8+]]),"",ABS(LSP_All[[#This Row],[M8+]]-('statistics-M8'!$F17/365))) | U14: =IF(ISBLANK(LSP_All[[#This Row],[M4+]]),"",ABS(LSP_All[[#This Row],[M4+]]-('statistics-M4'!$J17/365))) -> 0.56256164 | V14: =IF(ISBLANK(LSP_All[[#This Row],[M5+]]),"",ABS(LSP_All[[#This Row],[M5+]]-('statistics-M5'!$J17/365))) -> 0.56256164 | W14: =IF(ISBLANK(LSP_All[[#This Row],[M6+]]),"",ABS(LSP_All[[#This Row],[M6+]]-('statistics-M6'!$J17/365))) -> 0.47747945 | X14: =IF(ISBLANK(LSP_All[[#This Row],[M7+]]),"",ABS(LSP_All[[#This Row],[M7+]]-('statistics-M7'!$J17/365))) -> 1.6491233 | Y14: =IF(ISBLANK(LSP_All[[#This Row],[M8+]]),"",ABS(LSP_All[[#This Row],[M8+]]-('statistics-M8'!$J17/365)))
A15: Mexico | B15: 2 | C15: 2.341 | D15: 1.216 | E15: 2.734 | I15: =IF(ISBLANK(LSP_All[[#This Row],[M4+]]),"",ABS(LSP_All[[#This Row],[M4+]]-('statistics-M4'!$I18/365))) -> 1.3276158 | J15: =IF(ISBLANK(LSP_All[[#This Row],[M5+]]),"",ABS(LSP_All[[#This Row],[M5+]]-('statistics-M5'!$I18/365))) -> 0.092064757 | K15: =IF(ISBLANK(LSP_All[[#This Row],[M6+]]),"",ABS(LSP_All[[#This Row],[M6+]]-('statistics-M6'!$I18/365))) -> 0.91586946 | L15: =IF(ISBLANK(LSP_All[[#This Row],[M7+]]),"",ABS(LSP_All[[#This Row],[M7+]]-('statistics-M7'!$I18/365))) | M15: =IF(ISBLANK(LSP_All[[#This Row],[M8+]]),"",ABS(LSP_All[[#This Row],[M8+]]-('statistics-M8'!$I18/365))) | O15: =IF(ISBLANK(LSP_All[[#This Row],[M4+]]),"",ABS(LSP_All[[#This Row],[M4+]]-('statistics-M4'!$F18/365))) -> 1.6779863 | P15: =IF(ISBLANK(LSP_All[[#This Row],[M5+]]),"",ABS(LSP_All[[#This Row],[M5+]]-('statistics-M5'!$F18/365))) -> 0.68449315 | Q15: =IF(ISBLANK(LSP_All[[#This Row],[M6+]]),"",ABS(LSP_All[[#This Row],[M6+]]-('statistics-M6'!$F18/365))) -> 1.8024932 | R15: =IF(ISBLANK(LSP_All[[#This Row],[M7+]]),"",ABS(LSP_All[[#This Row],[M7+]]-('statistics-M7'!$F18/365))) | S15: =IF(ISBLANK(LSP_All[[#This Row],[M8+]]),"",ABS(LSP_All[[#This Row],[M8+]]-('statistics-M8'!$F18/365))) | U15: =IF(ISBLANK(LSP_All[[#This Row],[M4+]]),"",ABS(LSP_All[[#This Row],[M4+]]-('statistics-M4'!$J18/365))) -> 1.5204521 | V15: =IF(ISBLANK(LSP_All[[#This Row],[M5+]]),"",ABS(LSP_All[[#This Row],[M5+]]-('statistics-M5'!$J18/365))) -> 0.34887671 | W15: =IF(ISBLANK(LSP_All[[#This Row],[M6+]]),"",ABS(LSP_All[[#This Row],[M6+]]-('statistics-M6'!$J18/365))) -> 1.3093425 | X15: =IF(ISBLANK(LSP_All[[#This Row],[M7+]]),"",ABS(LSP_All[[#This Row],[M7+]]-('statistics-M7'!$J18/365))) | Y15: =IF(ISBLANK(LSP_All[[#This Row],[M8+]]),"",ABS(LSP_All[[#This Row],[M8+]]-('statistics-M8'!$J18/365)))
A16: Mexico | B16: 3 | C16: 3.189 | D16: 3.591 | I16: =IF(ISBLANK(LSP_All[[#This Row],[M4+]]),"",ABS(LSP_All[[#This Row],[M4+]]-('statistics-M4'!$I19/365))) -> 1.653726 | J16: =IF(ISBLANK(LSP_All[[#This Row],[M5+]]),"",ABS(LSP_All[[#This Row],[M5+]]-('statistics-M5'!$I19/365))) -> 1.5964795 | K16: =IF(ISBLANK(LSP_All[[#This Row],[M6+]]),"",ABS(LSP_All[[#This Row],[M6+]]-('statistics-M6'!$I19/365))) | L16: =IF(ISBLANK(LSP_All[[#This Row],[M7+]]),"",ABS(LSP_All[[#This Row],[M7+]]-('statistics-M7'!$I19/365))) | M16: =IF(ISBLANK(LSP_All[[#This Row],[M8+]]),"",ABS(LSP_All[[#This Row],[M8+]]-('statistics-M8'!$I19/365))) | O16: =IF(ISBLANK(LSP_All[[#This Row],[M4+]]),"",ABS(LSP_All[[#This Row],[M4+]]-('statistics-M4'!$F19/365))) -> 2.5780411 | P16: =IF(ISBLANK(LSP_All[[#This Row],[M5+]]),"",ABS(LSP_All[[#This Row],[M5+]]-('statistics-M5'!$F19/365))) -> 2.9800411 | Q16: =IF(ISBLANK(LSP_All[[#This Row],[M6+]]),"",ABS(LSP_All[[#This Row],[M6+]]-('statistics-M6'!$F19/365))) | R16: =IF(ISBLANK(LSP_All[[#This Row],[M7+]]),"",ABS(LSP_All[[#This Row],[M7+]]-('statistics-M7'!$F19/365))) | S16: =IF(ISBLANK(LSP_All[[#This Row],[M8+]]),"",ABS(LSP_All[[#This Row],[M8+]]-('statistics-M8'!$F19/365))) | U16: =IF(ISBLANK(LSP_All[[#This Row],[M4+]]),"",ABS(LSP_All[[#This Row],[M4+]]-('statistics-M4'!$J19/365))) -> 2.2259863 | V16: =IF(ISBLANK(LSP_All[[#This Row],[M5+]]),"",ABS(LSP_All[[#This Row],[M5+]]-('statistics-M5'!$J19/365))) -> 2.4485342 | W16: =IF(ISBLANK(LSP_All[[#This Row],[M6+]]),"",ABS(LSP_All[[#This Row],[M6+]]-('statistics-M6'!$J19/365))) | X16: =IF(ISBLANK(LSP_All[[#This Row],[M7+]]),"",ABS(LSP_All[[#This Row],[M7+]]-('statistics-M7'!$J19/365))) | Y16: =IF(ISBLANK(LSP_All[[#This Row],[M8+]]),"",ABS(LSP_All[[#This Row],[M8+]]-('statistics-M8'!$J19/365)))
A17: Canada | B17: 1 | C17: 2.647 | D17: 2.661 | E17: 3.559 | I17: =IF(ISBLANK(LSP_All[[#This Row],[M4+]]),"",ABS(LSP_All[[#This Row],[M4+]]-('statistics-M4'!$I20/365))) -> 1.4688339 | J17: =IF(ISBLANK(LSP_All[[#This Row],[M5+]]),"",ABS(LSP_All[[#This Row],[M5+]]-('statistics-M5'!$I20/365))) -> 1.4089452 | K17: =IF(ISBLANK(LSP_All[[#This Row],[M6+]]),"",ABS(LSP_All[[#This Row],[M6+]]-('statistics-M6'!$I20/365))) -> 1.6600502 | L17: =IF(ISBLANK(LSP_All[[#This Row],[M7+]]),"",ABS(LSP_All[[#This Row],[M7+]]-('statistics-M7'!$I20/365))) | M17: =IF(ISBLANK(LSP_All[[#This Row],[M8+]]),"",ABS(LSP_All[[#This Row],[M8+]]-('statistics-M8'!$I20/365))) | O17: =IF(ISBLANK(LSP_All[[#This Row],[M4+]]),"",ABS(LSP_All[[#This Row],[M4+]]-('statistics-M4'!$F20/365))) -> 1.8086438 | P17: =IF(ISBLANK(LSP_All[[#This Row],[M5+]]),"",ABS(LSP_All[[#This Row],[M5+]]-('statistics-M5'!$F20/365))) -> 1.8226438 | Q17: =IF(ISBLANK(LSP_All[[#This Row],[M6+]]),"",ABS(LSP_All[[#This Row],[M6+]]-('statistics-M6'!$F20/365))) -> 2.9206438 | R17: =IF(ISBLANK(LSP_All[[#This Row],[M7+]]),"",ABS(LSP_All[[#This Row],[M7+]]-('statistics-M7'!$F20/365))) | S17: =IF(ISBLANK(LSP_All[[#This Row],[M8+]]),"",ABS(LSP_All[[#This Row],[M8+]]-('statistics-M8'!$F20/365))) | U17: =IF(ISBLANK(LSP_All[[#This Row],[M4+]]),"",ABS(LSP_All[[#This Row],[M4+]]-('statistics-M4'!$J20/365))) -> 1.7333014 | V17: =IF(ISBLANK(LSP_All[[#This Row],[M5+]]),"",ABS(LSP_All[[#This Row],[M5+]]-('statistics-M5'!$J20/365))) -> 1.6883973 | W17: =IF(ISBLANK(LSP_All[[#This Row],[M6+]]),"",ABS(LSP_All[[#This Row],[M6+]]-('statistics-M6'!$J20/365))) -> 2.1411918 | X17: =IF(ISBLANK(LSP_All[[#This Row],[M7+]]),"",ABS(LSP_All[[#This Row],[M7+]]-('statistics-M7'!$J20/365))) | Y17: =IF(ISBLANK(LSP_All[[#This Row],[M8+]]),"",ABS(LSP_All[[#This Row],[M8+]]-('statistics-M8'!$J20/365)))
A18: Canada | B18: 2 | C18: 2.442 | D18: 7.177 | I18: =IF(ISBLANK(LSP_All[[#This Row],[M4+]]),"",ABS(LSP_All[[#This Row],[M4+]]-('statistics-M4'!$I21/365))) -> 0.61484098 | J18: =IF(ISBLANK(LSP_All[[#This Row],[M5+]]),"",ABS(LSP_All[[#This Row],[M5+]]-('statistics-M5'!$I21/365))) -> 2.6122941 | K18: =IF(ISBLANK(LSP_All[[#This Row],[M6+]]),"",ABS(LSP_All[[#This Row],[M6+]]-('statistics-M6'!$I21/365))) | L18: =IF(ISBLANK(LSP_All[[#This Row],[M7+]]),"",ABS(LSP_All[[#This Row],[M7+]]-('statistics-M7'!$I21/365))) | M18: =IF(ISBLANK(LSP_All[[#This Row],[M8+]]),"",ABS(LSP_All[[#This Row],[M8+]]-('statistics-M8'!$I21/365))) | O18: =IF(ISBLANK(LSP_All[[#This Row],[M4+]]),"",ABS(LSP_All[[#This Row],[M4+]]-('statistics-M4'!$F21/365))) -> 1.502274 | P18: =IF(ISBLANK(LSP_All[[#This Row],[M5+]]),"",ABS(LSP_All[[#This Row],[M5+]]-('statistics-M5'!$F21/365))) -> 6.5222055 | Q18: =IF(ISBLANK(LSP_All[[#This Row],[M6+]]),"",ABS(LSP_All[[#This Row],[M6+]]-('statistics-M6'!$F21/365))) | R18: =IF(ISBLANK(LSP_All[[#This Row],[M7+]]),"",ABS(LSP_All[[#This Row],[M7+]]-('statistics-M7'!$F21/365))) | S18: =IF(ISBLANK(LSP_All[[#This Row],[M8+]]),"",ABS(LSP_All[[#This Row],[M8+]]-('statistics-M8'!$F21/365))) | U18: =IF(ISBLANK(LSP_All[[#This Row],[M4+]]),"",ABS(LSP_All[[#This Row],[M4+]]-('statistics-M4'!$J21/365))) -> 1.342 | V18: =IF(ISBLANK(LSP_All[[#This Row],[M5+]]),"",ABS(LSP_All[[#This Row],[M5+]]-('statistics-M5'!$J21/365))) -> 4.2619315 | W18: =IF(ISBLANK(LSP_All[[#This Row],[M6+]]),"",ABS(LSP_All[[#This Row],[M6+]]-('statistics-M6'!$J21/365))) | X18: =IF(ISBLANK(LSP_All[[#This Row],[M7+]]),"",ABS(LSP_All[[#This Row],[M7+]]-('statistics-M7'!$J21/365))) | Y18: =IF(ISBLANK(LSP_All[[#This Row],[M8+]]),"",ABS(LSP_All[[#This Row],[M8+]]-('statistics-M8'!$J21/365)))
A19: Canada | B19: 3 | C19: 3.904 | I19: =IF(ISBLANK(LSP_All[[#This Row],[M4+]]),"",ABS(LSP_All[[#This Row],[M4+]]-('statistics-M4'!$I22/365))) -> 1.3533151 | J19: =IF(ISBLANK(LSP_All[[#This Row],[M5+]]),"",ABS(LSP_All[[#This Row],[M5+]]-('statistics-M5'!$I22/365))) | K19: =IF(ISBLANK(LSP_All[[#This Row],[M6+]]),"",ABS(LSP_All[[#This Row],[M6+]]-('statistics-M6'!$I22/365))) | L19: =IF(ISBLANK(LSP_All[[#This Row],[M7+]]),"",ABS(LSP_All[[#This Row],[M7+]]-('statistics-M7'!$I22/365))) | M19: =IF(ISBLANK(LSP_All[[#This Row],[M8+]]),"",ABS(LSP_All[[#This Row],[M8+]]-('statistics-M8'!$I22/365))) | O19: =IF(ISBLANK(LSP_All[[#This Row],[M4+]]),"",ABS(LSP_All[[#This Row],[M4+]]-('statistics-M4'!$F22/365))) -> 3.2355068 | P19: =IF(ISBLANK(LSP_All[[#This Row],[M5+]]),"",ABS(LSP_All[[#This Row],[M5+]]-('statistics-M5'!$F22/365))) | Q19: =IF(ISBLANK(LSP_All[[#This Row],[M6+]]),"",ABS(LSP_All[[#This Row],[M6+]]-('statistics-M6'!$F22/365))) | R19: =IF(ISBLANK(LSP_All[[#This Row],[M7+]]),"",ABS(LSP_All[[#This Row],[M7+]]-('statistics-M7'!$F22/365))) | S19: =IF(ISBLANK(LSP_All[[#This Row],[M8+]]),"",ABS(LSP_All[[#This Row],[M8+]]-('statistics-M8'!$F22/365))) | U19: =IF(ISBLANK(LSP_All[[#This Row],[M4+]]),"",ABS(LSP_All[[#This Row],[M4+]]-('statistics-M4'!$J22/365))) -> 2.1971507 | V19: =IF(ISBLANK(LSP_All[[#This Row],[M5+]]),"",ABS(LSP_All[[#This Row],[M5+]]-('statistics-M5'!$J22/365))) | W19: =IF(ISBLANK(LSP_All[[#This Row],[M6+]]),"",ABS(LSP_All[[#This Row],[M6+]]-('statistics-M6'!$J22/365))) | X19: =IF(ISBLANK(LSP_All[[#This Row],[M7+]]),"",ABS(LSP_All[[#This Row],[M7+]]-('statistics-M7'!$J22/365))) | Y19: =IF(ISBLANK(LSP_All[[#This Row],[M8+]]),"",ABS(LSP_All[[#This Row],[M8+]]-('statistics-M8'!$J22/365)))
A20: Guatemala | B20: 1 | C20: 1.344 | D20: 1.344 | E20: 2.73 | I20: =IF(ISBLANK(LSP_All[[#This Row],[M4+]]),"",ABS(LSP_All[[#This Row],[M4+]]-('statistics-M4'!$I23/365))) -> 0.088845717 | J20: =IF(ISBLANK(LSP_All[[#This Row],[M5+]]),"",ABS(LSP_All[[#This Row],[M5+]]-('statistics-M5'!$I23/365))) -> 0.088845717 | K20: =IF(ISBLANK(LSP_All[[#This Row],[M6+]]),"",ABS(LSP_All[[#This Row],[M6+]]-('statistics-M6'!$I23/365))) -> 0.2332709 | L20: =IF(ISBLANK(LSP_All[[#This Row],[M7+]]),"",ABS(LSP_All[[#This Row],[M7+]]-('statistics-M7'!$I23/365))) | M20: =IF(ISBLANK(LSP_All[[#This Row],[M8+]]),"",ABS(LSP_All[[#This Row],[M8+]]-('statistics-M8'!$I23/365))) | O20: =IF(ISBLANK(LSP_All[[#This Row],[M4+]]),"",ABS(LSP_All[[#This Row],[M4+]]-('statistics-M4'!$F23/365))) -> 0.83989041 | P20: =IF(ISBLANK(LSP_All[[#This Row],[M5+]]),"",ABS(LSP_All[[#This Row],[M5+]]-('statistics-M5'!$F23/365))) -> 0.83989041 | Q20: =IF(ISBLANK(LSP_All[[#This Row],[M6+]]),"",ABS(LSP_All[[#This Row],[M6+]]-('statistics-M6'!$F23/365))) -> 1.8560274 | R20: =IF(ISBLANK(LSP_All[[#This Row],[M7+]]),"",ABS(LSP_All[[#This Row],[M7+]]-('statistics-M7'!$F23/365))) | S20: =IF(ISBLANK(LSP_All[[#This Row],[M8+]]),"",ABS(LSP_All[[#This Row],[M8+]]-('statistics-M8'!$F23/365))) | U20: =IF(ISBLANK(LSP_All[[#This Row],[M4+]]),"",ABS(LSP_All[[#This Row],[M4+]]-('statistics-M4'!$J23/365))) -> 0.45358904 | V20: =IF(ISBLANK(LSP_All[[#This Row],[M5+]]),"",ABS(LSP_All[[#This Row],[M5+]]-('statistics-M5'!$J23/365))) -> 0.45358904 | W20: =IF(ISBLANK(LSP_All[[#This Row],[M6+]]),"",ABS(LSP_All[[#This Row],[M6+]]-('statistics-M6'!$J23/365))) -> 1.0724658 | X20: =IF(ISBLANK(LSP_All[[#This Row],[M7+]]),"",ABS(LSP_All[[#This Row],[M7+]]-('statistics-M7'!$J23/365))) | Y20: =IF(ISBLANK(LSP_All[[#This Row],[M8+]]),"",ABS(LSP_All[[#This Row],[M8+]]-('statistics-M8'!$J23/365)))
A21: Guatemala | B21: 2 | C21: 8.363 | I21: =IF(ISBLANK(LSP_All[[#This Row],[M4+]]),"",ABS(LSP_All[[#This Row],[M4+]]-('statistics-M4'!$I24/365))) -> 2.3713634 | J21: =IF(ISBLANK(LSP_All[[#This Row],[M5+]]),"",ABS(LSP_All[[#This Row],[M5+]]-('statistics-M5'!$I24/365))) | K21: =IF(ISBLANK(LSP_All[[#This Row],[M6+]]),"",ABS(LSP_All[[#This Row],[M6+]]-('statistics-M6'!$I24/365))) | L21: =IF(ISBLANK(LSP_All[[#This Row],[M7+]]),"",ABS(LSP_All[[#This Row],[M7+]]-('statistics-M7'!$I24/365))) | M21: =IF(ISBLANK(LSP_All[[#This Row],[M8+]]),"",ABS(LSP_All[[#This Row],[M8+]]-('statistics-M8'!$I24/365))) | O21: =IF(ISBLANK(LSP_All[[#This Row],[M4+]]),"",ABS(LSP_All[[#This Row],[M4+]]-('statistics-M4'!$F24/365))) -> 7.7849178 | P21: =IF(ISBLANK(LSP_All[[#This Row],[M5+]]),"",ABS(LSP_All[[#This Row],[M5+]]-('statistics-M5'!$F24/365))) | Q21: =IF(ISBLANK(LSP_All[[#This Row],[M6+]]),"",ABS(LSP_All[[#This Row],[M6+]]-('statistics-M6'!$F24/365))) | R21: =IF(ISBLANK(LSP_All[[#This Row],[M7+]]),"",ABS(LSP_All[[#This Row],[M7+]]-('statistics-M7'!$F24/365))) | S21: =IF(ISBLANK(LSP_All[[#This Row],[M8+]]),"",ABS(LSP_All[[#This Row],[M8+]]-('statistics-M8'!$F24/365))) | U21: =IF(ISBLANK(LSP_All[[#This Row],[M4+]]),"",ABS(LSP_All[[#This Row],[M4+]]-('statistics-M4'!$J24/365))) -> 6.2095753 | V21: =IF(ISBLANK(LSP_All[[#This Row],[M5+]]),"",ABS(LSP_All[[#This Row],[M5+]]-('statistics-M5'!$J24/365))) | W21: =IF(ISBLANK(LSP_All[[#This Row],[M6+]]),"",ABS(LSP_All[[#This Row],[M6+]]-('statistics-M6'!$J24/365))) | X21: =IF(ISBLANK(LSP_All[[#This Row],[M7+]]),"",ABS(LSP_All[[#This Row],[M7+]]-('statistics-M7'!$J24/365))) | Y21: =IF(ISBLANK(LSP_All[[#This Row],[M8+]]),"",ABS(LSP_All[[#This Row],[M8+]]-('statistics-M8'!$J24/365)))
A22: Russia | B22: 1 | C22: 1.069 | D22: 1.069 | E22: 1.069 | F22: 2.448 | I22: =IF(ISBLANK(LSP_All[[#This Row],[M4+]]),"",ABS(LSP_All[[#This Row],[M4+]]-('statistics-M4'!$I26/365))) -> 0.22812476 | J22: =IF(ISBLANK(LSP_All[[#This Row],[M5+]]),"",ABS(LSP_All[[#This Row],[M5+]]-('statistics-M5'!$I26/365))) -> 0.22812476 | K22: =IF(ISBLANK(LSP_All[[#This Row],[M6+]]),"",ABS(LSP_All[[#This Row],[M6+]]-('statistics-M6'!$I26/365))) -> 0.2049282 | L22: =IF(ISBLANK(LSP_All[[#This Row],[M7+]]),"",ABS(LSP_All[[#This Row],[M7+]]-('statistics-M7'!$I26/365))) -> 0.18618182 | M22: =IF(ISBLANK(LSP_All[[#This Row],[M8+]]),"",ABS(LSP_All[[#This Row],[M8+]]-('statistics-M8'!$I26/365))) | O22: =IF(ISBLANK(LSP_All[[#This Row],[M4+]]),"",ABS(LSP_All[[#This Row],[M4+]]-('statistics-M4'!$F26/365))) -> 0.55667123 | P22: =IF(ISBLANK(LSP_All[[#This Row],[M5+]]),"",ABS(LSP_All[[#This Row],[M5+]]-('statistics-M5'!$F26/365))) -> 0.55667123 | Q22: =IF(ISBLANK(LSP_All[[#This Row],[M6+]]),"",ABS(LSP_All[[#This Row],[M6+]]-('statistics-M6'!$F26/365))) -> 0.55667123 | R22: =IF(ISBLANK(LSP_All[[#This Row],[M7+]]),"",ABS(LSP_All[[#This Row],[M7+]]-('statistics-M7'!$F26/365))) -> 1.2233425 | S22: =IF(ISBLANK(LSP_All[[#This Row],[M8+]]),"",ABS(LSP_All[[#This Row],[M8+]]-('statistics-M8'!$F26/365))) | U22: =IF(ISBLANK(LSP_All[[#This Row],[M4+]]),"",ABS(LSP_All[[#This Row],[M4+]]-('statistics-M4'!$J26/365))) -> 0.31009589 | V22: =IF(ISBLANK(LSP_All[[#This Row],[M5+]]),"",ABS(LSP_All[[#This Row],[M5+]]-('statistics-M5'!$J26/365))) -> 0.31009589 | W22: =IF(ISBLANK(LSP_All[[#This Row],[M6+]]),"",ABS(LSP_All[[#This Row],[M6+]]-('statistics-M6'!$J26/365))) -> 0.28817808 | X22: =IF(ISBLANK(LSP_All[[#This Row],[M7+]]),"",ABS(LSP_All[[#This Row],[M7+]]-('statistics-M7'!$J26/365))) -> 0.76306849 | Y22: =IF(ISBLANK(LSP_All[[#This Row],[M8+]]),"",ABS(LSP_All[[#This Row],[M8+]]-('statistics-M8'!$J26/365)))
A23: Russia | B23: 2 | C23: 1.75 | D23: 2.072 | E23: 22.207 | I23: =IF(ISBLANK(LSP_All[[#This Row],[M4+]]),"",ABS(LSP_All[[#This Row],[M4+]]-('statistics-M4'!$I27/365))) -> 0.091672675 | J23: =IF(ISBLANK(LSP_All[[#This Row],[M5+]]),"",ABS(LSP_All[[#This Row],[M5+]]-('statistics-M5'!$I27/365))) -> 0.13303267 | K23: =IF(ISBLANK(LSP_All[[#This Row],[M6+]]),"",ABS(LSP_All[[#This Row],[M6+]]-('statistics-M6'!$I27/365))) -> 11.822982 | L23: =IF(ISBLANK(LSP_All[[#This Row],[M7+]]),"",ABS(LSP_All[[#This Row],[M7+]]-('statistics-M7'!$I27/365))) | M23: =IF(ISBLANK(LSP_All[[#This Row],[M8+]]),"",ABS(LSP_All[[#This Row],[M8+]]-('statistics-M8'!$I27/365))) | O23: =IF(ISBLANK(LSP_All[[#This Row],[M4+]]),"",ABS(LSP_All[[#This Row],[M4+]]-('statistics-M4'!$F27/365))) -> 1.0513699 | P23: =IF(ISBLANK(LSP_All[[#This Row],[M5+]]),"",ABS(LSP_All[[#This Row],[M5+]]-('statistics-M5'!$F27/365))) -> 1.5596712 | Q23: =IF(ISBLANK(LSP_All[[#This Row],[M6+]]),"",ABS(LSP_All[[#This Row],[M6+]]-('statistics-M6'!$F27/365))) -> 20.483712 | R23: =IF(ISBLANK(LSP_All[[#This Row],[M7+]]),"",ABS(LSP_All[[#This Row],[M7+]]-('statistics-M7'!$F27/365))) | S23: =IF(ISBLANK(LSP_All[[#This Row],[M8+]]),"",ABS(LSP_All[[#This Row],[M8+]]-('statistics-M8'!$F27/365))) | U23: =IF(ISBLANK(LSP_All[[#This Row],[M4+]]),"",ABS(LSP_All[[#This Row],[M4+]]-('statistics-M4'!$J27/365))) -> 1.0472603 | V23: =IF(ISBLANK(LSP_All[[#This Row],[M5+]]),"",ABS(LSP_All[[#This Row],[M5+]]-('statistics-M5'!$J27/365))) -> 1.2692603 | W23: =IF(ISBLANK(LSP_All[[#This Row],[M6+]]),"",ABS(LSP_All[[#This Row],[M6+]]-('statistics-M6'!$J27/365))) -> 16.397411 | X23: =IF(ISBLANK(LSP_All[[#This Row],[M7+]]),"",ABS(LSP_All[[#This Row],[M7+]]-('statistics-M7'!$J27/365))) | Y23: =IF(ISBLANK(LSP_All[[#This Row],[M8+]]),"",ABS(LSP_All[[#This Row],[M8+]]-('statistics-M8'!$J27/365)))
A24: Russia | B24: 3 | C24: 2.135 | D24: 3.517 | I24: =IF(ISBLANK(LSP_All[[#This Row],[M4+]]),"",ABS(LSP_All[[#This Row],[M4+]]-('statistics-M4'!$I28/365))) -> 0.17385021 | J24: =IF(ISBLANK(LSP_All[[#This Row],[M5+]]),"",ABS(LSP_All[[#This Row],[M5+]]-('statistics-M5'!$I28/365))) -> 0.28375305 | K24: =IF(ISBLANK(LSP_All[[#This Row],[M6+]]),"",ABS(LSP_All[[#This Row],[M6+]]-('statistics-M6'!$I28/365))) | L24: =IF(ISBLANK(LSP_All[[#This Row],[M7+]]),"",ABS(LSP_All[[#This Row],[M7+]]-('statistics-M7'!$I28/365))) | M24: =IF(ISBLANK(LSP_All[[#This Row],[M8+]]),"",ABS(LSP_All[[#This Row],[M8+]]-('statistics-M8'!$I28/365))) | O24: =IF(ISBLANK(LSP_All[[#This Row],[M4+]]),"",ABS(LSP_All[[#This Row],[M4+]]-('statistics-M4'!$F28/365))) -> 0.86376712 | P24: =IF(ISBLANK(LSP_All[[#This Row],[M5+]]),"",ABS(LSP_All[[#This Row],[M5+]]-('statistics-M5'!$F28/365))) -> 2.9909726 | Q24: =IF(ISBLANK(LSP_All[[#This Row],[M6+]]),"",ABS(LSP_All[[#This Row],[M6+]]-('statistics-M6'!$F28/365))) | R24: =IF(ISBLANK(LSP_All[[#This Row],[M7+]]),"",ABS(LSP_All[[#This Row],[M7+]]-('statistics-M7'!$F28/365))) | S24: =IF(ISBLANK(LSP_All[[#This Row],[M8+]]),"",ABS(LSP_All[[#This Row],[M8+]]-('statistics-M8'!$F28/365))) | U24: =IF(ISBLANK(LSP_All[[#This Row],[M4+]]),"",ABS(LSP_All[[#This Row],[M4+]]-('statistics-M4'!$J28/365))) -> 1.2034932 | V24: =IF(ISBLANK(LSP_All[[#This Row],[M5+]]),"",ABS(LSP_All[[#This Row],[M5+]]-('statistics-M5'!$J28/365))) -> 2.2457671 | W24: =IF(ISBLANK(LSP_All[[#This Row],[M6+]]),"",ABS(LSP_All[[#This Row],[M6+]]-('statistics-M6'!$J28/365))) | X24: =IF(ISBLANK(LSP_All[[#This Row],[M7+]]),"",ABS(LSP_All[[#This Row],[M7+]]-('statistics-M7'!$J28/365))) | Y24: =IF(ISBLANK(LSP_All[[#This Row],[M8+]]),"",ABS(LSP_All[[#This Row],[M8+]]-('statistics-M8'!$J28/365)))
A25: China | B25: 1 | C25: 2.658 | D25: 2.658 | E25: 3.006 | I25: =IF(ISBLANK(LSP_All[[#This Row],[M4+]]),"",ABS(LSP_All[[#This Row],[M4+]]-('statistics-M4'!$I29/365))) -> 1.4365162 | J25: =IF(ISBLANK(LSP_All[[#This Row],[M5+]]),"",ABS(LSP_All[[#This Row],[M5+]]-('statistics-M5'!$I29/365))) -> 1.4365162 | K25: =IF(ISBLANK(LSP_All[[#This Row],[M6+]]),"",ABS(LSP_All[[#This Row],[M6+]]-('statistics-M6'!$I29/365))) -> 0.18038675 | L25: =IF(ISBLANK(LSP_All[[#This Row],[M7+]]),"",ABS(LSP_All[[#This Row],[M7+]]-('statistics-M7'!$I29/365))) | M25: =IF(ISBLANK(LSP_All[[#This Row],[M8+]]),"",ABS(LSP_All[[#This Row],[M8+]]-('statistics-M8'!$I29/365))) | O25: =IF(ISBLANK(LSP_All[[#This Row],[M4+]]),"",ABS(LSP_All[[#This Row],[M4+]]-('statistics-M4'!$F29/365))) -> 2.1292329 | P25: =IF(ISBLANK(LSP_All[[#This Row],[M5+]]),"",ABS(LSP_All[[#This Row],[M5+]]-('statistics-M5'!$F29/365))) -> 2.1292329 | Q25: =IF(ISBLANK(LSP_All[[#This Row],[M6+]]),"",ABS(LSP_All[[#This Row],[M6+]]-('statistics-M6'!$F29/365))) -> 1.5830411 | R25: =IF(ISBLANK(LSP_All[[#This Row],[M7+]]),"",ABS(LSP_All[[#This Row],[M7+]]-('statistics-M7'!$F29/365))) | S25: =IF(ISBLANK(LSP_All[[#This Row],[M8+]]),"",ABS(LSP_All[[#This Row],[M8+]]-('statistics-M8'!$F29/365))) | U25: =IF(ISBLANK(LSP_All[[#This Row],[M4+]]),"",ABS(LSP_All[[#This Row],[M4+]]-('statistics-M4'!$J29/365))) -> 1.7730685 | V25: =IF(ISBLANK(LSP_All[[#This Row],[M5+]]),"",ABS(LSP_All[[#This Row],[M5+]]-('statistics-M5'!$J29/365))) -> 1.7730685 | W25: =IF(ISBLANK(LSP_All[[#This Row],[M6+]]),"",ABS(LSP_All[[#This Row],[M6+]]-('statistics-M6'!$J29/365))) -> 1.2388767 | X25: =IF(ISBLANK(LSP_All[[#This Row],[M7+]]),"",ABS(LSP_All[[#This Row],[M7+]]-('statistics-M7'!$J29/365))) | Y25: =IF(ISBLANK(LSP_All[[#This Row],[M8+]]),"",ABS(LSP_All[[#This Row],[M8+]]-('statistics-M8'!$J29/365)))
A26: China | B26: 2 | C26: 2.389 | D26: 1.866 | E26: 9.057 | I26: =IF(ISBLANK(LSP_All[[#This Row],[M4+]]),"",ABS(LSP_All[[#This Row],[M4+]]-('statistics-M4'!$I30/365))) -> 0.89577425 | J26: =IF(ISBLANK(LSP_All[[#This Row],[M5+]]),"",ABS(LSP_All[[#This Row],[M5+]]-('statistics-M5'!$I30/365))) -> 0.23905255 | K26: =IF(ISBLANK(LSP_All[[#This Row],[M6+]]),"",ABS(LSP_All[[#This Row],[M6+]]-('statistics-M6'!$I30/365))) -> 1.5446712 | L26: =IF(ISBLANK(LSP_All[[#This Row],[M7+]]),"",ABS(LSP_All[[#This Row],[M7+]]-('statistics-M7'!$I30/365))) | M26: =IF(ISBLANK(LSP_All[[#This Row],[M8+]]),"",ABS(LSP_All[[#This Row],[M8+]]-('statistics-M8'!$I30/365))) | O26: =IF(ISBLANK(LSP_All[[#This Row],[M4+]]),"",ABS(LSP_All[[#This Row],[M4+]]-('statistics-M4'!$F30/365))) -> 1.7561233 | P26: =IF(ISBLANK(LSP_All[[#This Row],[M5+]]),"",ABS(LSP_All[[#This Row],[M5+]]-('statistics-M5'!$F30/365))) -> 1.2331233 | Q26: =IF(ISBLANK(LSP_All[[#This Row],[M6+]]),"",ABS(LSP_All[[#This Row],[M6+]]-('statistics-M6'!$F30/365))) -> 8.3720685 | R26: =IF(ISBLANK(LSP_All[[#This Row],[M7+]]),"",ABS(LSP_All[[#This Row],[M7+]]-('statistics-M7'!$F30/365))) | S26: =IF(ISBLANK(LSP_All[[#This Row],[M8+]]),"",ABS(LSP_All[[#This Row],[M8+]]-('statistics-M8'!$F30/365))) | U26: =IF(ISBLANK(LSP_All[[#This Row],[M4+]]),"",ABS(LSP_All[[#This Row],[M4+]]-('statistics-M4'!$J30/365))) -> 1.4958493 | V26: =IF(ISBLANK(LSP_All[[#This Row],[M5+]]),"",ABS(LSP_All[[#This Row],[M5+]]-('statistics-M5'!$J30/365))) -> 0.90161644 | W26: =IF(ISBLANK(LSP_All[[#This Row],[M6+]]),"",ABS(LSP_All[[#This Row],[M6+]]-('statistics-M6'!$J30/365))) -> 4.5953562 | X26: =IF(ISBLANK(LSP_All[[#This Row],[M7+]]),"",ABS(LSP_All[[#This Row],[M7+]]-('statistics-M7'!$J30/365))) | Y26: =IF(ISBLANK(LSP_All[[#This Row],[M8+]]),"",ABS(LSP_All[[#This Row],[M8+]]-('statistics-M8'!$J30/365)))
