Workbook

Sheet results_v1
A1: country | B1: cluster_id | C1: M4+ | D1: M5+ | E1: M6+ | F1: M7+ | G1: M8+
A2: Japan | B2: 1 | C2: =IF(ISBLANK(VLOOKUP(A2&" "&B2,NFFT_M4!$A$2:$D$100,4,FALSE))," ",_xlfn.IFNA(VLOOKUP(A2&" "&B2,NFFT_M4!$A$2:$D$100,4,FALSE)," ")) -> 1.541 | D2: =IF(ISBLANK(VLOOKUP(A2&" "&B2,NFFT_M5!$A$2:$D$100,4,FALSE))," ",_xlfn.IFNA(VLOOKUP(A2&" "&B2,NFFT_M5!$A$2:$D$100,4,FALSE)," ")) -> 1.541 | E2: =IF(ISBLANK(VLOOKUP(A2&" "&B2,NFFT_M6!$A$2:$D$100,4,FALSE))," ",_xlfn.IFNA(VLOOKUP(A2&" "&B2,NFFT_M6!$A$2:$D$100,4,FALSE)," ")) -> 1.833 | F2: =IF(ISBLANK(VLOOKUP(A2&" "&B2,NFFT_M7!$A$2:$D$100,4,FALSE))," ",_xlfn.IFNA(VLOOKUP(A2&" "&B2,NFFT_M7!$A$2:$D$100,4,FALSE)," ")) -> 2.587 | G2: =IF(ISBLANK(VLOOKUP(A2&" "&B2,NFFT_M8!$A$2:$D$100,4,FALSE))," ",_xlfn.IFNA(VLOOKUP(A2&" "&B2,NFFT_M8!$A$2:$D$100,4,FALSE)," "))
A3: Japan | B3: 2 | C3: =IF(ISBLANK(VLOOKUP(A3&" "&B3,NFFT_M4!$A$2:$D$100,4,FALSE))," ",_xlfn.IFNA(VLOOKUP(A3&" "&B3,NFFT_M4!$A$2:$D$100,4,FALSE)," ")) -> 1.506 | D3: =IF(ISBLANK(VLOOKUP(A3&" "&B3,NFFT_M5!$A$2:$D$100,4,FALSE))," ",_xlfn.IFNA(VLOOKUP(A3&" "&B3,NFFT_M5!$A$2:$D$100,4,FALSE)," ")) -> 1.506 | E3: =IF(ISBLANK(VLOOKUP(A3&" "&B3,NFFT_M6!$A$2:$D$100,4,FALSE))," ",_xlfn.IFNA(VLOOKUP(A3&" "&B3,NFFT_M6!$A$2:$D$100,4,FALSE)," ")) -> 2.743 | F3: =IF(ISBLANK(VLOOKUP(A3&" "&B3,NFFT_M7!$A$2:$D$100,4,FALSE))," ",_xlfn.IFNA(VLOOKUP(A3&" "&B3,NFFT_M7!$A$2:$D$100,4,FALSE)," ")) | G3: =IF(ISBLANK(VLOOKUP(A3&" "&B3,NFFT_M8!$A$2:$D$100,4,FALSE))," ",_xlfn.IFNA(VLOOKUP(A3&" "&B3,NFFT_M8!$A$2:$D$100,4,FALSE)," "))
A4: Japan | B4: 3 | C4: =IF(ISBLANK(VLOOKUP(A4&" "&B4,NFFT_M4!$A$2:$D$100,4,FALSE))," ",_xlfn.IFNA(VLOOKUP(A4&" "&B4,NFFT_M4!$A$2:$D$100,4,FALSE)," ")) | D4: =IF(ISBLANK(VLOOKUP(A4&" "&B4,NFFT_M5!$A$2:$D$100,4,FALSE))," ",_xlfn.IFNA(VLOOKUP(A4&" "&B4,NFFT_M5!$A$2:$D$100,4,FALSE)," ")) -> 3.804 | E4: =IF(ISBLANK(VLOOKUP(A4&" "&B4,NFFT_M6!$A$2:$D$100,4,FALSE))," ",_xlfn.IFNA(VLOOKUP(A4&" "&B4,NFFT_M6!$A$2:$D$100,4,FALSE)," ")) | F4: =IF(ISBLANK(VLOOKUP(A4&" "&B4,NFFT_M7!$A$2:$D$100,4,FALSE))," ",_xlfn.IFNA(VLOOKUP(A4&" "&B4,NFFT_M7!$A$2:$D$100,4,FALSE)," ")) | G4: =IF(ISBLANK(VLOOKUP(A4&" "&B4,NFFT_M8!$A$2:$D$100,4,FALSE))," ",_xlfn.IFNA(VLOOKUP(A4&" "&B4,NFFT_M8!$A$2:$D$100,4,FALSE)," "))
A5: Papua New Guinea | B5: 1 | C5: =IF(ISBLANK(VLOOKUP(A5&" "&B5,NFFT_M4!$A$2:$D$100,4,FALSE))," ",_xlfn.IFNA(VLOOKUP(A5&" "&B5,NFFT_M4!$A$2:$D$100,4,FALSE)," ")) -> 2.11 | D5: =IF(ISBLANK(VLOOKUP(A5&" "&B5,NFFT_M5!$A$2:$D$100,4,FALSE))," ",_xlfn.IFNA(VLOOKUP(A5&" "&B5,NFFT_M5!$A$2:$D$100,4,FALSE)," ")) -> 2.11 | E5: =IF(ISBLANK(VLOOKUP(A5&" "&B5,NFFT_M6!$A$2:$D$100,4,FALSE))," ",_xlfn.IFNA(VLOOKUP(A5&" "&B5,NFFT_M6!$A$2:$D$100,4,FALSE)," ")) -> 2.11 | F5: =IF(ISBLANK(VLOOKUP(A5&" "&B5,NFFT_M7!$A$2:$D$100,4,FALSE))," ",_xlfn.IFNA(VLOOKUP(A5&" "&B5,NFFT_M7!$A$2:$D$100,4,FALSE)," ")) -> 2.795 | G5: =IF(ISBLANK(VLOOKUP(A5&" "&B5,NFFT_M8!$A$2:$D$100,4,FALSE))," ",_xlfn.IFNA(VLOOKUP(A5&" "&B5,NFFT_M8!$A$2:$D$100,4,FALSE)," "))
A6: Papua New Guinea | B6: 2 | C6: =IF(ISBLANK(VLOOKUP(A6&" "&B6,NFFT_M4!$A$2:$D$100,4,FALSE))," ",_xlfn.IFNA(VLOOKUP(A6&" "&B6,NFFT_M4!$A$2:$D$100,4,FALSE)," ")) -> 1.231 | D6: =IF(ISBLANK(VLOOKUP(A6&" "&B6,NFFT_M5!$A$2:$D$100,4,FALSE))," ",_xlfn.IFNA(VLOOKUP(A6&" "&B6,NFFT_M5!$A$2:$D$100,4,FALSE)," ")) -> 1.277 | E6: =IF(ISBLANK(VLOOKUP(A6&" "&B6,NFFT_M6!$A$2:$D$100,4,FALSE))," ",_xlfn.IFNA(VLOOKUP(A6&" "&B6,NFFT_M6!$A$2:$D$100,4,FALSE)," ")) | F6: =IF(ISBLANK(VLOOKUP(A6&" "&B6,NFFT_M7!$A$2:$D$100,4,FALSE))," ",_xlfn.IFNA(VLOOKUP(A6&" "&B6,NFFT_M7!$A$2:$D$100,4,FALSE)," ")) | G6: =IF(ISBLANK(VLOOKUP(A6&" "&B6,NFFT_M8!$A$2:$D$100,4,FALSE))," ",_xlfn.IFNA(VLOOKUP(A6&" "&B6,NFFT_M8!$A$2:$D$100,4,FALSE)," "))
A7: Papua New Guinea | B7: 3 | C7: =IF(ISBLANK(VLOOKUP(A7&" "&B7,NFFT_M4!$A$2:$D$100,4,FALSE))," ",_xlfn.IFNA(VLOOKUP(A7&" "&B7,NFFT_M4!$A$2:$D$100,4,FALSE)," ")) -> 2.373 | D7: =IF(ISBLANK(VLOOKUP(A7&" "&B7,NFFT_M5!$A$2:$D$100,4,FALSE))," ",_xlfn.IFNA(VLOOKUP(A7&" "&B7,NFFT_M5!$A$2:$D$100,4,FALSE)," ")) -> 5.586 | E7: =IF(ISBLANK(VLOOKUP(A7&" "&B7,NFFT_M6!$A$2:$D$100,4,FALSE))," ",_xlfn.IFNA(VLOOKUP(A7&" "&B7,NFFT_M6!$A$2:$D$100,4,FALSE)," ")) | F7: =IF(ISBLANK(VLOOKUP(A7&" "&B7,NFFT_M7!$A$2:$D$100,4,FALSE))," ",_xlfn.IFNA(VLOOKUP(A7&" "&B7,NFFT_M7!$A$2:$D$100,4,FALSE)," ")) | G7: =IF(ISBLANK(VLOOKUP(A7&" "&B7,NFFT_M8!$A$2:$D$100,4,FALSE))," ",_xlfn.IFNA(VLOOKUP(A7&" "&B7,NFFT_M8!$A$2:$D$100,4,FALSE)," "))
A8: Philippines | B8: 1 | C8: =IF(ISBLANK(VLOOKUP(A8&" "&B8,NFFT_M4!$A$2:$D$100,4,FALSE))," ",_xlfn.IFNA(VLOOKUP(A8&" "&B8,NFFT_M4!$A$2:$D$100,4,FALSE)," ")) -> 1.602 | D8: =IF(ISBLANK(VLOOKUP(A8&" "&B8,NFFT_M5!$A$2:$D$100,4,FALSE))," ",_xlfn.IFNA(VLOOKUP(A8&" "&B8,NFFT_M5!$A$2:$D$100,4,FALSE)," ")) -> 1.602 | E8: =IF(ISBLANK(VLOOKUP(A8&" "&B8,NFFT_M6!$A$2:$D$100,4,FALSE))," ",_xlfn.IFNA(VLOOKUP(A8&" "&B8,NFFT_M6!$A$2:$D$100,4,FALSE)," ")) -> 1.592 | F8: =IF(ISBLANK(VLOOKUP(A8&" "&B8,NFFT_M7!$A$2:$D$100,4,FALSE))," ",_xlfn.IFNA(VLOOKUP(A8&" "&B8,NFFT_M7!$A$2:$D$100,4,FALSE)," ")) -> 2.491 | G8: =IF(ISBLANK(VLOOKUP(A8&" "&B8,NFFT_M8!$A$2:$D$100,4,FALSE))," ",_xlfn.IFNA(VLOOKUP(A8&" "&B8,NFFT_M8!$A$2:$D$100,4,FALSE)," "))
A9: Philippines | B9: 2 | C9: =IF(ISBLANK(VLOOKUP(A9&" "&B9,NFFT_M4!$A$2:$D$100,4,FALSE))," ",_xlfn.IFNA(VLOOKUP(A9&" "&B9,NFFT_M4!$A$2:$D$100,4,FALSE)," ")) | D9: =IF(ISBLANK(VLOOKUP(A9&" "&B9,NFFT_M5!$A$2:$D$100,4,FALSE))," ",_xlfn.IFNA(VLOOKUP(A9&" "&B9,NFFT_M5!$A$2:$D$100,4,FALSE)," ")) | E9: =IF(ISBLANK(VLOOKUP(A9&" "&B9,NFFT_M6!$A$2:$D$100,4,FALSE))," ",_xlfn.IFNA(VLOOKUP(A9&" "&B9,NFFT_M6!$A$2:$D$100,4,FALSE)," ")) | F9: =IF(ISBLANK(VLOOKUP(A9&" "&B9,NFFT_M7!$A$2:$D$100,4,FALSE))," ",_xlfn.IFNA(VLOOKUP(A9&" "&B9,NFFT_M7!$A$2:$D$100,4,FALSE)," ")) | G9: =IF(ISBLANK(VLOOKUP(A9&" "&B9,NFFT_M8!$A$2:$D$100,4,FALSE))," ",_xlfn.IFNA(VLOOKUP(A9&" "&B9,NFFT_M8!$A$2:$D$100,4,FALSE)," "))
A10: Tonga | B10: 1 | C10: =IF(ISBLANK(VLOOKUP(A10&" "&B10,NFFT_M4!$A$2:$D$100,4,FALSE))," ",_xlfn.IFNA(VLOOKUP(A10&" "&B10,NFFT_M4!$A$2:$D$100,4,FALSE)," ")) -> 1.431 | D10: =IF(ISBLANK(VLOOKUP(A10&" "&B10,NFFT_M5!$A$2:$D$100,4,FALSE))," ",_xlfn.IFNA(VLOOKUP(A10&" "&B10,NFFT_M5!$A$2:$D$100,4,FALSE)," ")) -> 1.431 | E10: =IF(ISBLANK(VLOOKUP(A10&" "&B10,NFFT_M6!$A$2:$D$100,4,FALSE))," ",_xlfn.IFNA(VLOOKUP(A10&" "&B10,NFFT_M6!$A$2:$D$100,4,FALSE)," ")) -> 1.662 | F10: =IF(ISBLANK(VLOOKUP(A10&" "&B10,NFFT_M7!$A$2:$D$100,4,FALSE))," ",_xlfn.IFNA(VLOOKUP(A10&" "&B10,NFFT_M7!$A$2:$D$100,4,FALSE)," ")) -> 4.192 | G10: =IF(ISBLANK(VLOOKUP(A10&" "&B10,NFFT_M8!$A$2:$D$100,4,FALSE))," ",_xlfn.IFNA(VLOOKUP(A10&" "&B10,NFFT_M8!$A$2:$D$100,4,FALSE)," "))
A11: USA | B11: 1 | C11: =IF(ISBLANK(VLOOKUP(A11&" "&B11,NFFT_M4!$A$2:$D$100,4,FALSE))," ",_xlfn.IFNA(VLOOKUP(A11&" "&B11,NFFT_M4!$A$2:$D$100,4,FALSE)," ")) -> 2.091 | D11: =IF(ISBLANK(VLOOKUP(A11&" "&B11,NFFT_M5!$A$2:$D$100,4,FALSE))," ",_xlfn.IFNA(VLOOKUP(A11&" "&B11,NFFT_M5!$A$2:$D$100,4,FALSE)," ")) -> 2.091 | E11: =IF(ISBLANK(VLOOKUP(A11&" "&B11,NFFT_M6!$A$2:$D$100,4,FALSE))," ",_xlfn.IFNA(VLOOKUP(A11&" "&B11,NFFT_M6!$A$2:$D$100,4,FALSE)," ")) -> 1.804 | F11: =IF(ISBLANK(VLOOKUP(A11&" "&B11,NFFT_M7!$A$2:$D$100,4,FALSE))," ",_xlfn.IFNA(VLOOKUP(A11&" "&B11,NFFT_M7!$A$2:$D$100,4,FALSE)," ")) -> 5.993 | G11: =IF(ISBLANK(VLOOKUP(A11&" "&B11,NFFT_M8!$A$2:$D$100,4,FALSE))," ",_xlfn.IFNA(VLOOKUP(A11&" "&B11,NFFT_M8!$A$2:$D$100,4,FALSE)," "))
A12: USA | B12: 2 | C12: =IF(ISBLANK(VLOOKUP(A12&" "&B12,NFFT_M4!$A$2:$D$100,4,FALSE))," ",_xlfn.IFNA(VLOOKUP(A12&" "&B12,NFFT_M4!$A$2:$D$100,4,FALSE)," ")) -> 1.682 | D12: =IF(ISBLANK(VLOOKUP(A12&" "&B12,NFFT_M5!$A$2:$D$100,4,FALSE))," ",_xlfn.IFNA(VLOOKUP(A12&" "&B12,NFFT_M5!$A$2:$D$100,4,FALSE)," ")) -> 2.159 | E12: =IF(ISBLANK(VLOOKUP(A12&" "&B12,NFFT_M6!$A$2:$D$100,4,FALSE))," ",_xlfn.IFNA(VLOOKUP(A12&" "&B12,NFFT_M6!$A$2:$D$100,4,FALSE)," ")) -> 2.322 | F12: =IF(ISBLANK(VLOOKUP(A12&" "&B12,NFFT_M7!$A$2:$D$100,4,FALSE))," ",_xlfn.IFNA(VLOOKUP(A12&" "&B12,NFFT_M7!$A$2:$D$100,4,FALSE)," ")) | G12: =IF(ISBLANK(VLOOKUP(A12&" "&B12,NFFT_M8!$A$2:$D$100,4,FALSE))," ",_xlfn.IFNA(VLOOKUP(A12&" "&B12,NFFT_M8!$A$2:$D$100,4,FALSE)," "))
A13: USA | B13: 3 | C13: =IF(ISBLANK(VLOOKUP(A13&" "&B13,NFFT_M4!$A$2:$D$100,4,FALSE))," ",_xlfn.IFNA(VLOOKUP(A13&" "&B13,NFFT_M4!$A$2:$D$100,4,FALSE)," ")) -> 1.746 | D13: =IF(ISBLANK(VLOOKUP(A13&" "&B13,NFFT_M5!$A$2:$D$100,4,FALSE))," ",_xlfn.IFNA(VLOOKUP(A13&" "&B13,NFFT_M5!$A$2:$D$100,4,FALSE)," ")) -> 2.673 | E13: =IF(ISBLANK(VLOOKUP(A13&" "&B13,NFFT_M6!$A$2:$D$100,4,FALSE))," ",_xlfn.IFNA(VLOOKUP(A13&" "&B13,NFFT_M6!$A$2:$D$100,4,FALSE)," ")) -> 4.532 | F13: =IF(ISBLANK(VLOOKUP(A13&" "&B13,NFFT_M7!$A$2:$D$100,4,FALSE))," ",_xlfn.IFNA(VLOOKUP(A13&" "&B13,NFFT_M7!$A$2:$D$100,4,FALSE)," ")) | G13: =IF(ISBLANK(VLOOKUP(A13&" "&B13,NFFT_M8!$A$2:$D$100,4,FALSE))," ",_xlfn.IFNA(VLOOKUP(A13&" "&B13,NFFT_M8!$A$2:$D$100,4,FALSE)," "))
... A69: Saint Helena | B69: 2 | C69: =IF(ISBLANK(VLOOKUP(A69&" "&B69,NFFT_M4!$A$2:$D$100,4,FALSE))," ",_xlfn.IFNA(VLOOKUP(A69&" "&B69,NFFT_M4!$A$2:$D$100,4,FALSE)," ")) | D69: =IF(ISBLANK(VLOOKUP(A69&" "&B69,NFFT_M5!$A$2:$D$100,4,FALSE))," ",_xlfn.IFNA(VLOOKUP(A69&" "&B69,NFFT_M5!$A$2:$D$100,4,FALSE)," ")) | E69: =IF(ISBLANK(VLOOKUP(A69&" "&B69,NFFT_M6!$A$2:$D$100,4,FALSE))," ",_xlfn.IFNA(VLOOKUP(A69&" "&B69,NFFT_M6!$A$2:$D$100,4,FALSE)," ")) | F69: =IF(ISBLANK(VLOOKUP(A69&" "&B69,NFFT_M7!$A$2:$D$100,4,FALSE))," ",_xlfn.IFNA(VLOOKUP(A69&" "&B69,NFFT_M7!$A$2:$D$100,4,FALSE)," ")) | G69: =IF(ISBLANK(VLOOKUP(A69&" "&B69,NFFT_M8!$A$2:$D$100,4,FALSE))," ",_xlfn.IFNA(VLOOKUP(A69&" "&B69,NFFT_M8!$A$2:$D$100,4,FALSE)," "))

Sheet NFFT_M4
B1: country | C1: cluster | D1: return_P_nomes | E1: avg_gap | F1: Number of record | G1: Number of the day | H1: percent | I1: highest_amplitude | J1: highest_frequency | K1: highest_years_not_normalised
A2: =NFFT_M4[[#This Row],[country]]& " "&NFFT_M4[[#This Row],[cluster]] -> Japan 1 | B2: Japan | C2: 1 | D2: 1.541 | E2: 322.23776 | F2: 144 | G2: 46080 | H2: 81.944444 | I2: 0.13393399 | J2: 59 | K2: 2.1383079
A3: =NFFT_M4[[#This Row],[country]]& " "&NFFT_M4[[#This Row],[cluster]] -> Japan 2 | B3: Japan | C3: 2 | D3: 1.506 | E3: 353.99225 | F3: 130 | G3: 45665 | H3: 83.076923 | I3: 0.1096788 | J3: 54 | K3: 2.3152584
A4: =NFFT_M4[[#This Row],[country]]& " "&NFFT_M4[[#This Row],[cluster]] -> Japan 3 | B4: Japan | C4: 3 | E4: 1285.7778 | F4: 28 | G4: 34716 | H4: 0 | I4: 0 | J4: 0 | K4: 0
A5: =NFFT_M4[[#This Row],[country]]& " "&NFFT_M4[[#This Row],[cluster]] -> Papua New Guinea 1 | B5: Papua New Guinea | C5: 1 | D5: 2.11 | E5: 330.02857 | F5: 141 | G5: 46204 | H5: 60 | I5: 0.10182727 | J5: 42 | K5: 3.0118966
A6: =NFFT_M4[[#This Row],[country]]& " "&NFFT_M4[[#This Row],[cluster]] -> Papua New Guinea 2 | B6: Papua New Guinea | C6: 2 | D6: 1.231 | E6: 454.24138 | F6: 59 | G6: 26346 | H6: 58.62069 | I6: 0.20915628 | J6: 17 | K6: 4.2430245
A7: =NFFT_M4[[#This Row],[country]]& " "&NFFT_M4[[#This Row],[cluster]] -> Papua New Guinea 3 | B7: Papua New Guinea | C7: 3 | D7: 2.373 | E7: 826.97917 | F7: 49 | G7: 39695 | H7: 45.833333 | I7: 0.10459078 | J7: 11 | K7: 9.8799079
A8: =NFFT_M4[[#This Row],[country]]& " "&NFFT_M4[[#This Row],[cluster]] -> Philippines 1 | B8: Philippines | C8: 1 | D8: 1.602 | E8: 315.73611 | F8: 145 | G8: 45466 | H8: 77.777778 | I8: 0.19507018 | J8: 56 | K8: 2.2228415
A9: =NFFT_M4[[#This Row],[country]]& " "&NFFT_M4[[#This Row],[cluster]] -> Philippines 2 | B9: Philippines | C9: 2 | E9: 0 | F9: 0 | G9: 0 | H9: 0 | I9: 0 | J9: 0 | K9: 0
A10: =NFFT_M4[[#This Row],[country]]& " "&NFFT_M4[[#This Row],[cluster]] -> Tonga 1 | B10: Tonga | C10: 1 | D10: 1.431 | E10: 348.87597 | F10: 130 | G10: 45005 | H10: 86.153846 | I10: 0.15045955 | J10: 56 | K10: 2.2003031
A11: =NFFT_M4[[#This Row],[country]]& " "&NFFT_M4[[#This Row],[cluster]] -> USA 1 | B11: USA | C11: 1 | D11: 2.091 | E11: 327.15714 | F11: 141 | G11: 45802 | H11: 60 | I11: 0.16495632 | J11: 42 | K11: 2.9856915
A12: =NFFT_M4[[#This Row],[country]]& " "&NFFT_M4[[#This Row],[cluster]] -> USA 2 | B12: USA | C12: 2 | D12: 1.682 | E12: 319.82639 | F12: 145 | G12: 46055 | H12: 75 | I12: 0.23259604 | J12: 54 | K12: 2.3350318
A13: =NFFT_M4[[#This Row],[country]]& " "&NFFT_M4[[#This Row],[cluster]] -> USA 3 | B13: USA | C13: 3 | D13: 1.746 | E13: 349.62791 | F13: 130 | G13: 45102 | H13: 70.769231 | I13: 0.13246328 | J13: 46 | K13: 2.6844032
A14: =NFFT_M4[[#This Row],[country]]& " "&NFFT_M4[[#This Row],[cluster]] -> Mexico 1 | B14: Mexico | C14: 1 | D14: 2.481 | E14: 365.10317 | F14: 127 | G14: 46003 | H14: 50.793651 | I14: 0.16985697 | J14: 32 | K14: 3.9359172
A15: =NFFT_M4[[#This Row],[country]]& " "&NFFT_M4[[#This Row],[cluster]] -> Mexico 2 | B15: Mexico | C15: 2 | D15: 2.433 | E15: 369.88525 | F15: 123 | G15: 45126 | H15: 50.819672 | I15: 0.19999227 | J15: 31 | K15: 3.9854276
A16: =NFFT_M4[[#This Row],[country]]& " "&NFFT_M4[[#This Row],[cluster]] -> Mexico 3 | B16: Mexico | C16: 3 | D16: 1.85 | E16: 560.375 | F16: 65 | G16: 35864 | H16: 53.125 | I16: 0.15704008 | J16: 17 | K16: 5.7758989
A17: =NFFT_M4[[#This Row],[country]]& " "&NFFT_M4[[#This Row],[cluster]] -> Canada 1 | B17: Canada | C17: 1 | D17: 2.829 | E17: 430.03061 | F17: 99 | G17: 42143 | H17: 40.816327 | I17: 0.19901055 | J17: 20 | K17: 5.7690623
A18: =NFFT_M4[[#This Row],[country]]& " "&NFFT_M4[[#This Row],[cluster]] -> Canada 2 | B18: Canada | C18: 2 | D18: 1.757 | E18: 666.91304 | F18: 47 | G18: 30678 | H18: 47.826087 | I18: 0.14856584 | J18: 11 | K18: 7.635617
A19: =NFFT_M4[[#This Row],[country]]& " "&NFFT_M4[[#This Row],[cluster]] -> Canada 3 | B19: Canada | C19: 3 | D19: 2.423 | E19: 931 | F19: 20 | G19: 17689 | H19: 20 | I19: 0.73989738 | J19: 2 | K19: 24.214921
A20: =NFFT_M4[[#This Row],[country]]& " "&NFFT_M4[[#This Row],[cluster]] -> Guatemala 1 | B20: Guatemala | C20: 1 | D20: 2.071 | E20: 458.13131 | F20: 100 | G20: 45355 | H20: 60 | I20: 0.1352419 | J20: 30 | K20: 4.1391741
A21: =NFFT_M4[[#This Row],[country]]& " "&NFFT_M4[[#This Row],[cluster]] -> Guatemala 2 | B21: Guatemala | C21: 2 | E21: 2186.9474 | F21: 20 | G21: 41552 | H21: 0 | I21: 0 | J21: 0 | K21: 0
A22: =NFFT_M4[[#This Row],[country]]& " "&NFFT_M4[[#This Row],[cluster]] -> Russia 1 | B22: Russia | C22: 1 | D22: 1.54 | E22: 306.91946 | F22: 150 | G22: 45731 | H22: 81.333333 | I22: 0.11520888 | J22: 61 | K22: 2.0525353
A23: =NFFT_M4[[#This Row],[country]]& " "&NFFT_M4[[#This Row],[cluster]] -> Russia 2 | B23: Russia | C23: 2 | D23: 2.395 | E23: 605.28947 | F23: 77 | G23: 46002 | H23: 52.631579 | I23: 0.12754727 | J23: 20 | K23: 6.2973306
A24: =NFFT_M4[[#This Row],[country]]& " "&NFFT_M4[[#This Row],[cluster]] -> Russia 3 | B24: Russia | C24: 3 | D24: 2.472 | E24: 715.81967 | F24: 62 | G24: 43665 | H24: 48.387097 | I24: 0.16217158 | J24: 15 | K24: 7.9698836
A25: =NFFT_M4[[#This Row],[country]]& " "&NFFT_M4[[#This Row],[cluster]] -> China 1 | B25: China | C25: 1 | D25: 2.622 | E25: 445.84158 | F25: 102 | G25: 45030 | H25: 47.058824 | I25: 0.101602 | J25: 24 | K25: 5.1368925
A26: =NFFT_M4[[#This Row],[country]]& " "&NFFT_M4[[#This Row],[cluster]] -> China 2 | B26: China | C26: 2 | D26: 2.017 | E26: 545.0274 | F26: 74 | G26: 39787 | H26: 54.054054 | I26: 0.14847976 | J26: 20 | K26: 5.4465435
A27: =NFFT_M4[[#This Row],[country]]& " "&NFFT_M4[[#This Row],[cluster]] -> China 3 | B27: China | C27: 3 | D27: 2.024 | E27: 512.97222 | F27: 73 | G27: 36934 | H27: 50 | I27: 0.17377613 | J27: 18 | K27: 5.6177656
A28: =NFFT_M4[[#This Row],[country]]& " "&NFFT_M4[[#This Row],[cluster]] -> India 1 | B28: India | C28: 1 | D28: 2.661 | E28: 433.67327 | F28: 102 | G28: 43801 | H28: 45.098039 | I28: 0.1193365 | J28: 23 | K28: 5.2139392
A29: =NFFT_M4[[#This Row],[country]]& " "&NFFT_M4[[#This Row],[cluster]] -> India 2 | B29: India | C29: 2 | D29: 2.118 | E29: 416.72381 | F29: 106 | G29: 43756 | H29: 56.603774 | I29: 0.11678401 | J29: 30 | K29: 3.9932466
A30: =NFFT_M4[[#This Row],[country]]& " "&NFFT_M4[[#This Row],[cluster]] -> India 3 | B30: India | C30: 3 | D30: 2.829 | E30: 533.21687 | F30: 84 | G30: 44257 | H30: 42.857143 | I30: 0.12062106 | J30: 18 | K30: 6.7316146
A31: =NFFT_M4[[#This Row],[country]]& " "&NFFT_M4[[#This Row],[cluster]] -> Iran 1 | B31: Iran | C31: 1 | D31: 2.157 | E31: 387.79825 | F31: 115 | G31: 44209 | H31: 56.140351 | I31: 0.10108108 | J31: 32 | K31: 3.7824264
A32: =NFFT_M4[[#This Row],[country]]& " "&NFFT_M4[[#This Row],[cluster]] -> Iran 2 | B32: Iran | C32: 2 | D32: 2.236 | E32: 513.65753 | F32: 74 | G32: 37497 | H32: 45.945946 | I32: 0.14219274 | J32: 17 | K32: 6.0388936
A33: =NFFT_M4[[#This Row],[country]]& " "&NFFT_M4[[#This Row],[cluster]] -> Iran 3 | B33: Iran | C33: 3 | D33: 2.222 | E33: 686.2623 | F33: 62 | G33: 41862 | H33: 51.612903 | I33: 0.065360641 | J33: 16 | K33: 7.1632444
... A37: =NFFT_M4[[#This Row],[country]]& " "&NFFT_M4[[#This Row],[cluster]] -> Dominican 1 | B37: Dominican | C37: 1 | D37: 2.053 | E37: 488.40476 | F37: 85 | G37: 41026 | H37: 54.761905 | I37: 0.098894141 | J37: 23 | K37: 4.8836116
A38: =NFFT_M4[[#This Row],[country]]& " "&NFFT_M4[[#This Row],[cluster]] -> Dominican 2 | B38: Dominican | C38: 2 | E38: 1447 | F38: 13 | G38: 17364 | H38: 0 | I38: 0 | J38: 0 | K38: 0
A39: =NFFT_M4[[#This Row],[country]]& " "&NFFT_M4[[#This Row],[cluster]] -> Chile 1 | B39: Chile | C39: 1 | D39: 1.892 | E39: 345.94574 | F39: 130 | G39: 44627 | H39: 64.615385 | I39: 0.13434377 | J39: 42 | K39: 2.9090968
A40: =NFFT_M4[[#This Row],[country]]& " "&NFFT_M4[[#This Row],[cluster]] -> Chile 2 | B40: Chile | C40: 2 | D40: 1.748 | E40: 423.88608 | F40: 80 | G40: 33487 | H40: 52.5 | I40: 0.15265829 | J40: 21 | K40: 4.365829
A41: =NFFT_M4[[#This Row],[country]]& " "&NFFT_M4[[#This Row],[cluster]] -> Chile 3 | B41: Chile | C41: 3 | D41: 2.119 | E41: 543.20896 | F41: 68 | G41: 36395 | H41: 47.058824 | I41: 0.079839193 | J41: 16 | K41: 6.227755
A42: =NFFT_M4[[#This Row],[country]]& " "&NFFT_M4[[#This Row],[cluster]] -> Argentina 1 | B42: Argentina | C42: 1 | D42: 2.295 | E42: 502.03896 | F42: 78 | G42: 38657 | H42: 46.153846 | I42: 0.13012822 | J42: 18 | K42: 5.8798388
A43: =NFFT_M4[[#This Row],[country]]& " "&NFFT_M4[[#This Row],[cluster]] -> Argentina 2 | B43: Argentina | C43: 2 | D43: 2.487 | E43: 526.15942 | F43: 70 | G43: 36305 | H43: 40 | I43: 0.17039183 | J43: 14 | K43: 7.0998338
...

Sheet NFFT_M5
B1: country | C1: cluster | D1: return_P_nomes | E1: avg_gap | F1: Number of record | G1: Number of the day | H1: percent | I1: highest_amplitude | J1: highest_frequency | K1: highest_years_not_normalised
A2: =NFFT_M5[[#This Row],[country]]& " "&NFFT_M5[[#This Row],[cluster]] -> Japan 1 | B2: Japan | C2: 1 | D2: 1.541 | E2: 322.23776 | F2: 144 | G2: 46080 | H2: 81.944444 | I2: 0.13393399 | J2: 59 | K2: 2.1383079
A3: =NFFT_M5[[#This Row],[country]]& " "&NFFT_M5[[#This Row],[cluster]] -> Japan 2 | B3: Japan | C3: 2 | D3: 1.506 | E3: 353.99225 | F3: 130 | G3: 45665 | H3: 83.076923 | I3: 0.1096788 | J3: 54 | K3: 2.3152584
A4: =NFFT_M5[[#This Row],[country]]& " "&NFFT_M5[[#This Row],[cluster]] -> Japan 3 | B4: Japan | C4: 3 | D4: 3.804 | E4: 2314.4 | F4: 16 | G4: 34716 | H4: 25 | I4: 0.53511293 | J4: 2 | K4: 47.523614
A5: =NFFT_M5[[#This Row],[country]]& " "&NFFT_M5[[#This Row],[cluster]] -> Papua New Guinea 1 | B5: Papua New Guinea | C5: 1 | D5: 2.11 | E5: 330.02857 | F5: 141 | G5: 46204 | H5: 60 | I5: 0.10182727 | J5: 42 | K5: 3.0118966
A6: =NFFT_M5[[#This Row],[country]]& " "&NFFT_M5[[#This Row],[cluster]] -> Papua New Guinea 2 | B6: Papua New Guinea | C6: 2 | D6: 1.277 | E6: 572.73913 | F6: 47 | G6: 26346 | H6: 56.521739 | I6: 0.26694511 | J6: 13 | K6: 5.5485705
A7: =NFFT_M5[[#This Row],[country]]& " "&NFFT_M5[[#This Row],[cluster]] -> Papua New Guinea 3 | B7: Papua New Guinea | C7: 3 | D7: 5.586 | E7: 1194.6875 | F7: 33 | G7: 38230 | H7: 18.75 | I7: 0.21452924 | J7: 3 | K7: 34.889345
A8: =NFFT_M5[[#This Row],[country]]& " "&NFFT_M5[[#This Row],[cluster]] -> Philippines 1 | B8: Philippines | C8: 1 | D8: 1.602 | E8: 315.73611 | F8: 145 | G8: 45466 | H8: 77.777778 | I8: 0.19507018 | J8: 56 | K8: 2.2228415
A9: =NFFT_M5[[#This Row],[country]]& " "&NFFT_M5[[#This Row],[cluster]] -> Philippines 2 | B9: Philippines | C9: 2 | E9: 0 | F9: 0 | G9: 0 | H9: 0 | I9: 0 | J9: 0 | K9: 0
A10: =NFFT_M5[[#This Row],[country]]& " "&NFFT_M5[[#This Row],[cluster]] -> Tonga 1 | B10: Tonga | C10: 1 | D10: 1.431 | E10: 348.87597 | F10: 130 | G10: 45005 | H10: 86.153846 | I10: 0.15045955 | J10: 56 | K10: 2.2003031
A11: =NFFT_M5[[#This Row],[country]]& " "&NFFT_M5[[#This Row],[cluster]] -> USA 1 | B11: USA | C11: 1 | D11: 2.091 | E11: 327.15714 | F11: 141 | G11: 45802 | H11: 60 | I11: 0.16495632 | J11: 42 | K11: 2.9856915
A12: =NFFT_M5[[#This Row],[country]]& " "&NFFT_M5[[#This Row],[cluster]] -> USA 2 | B12: USA | C12: 2 | D12: 2.159 | E12: 368.93548 | F12: 125 | G12: 45748 | H12: 58.064516 | I12: 0.11406378 | J12: 36 | K12: 3.4791999
A13: =NFFT_M5[[#This Row],[country]]& " "&NFFT_M5[[#This Row],[cluster]] -> USA 3 | B13: USA | C13: 3 | D13: 2.673 | E13: 613.9863 | F13: 74 | G13: 44821 | H13: 45.945946 | I13: 0.1712495 | J13: 17 | K13: 7.2184241
A14: =NFFT_M5[[#This Row],[country]]& " "&NFFT_M5[[#This Row],[cluster]] -> Mexico 1 | B14: Mexico | C14: 1 | D14: 2.481 | E14: 365.10317 | F14: 127 | G14: 46003 | H14: 50.793651 | I14: 0.16985697 | J14: 32 | K14: 3.9359172
A15: =NFFT_M5[[#This Row],[country]]& " "&NFFT_M5[[#This Row],[cluster]] -> Mexico 2 | B15: Mexico | C15: 2 | D15: 3.091 | E15: 410.23636 | F15: 111 | G15: 45126 | H15: 40 | I15: 0.18585814 | J15: 22 | K15: 5.6158298
A16: =NFFT_M5[[#This Row],[country]]& " "&NFFT_M5[[#This Row],[cluster]] -> Mexico 3 | B16: Mexico | C16: 3 | D16: 1.879 | E16: 728 | F16: 50 | G16: 35672 | H16: 52 | I16: 0.15416022 | J16: 13 | K16: 7.5126626
A17: =NFFT_M5[[#This Row],[country]]& " "&NFFT_M5[[#This Row],[cluster]] -> Canada 1 | B17: Canada | C17: 1 | D17: 2.621 | E17: 457 | F17: 92 | G17: 41587 | H17: 43.478261 | I17: 0.14650077 | J17: 20 | K17: 5.69295
A18: =NFFT_M5[[#This Row],[country]]& " "&NFFT_M5[[#This Row],[cluster]] -> Canada 2 | B18: Canada | C18: 2 | E18: 1666.1176 | F18: 18 | G18: 28324 | H18: 0 | I18: 0 | J18: 0 | K18: 0
A19: =NFFT_M5[[#This Row],[country]]& " "&NFFT_M5[[#This Row],[cluster]] -> Canada 3 | B19: Canada | C19: 3 | E19: 0 | F19: 0 | G19: 0 | H19: 0 | I19: 0 | J19: 0 | K19: 0
A20: =NFFT_M5[[#This Row],[country]]& " "&NFFT_M5[[#This Row],[cluster]] -> Guatemala 1 | B20: Guatemala | C20: 1 | D20: 2.071 | E20: 458.13131 | F20: 100 | G20: 45355 | H20: 60 | I20: 0.1352419 | J20: 30 | K20: 4.1391741
A21: =NFFT_M5[[#This Row],[country]]& " "&NFFT_M5[[#This Row],[cluster]] -> Guatemala 2 | B21: Guatemala | C21: 2 | E21: 0 | F21: 0 | G21: 0 | H21: 0 | I21: 0 | J21: 0 | K21: 0
A22: =NFFT_M5[[#This Row],[country]]& " "&NFFT_M5[[#This Row],[cluster]] -> Russia 1 | B22: Russia | C22: 1 | D22: 1.54 | E22: 306.91946 | F22: 150 | G22: 45731 | H22: 81.333333 | I22: 0.11520888 | J22: 61 | K22: 2.0525353
A23: =NFFT_M5[[#This Row],[country]]& " "&NFFT_M5[[#This Row],[cluster]] -> Russia 2 | B23: Russia | C23: 2 | E23: 707.72308 | F23: 66 | G23: 46002 | H23: 0 | I23: 0 | J23: 0 | K23: 0
A24: =NFFT_M5[[#This Row],[country]]& " "&NFFT_M5[[#This Row],[cluster]] -> Russia 3 | B24: Russia | C24: 3 | D24: 4.546 | E24: 1180.1351 | F24: 38 | G24: 43665 | H24: 26.315789 | I24: 0.28219991 | J24: 5 | K24: 23.909651
A25: =NFFT_M5[[#This Row],[country]]& " "&NFFT_M5[[#This Row],[cluster]] -> China 1 | B25: China | C25: 1 | D25: 2.622 | E25: 445.84158 | F25: 102 | G25: 45030 | H25: 47.058824 | I25: 0.101602 | J25: 24 | K25: 5.1368925
A26: =NFFT_M5[[#This Row],[country]]& " "&NFFT_M5[[#This Row],[cluster]] -> China 2 | B26: China | C26: 2 | D26: 1.951 | E26: 593.83582 | F26: 68 | G26: 39787 | H26: 55.882353 | I26: 0.15627857 | J26: 19 | K26: 5.7332036
A27: =NFFT_M5[[#This Row],[country]]& " "&NFFT_M5[[#This Row],[cluster]] -> China 3 | B27: China | C27: 3 | D27: 2.241 | E27: 605.47541 | F27: 62 | G27: 36934 | H27: 45.16129 | I27: 0.23401227 | J27: 14 | K27: 7.2228415
A28: =NFFT_M5[[#This Row],[country]]& " "&NFFT_M5[[#This Row],[cluster]] -> India 1 | B28: India | C28: 1 | D28: 2.661 | E28: 433.67327 | F28: 102 | G28: 43801 | H28: 45.098039 | I28: 0.1193365 | J28: 23 | K28: 5.2139392
A29: =NFFT_M5[[#This Row],[country]]& " "&NFFT_M5[[#This Row],[cluster]] -> India 2 | B29: India | C29: 2 | D29: 2.17 | E29: 426.26471 | F29: 103 | G29: 43479 | H29: 54.901961 | I29: 0.11267656 | J29: 28 | K29: 4.2513934
A30: =NFFT_M5[[#This Row],[country]]& " "&NFFT_M5[[#This Row],[cluster]] -> India 3 | B30: India | C30: 3 | D30: 2.489 | E30: 574.76623 | F30: 78 | G30: 44257 | H30: 48.717949 | I30: 0.094689435 | J30: 19 | K30: 6.3773191
A31: =NFFT_M5[[#This Row],[country]]& " "&NFFT_M5[[#This Row],[cluster]] -> Iran 1 | B31: Iran | C31: 1 | D31: 2.157 | E31: 387.79825 | F31: 115 | G31: 44209 | H31: 56.140351 | I31: 0.10108108 | J31: 32 | K31: 3.7824264
A32: =NFFT_M5[[#This Row],[country]]& " "&NFFT_M5[[#This Row],[cluster]] -> Iran 2 | B32: Iran | C32: 2 | D32: 2.038 | E32: 676.29091 | F32: 56 | G32: 37196 | H32: 50 | I32: 0.14084506 | J32: 14 | K32: 7.2740784
A33: =NFFT_M5[[#This Row],[country]]& " "&NFFT_M5[[#This Row],[cluster]] -> Iran 3 | B33: Iran | C33: 3 | D33: 7.601 | E33: 1040.35 | F33: 41 | G33: 41614 | H33: 15 | I33: 0.45260185 | J33: 3 | K33: 37.977641
A34: =NFFT_M5[[#This Row],[country]]& " "&NFFT_M5[[#This Row],[cluster]] -> Nicaragua 1 | B34: Nicaragua | C34: 1 | D34: 2.762 | E34: 450.09901 | F34: 102 | G34: 45460 | H34: 45.098039 | I34: 0.12237186 | J34: 23 | K34: 5.4114216
A35: =NFFT_M5[[#This Row],[country]]& " "&NFFT_M5[[#This Row],[cluster]] -> El Salvador 1 | B35: El Salvador | C35: 1 | D35: 3.135 | E35: 514.2809 | F35: 90 | G35: 45771 | H35: 40 | I35: 0.13965082 | J35: 18 | K35: 6.9618982
... A37: =NFFT_M5[[#This Row],[country]]& " "&NFFT_M5[[#This Row],[cluster]] -> Dominican 1 | B37: Dominican | C37: 1 | D37: 2.228 | E37: 564.70833 | F37: 73 | G37: 40659 | H37: 50 | I37: 0.13092093 | J37: 18 | K37: 6.1843486
A38: =NFFT_M5[[#This Row],[country]]& " "&NFFT_M5[[#This Row],[cluster]] -> Dominican 2 | B38: Dominican | C38: 2 | E38: 0 | F38: 0 | G38: 0 | H38: 0 | I38: 0 | J38: 0 | K38: 0
A39: =NFFT_M5[[#This Row],[country]]& " "&NFFT_M5[[#This Row],[cluster]] -> Chile 1 | B39: Chile | C39: 1 | D39: 1.892 | E39: 345.94574 | F39: 130 | G39: 44627 | H39: 64.615385 | I39: 0.13434377 | J39: 42 | K39: 2.9090968
A40: =NFFT_M5[[#This Row],[country]]& " "&NFFT_M5[[#This Row],[cluster]] -> Chile 2 | B40: Chile | C40: 2 | D40: 1.748 | E40: 423.88608 | F40: 80 | G40: 33487 | H40: 52.5 | I40: 0.15265829 | J40: 21 | K40: 4.365829
A41: =NFFT_M5[[#This Row],[country]]& " "&NFFT_M5[[#This Row],[cluster]] -> Chile 3 | B41: Chile | C41: 3 | D41: 2.119 | E41: 543.20896 | F41: 68 | G41: 36395 | H41: 47.058824 | I41: 0.079839193 | J41: 16 | K41: 6.227755
...

Sheet NFFT_M6
B1: country | C1: cluster | D1: return_P_nomes | E1: avg_gap | F1: Number of record | G1: Number of the day | H1: percent | I1: highest_amplitude | J1: highest_frequency | K1: highest_years_not_normalised
A2: =NFFT_M6[[#This Row],[country]]& " "&NFFT_M6[[#This Row],[cluster]] -> Japan 1 | B2: Japan | C2: 1 | D2: 1.833 | E2: 327.62143 | F2: 141 | G2: 45867 | H2: 68.571429 | I2: 0.097099664 | J2: 48 | K2: 2.6161875
A3: =NFFT_M6[[#This Row],[country]]& " "&NFFT_M6[[#This Row],[cluster]] -> Japan 2 | B3: Japan | C3: 2 | D3: 2.743 | E3: 400.57018 | F3: 115 | G3: 45665 | H3: 45.614035 | I3: 0.22232004 | J3: 26 | K3: 4.8086137
A4: =NFFT_M6[[#This Row],[country]]& " "&NFFT_M6[[#This Row],[cluster]] -> Japan 3 | B4: Japan | C4: 3 | E4: 0 | F4: 0 | G4: 0 | H4: 0 | I4: 0 | J4: 0 | K4: 0
A5: =NFFT_M6[[#This Row],[country]]& " "&NFFT_M6[[#This Row],[cluster]] -> Papua New Guinea 1 | B5: Papua New Guinea | C5: 1 | D5: 2.11 | E5: 330.02857 | F5: 141 | G5: 46204 | H5: 60 | I5: 0.10182727 | J5: 42 | K5: 3.0118966
A6: =NFFT_M6[[#This Row],[country]]& " "&NFFT_M6[[#This Row],[cluster]] -> Papua New Guinea 2 | B6: Papua New Guinea | C6: 2 | E6: 2172.4545 | F6: 12 | G6: 23897 | H6: 0 | I6: 0 | J6: 0 | K6: 0
A7: =NFFT_M6[[#This Row],[country]]& " "&NFFT_M6[[#This Row],[cluster]] -> Papua New Guinea 3 | B7: Papua New Guinea | C7: 3 | E7: 0 | F7: 0 | G7: 0 | H7: 0 | I7: 0 | J7: 0 | K7: 0
A8: =NFFT_M6[[#This Row],[country]]& " "&NFFT_M6[[#This Row],[cluster]] -> Philippines 1 | B8: Philippines | C8: 1 | D8: 1.592 | E8: 329.46377 | F8: 139 | G8: 45466 | H8: 78.26087 | I8: 0.16746841 | J8: 54 | K8: 2.305169
A9: =NFFT_M6[[#This Row],[country]]& " "&NFFT_M6[[#This Row],[cluster]] -> Tonga 1 | B9: Tonga | C9: 1 | D9: 1.662 | E9: 362.94355 | F9: 125 | G9: 45005 | H9: 74.193548 | I9: 0.14347172 | J9: 46 | K9: 2.6786299
A10: =NFFT_M6[[#This Row],[country]]& " "&NFFT_M6[[#This Row],[cluster]] -> USA 1 | B10: USA | C10: 1 | D10: 1.804 | E10: 331.89855 | F10: 139 | G10: 45802 | H10: 69.565217 | I10: 0.12009597 | J10: 48 | K10: 2.61248
A11: =NFFT_M6[[#This Row],[country]]& " "&NFFT_M6[[#This Row],[cluster]] -> USA 2 | B11: USA | C11: 2 | D11: 2.322 | E11: 766.15254 | F11: 60 | G11: 45203 | H11: 53.333333 | I11: 0.30502141 | J11: 16 | K11: 7.7349418
A12: =NFFT_M6[[#This Row],[country]]& " "&NFFT_M6[[#This Row],[cluster]] -> USA 3 | B12: USA | C12: 3 | D12: 4.532 | E12: 1722.9583 | F12: 25 | G12: 41351 | H12: 25 | I12: 1.2044541 | J12: 3 | K12: 37.737623
A13: =NFFT_M6[[#This Row],[country]]& " "&NFFT_M6[[#This Row],[cluster]] -> Mexico 1 | B13: Mexico | C13: 1 | D13: 3.014 | E13: 422.04587 | F13: 110 | G13: 46003 | H13: 41.818182 | I13: 0.17896135 | J13: 23 | K13: 5.4760587
A14: =NFFT_M6[[#This Row],[country]]& " "&NFFT_M6[[#This Row],[cluster]] -> Mexico 2 | B14: Mexico | C14: 2 | D14: 2.335 | E14: 663.61765 | F14: 69 | G14: 45126 | H14: 52.941176 | I14: 0.23401214 | J14: 18 | K14: 6.8637919
A15: =NFFT_M6[[#This Row],[country]]& " "&NFFT_M6[[#This Row],[cluster]] -> Mexico 3 | B15: Mexico | C15: 3 | E15: 0 | F15: 0 | G15: 0 | H15: 0 | I15: 0 | J15: 0 | K15: 0
A16: =NFFT_M6[[#This Row],[country]]& " "&NFFT_M6[[#This Row],[cluster]] -> Canada 1 | B16: Canada | C16: 1 | D16: 2.848 | E16: 693.11667 | F16: 61 | G16: 41587 | H16: 40 | I16: 0.27464845 | J16: 12 | K16: 9.4882501
A17: =NFFT_M6[[#This Row],[country]]& " "&NFFT_M6[[#This Row],[cluster]] -> Canada 2 | B17: Canada | C17: 2 | E17: 0 | F17: 0 | G17: 0 | H17: 0 | I17: 0 | J17: 0 | K17: 0
A18: =NFFT_M6[[#This Row],[country]]& " "&NFFT_M6[[#This Row],[cluster]] -> Canada 3 | B18: Canada | C18: 3 | E18: 0 | F18: 0 | G18: 0 | H18: 0 | I18: 0 | J18: 0 | K18: 0
A19: =NFFT_M6[[#This Row],[country]]& " "&NFFT_M6[[#This Row],[cluster]] -> Guatemala 1 | B19: Guatemala | C19: 1 | D19: 2.78 | E19: 911.30612 | F19: 50 | G19: 44654 | H19: 44 | I19: 0.33498757 | J19: 11 | K19: 11.114181
A20: =NFFT_M6[[#This Row],[country]]& " "&NFFT_M6[[#This Row],[cluster]] -> Guatemala 2 | B20: Guatemala | C20: 2 | E20: 0 | F20: 0 | G20: 0 | H20: 0 | I20: 0 | J20: 0 | K20: 0
A21: =NFFT_M6[[#This Row],[country]]& " "&NFFT_M6[[#This Row],[cluster]] -> Russia 1 | B21: Russia | C21: 1 | D21: 1.905 | E21: 315.38621 | F21: 146 | G21: 45731 | H21: 65.753425 | I21: 0.13608879 | J21: 48 | K21: 2.6084303
A22: =NFFT_M6[[#This Row],[country]]& " "&NFFT_M6[[#This Row],[cluster]] -> Russia 2 | B22: Russia | C22: 2 | E22: 3790.1667 | F22: 13 | G22: 45482 | H22: 0 | I22: 0 | J22: 0 | K22: 0
A23: =NFFT_M6[[#This Row],[country]]& " "&NFFT_M6[[#This Row],[cluster]] -> Russia 3 | B23: Russia | C23: 3 | E23: 0 | F23: 0 | G23: 0 | H23: 0 | I23: 0 | J23: 0 | K23: 0
A24: =NFFT_M6[[#This Row],[country]]& " "&NFFT_M6[[#This Row],[cluster]] -> China 1 | B24: China | C24: 1 | D24: 6.683 | E24: 1031.3488 | F24: 44 | G24: 44348 | H24: 18.181818 | I24: 0.50129045 | J24: 4 | K24: 30.354552
A25: =NFFT_M6[[#This Row],[country]]& " "&NFFT_M6[[#This Row],[cluster]] -> China 2 | B25: China | C25: 2 | D25: 3.681 | E25: 2742 | F25: 15 | G25: 38388 | H25: 28.571429 | I25: 1.2335119 | J25: 2 | K25: 52.550308
A26: =NFFT_M6[[#This Row],[country]]& " "&NFFT_M6[[#This Row],[cluster]] -> China 3 | B26: China | C26: 3 | E26: 2342 | F26: 16 | G26: 35130 | H26: 0 | I26: 0 | J26: 0 | K26: 0
A27: =NFFT_M6[[#This Row],[country]]& " "&NFFT_M6[[#This Row],[cluster]] -> India 1 | B27: India | C27: 1 | D27: 4.606 | E27: 976.21951 | F27: 42 | G27: 40025 | H27: 23.809524 | I27: 0.73162699 | J27: 5 | K27: 21.916496
A28: =NFFT_M6[[#This Row],[country]]& " "&NFFT_M6[[#This Row],[cluster]] -> India 2 | B28: India | C28: 2 | D28: 4.589 | E28: 1308.7188 | F28: 33 | G28: 41879 | H28: 25 | I28: 1.3609532 | J28: 4 | K28: 28.664613
A29: =NFFT_M6[[#This Row],[country]]& " "&NFFT_M6[[#This Row],[cluster]] -> India 3 | B29: India | C29: 3 | E29: 0 | F29: 0 | G29: 0 | H29: 0 | I29: 0 | J29: 0 | K29: 0
A30: =NFFT_M6[[#This Row],[country]]& " "&NFFT_M6[[#This Row],[cluster]] -> Iran 1 | B30: Iran | C30: 1 | D30: 4.467 | E30: 1129.1316 | F30: 39 | G30: 42907 | H30: 26.315789 | I30: 0.37499574 | J30: 5 | K30: 23.494593
A31: =NFFT_M6[[#This Row],[country]]& " "&NFFT_M6[[#This Row],[cluster]] -> Iran 2 | B31: Iran | C31: 2 | E31: 0 | F31: 0 | G31: 0 | H31: 0 | I31: 0 | J31: 0 | K31: 0
A32: =NFFT_M6[[#This Row],[country]]& " "&NFFT_M6[[#This Row],[cluster]] -> Iran 3 | B32: Iran | C32: 3 | E32: 4327.1111 | F32: 10 | G32: 38944 | H32: 0 | I32: 0 | J32: 0 | K32: 0
A33: =NFFT_M6[[#This Row],[country]]& " "&NFFT_M6[[#This Row],[cluster]] -> Nicaragua 1 | B33: Nicaragua | C33: 1 | D33: 2.091 | E33: 846.63462 | F33: 53 | G33: 44025 | H33: 57.692308 | I33: 0.28976014 | J33: 15 | K33: 8.0355921
A34: =NFFT_M6[[#This Row],[country]]& " "&NFFT_M6[[#This Row],[cluster]] -> El Salvador 1 | B34: El Salvador | C34: 1 | D34: 5.307 | E34: 1340.5294 | F34: 35 | G34: 45578 | H34: 23.529412 | I34: 0.79886414 | J34: 4 | K34: 31.196441
A35: =NFFT_M6[[#This Row],[country]]& " "&NFFT_M6[[#This Row],[cluster]] -> Costa Rica 1 | B35: Costa Rica | C35: 1 | D35: 4.561 | E35: 1031.9091 | F35: 45 | G35: 45404 | H35: 27.272727 | I35: 0.46393669 | J35: 6 | K35: 20.71823
A36: =NFFT_M6[[#This Row],[country]]& " "&NFFT_M6[[#This Row],[cluster]] -> Dominican 1 | B36: Dominican | C36: 1 | E36: 1557.7619 | F36: 22 | G36: 32713 | H36: 0 | I36: 0 | J36: 0 | K36: 0
A37: =NFFT_M6[[#This Row],[country]]& " "&NFFT_M6[[#This Row],[cluster]] -> Chile 1 | B37: Chile | C37: 1 | D37: 2.983 | E37: 365.79508 | F37: 123 | G37: 44627 | H37: 40.983607 | I37: 0.17648094 | J37: 25 | K37: 4.8872827
A38: =NFFT_M6[[#This Row],[country]]& " "&NFFT_M6[[#This Row],[cluster]] -> Chile 2 | B38: Chile | C38: 2 | E38: 882.81081 | F38: 38 | G38: 32664 | H38: 0 | I38: 0 | J38: 0 | K38: 0
A39: =NFFT_M6[[#This Row],[country]]& " "&NFFT_M6[[#This Row],[cluster]] -> Chile 3 | B39: Chile | C39: 3 | E39: 0 | F39: 0 | G39: 0 | H39: 0 | I39: 0 | J39: 0 | K39: 0
A40: =NFFT_M6[[#This Row],[country]]& " "&NFFT_M6[[#This Row],[cluster]] -> Argentina 1 | B40: Argentina | C40: 1 | D40: 5.731 | E40: 1728.8636 | F40: 23 | G40: 38035 | H40: 18.181818 | I40: 0.90081162 | J40: 2 | K40: 52.067077
...

Sheet NFFT_M7
B1: country | C1: cluster | D1: return_P_nomes | E1: avg_gap | F1: Number of record | G1: Number of the day | H1: percent | I1: highest_amplitude | J1: highest_frequency | K1: highest_years_not_normalised
A2: =NFFT_M7[[#This Row],[country]]& " "&NFFT_M7[[#This Row],[cluster]] -> Japan 1 | B2: Japan | C2: 1 | D2: 2.587 | E2: 655.24286 | F2: 71 | G2: 45867 | H2: 48.571429 | I2: 0.30550783 | J2: 17 | K2: 7.3868825
A3: =NFFT_M7[[#This Row],[country]]& " "&NFFT_M7[[#This Row],[cluster]] -> Japan 2 | B3: Japan | C3: 2 | E3: 2044.1364 | F3: 23 | G3: 44971 | H3: 0 | I3: 0 | J3: 0 | K3: 0
A4: =NFFT_M7[[#This Row],[country]]& " "&NFFT_M7[[#This Row],[cluster]] -> Papua New Guinea 1 | B4: Papua New Guinea | C4: 1 | D4: 2.795 | E4: 661.85294 | F4: 69 | G4: 45006 | H4: 44.117647 | I4: 0.24160136 | J4: 15 | K4: 8.2146475
A5: =NFFT_M7[[#This Row],[country]]& " "&NFFT_M7[[#This Row],[cluster]] -> Philippines 1 | B5: Philippines | C5: 1 | D5: 2.491 | E5: 721.68254 | F5: 64 | G5: 45466 | H5: 50 | I5: 0.2555057 | J5: 16 | K5: 7.7799452
A6: =NFFT_M7[[#This Row],[country]]& " "&NFFT_M7[[#This Row],[cluster]] -> Tonga 1 | B6: Tonga | C6: 1 | D6: 4.192 | E6: 1363.7879 | F6: 34 | G6: 45005 | H6: 29.411765 | I6: 1.7315035 | J6: 5 | K6: 24.643395
A7: =NFFT_M7[[#This Row],[country]]& " "&NFFT_M7[[#This Row],[cluster]] -> USA 1 | B7: USA | C7: 1 | D7: 5.993 | E7: 969.59574 | F7: 48 | G7: 45571 | H7: 20.833333 | I7: 1.4382796 | J7: 5 | K7: 24.95332
A8: =NFFT_M7[[#This Row],[country]]& " "&NFFT_M7[[#This Row],[cluster]] -> USA 2 | B8: USA | C8: 2 | E8: 0 | F8: 0 | G8: 0 | H8: 0 | I8: 0 | J8: 0 | K8: 0
A9: =NFFT_M7[[#This Row],[country]]& " "&NFFT_M7[[#This Row],[cluster]] -> USA 3 | B9: USA | C9: 3 | E9: 0 | F9: 0 | G9: 0 | H9: 0 | I9: 0 | J9: 0 | K9: 0
A10: =NFFT_M7[[#This Row],[country]]& " "&NFFT_M7[[#This Row],[cluster]] -> Mexico 1 | B10: Mexico | C10: 1 | D10: 8.592 | E10: 1066.7143 | F10: 43 | G10: 44802 | H10: 14.285714 | I10: 1.6359608 | J10: 3 | K10: 40.887064
A11: =NFFT_M7[[#This Row],[country]]& " "&NFFT_M7[[#This Row],[cluster]] -> Mexico 2 | B11: Mexico | C11: 2 | E11: 0 | F11: 0 | G11: 0 | H11: 0 | I11: 0 | J11: 0 | K11: 0
A12: =NFFT_M7[[#This Row],[country]]& " "&NFFT_M7[[#This Row],[cluster]] -> Canada 1 | B12: Canada | C12: 1 | E12: 0 | F12: 0 | G12: 0 | H12: 0 | I12: 0 | J12: 0 | K12: 0
A13: =NFFT_M7[[#This Row],[country]]& " "&NFFT_M7[[#This Row],[cluster]] -> Guatemala 1 | B13: Guatemala | C13: 1 | E13: 0 | F13: 0 | G13: 0 | H13: 0 | I13: 0 | J13: 0 | K13: 0
A14: =NFFT_M7[[#This Row],[country]]& " "&NFFT_M7[[#This Row],[cluster]] -> Russia 1 | B14: Russia | C14: 1 | D14: 2.488 | E14: 825.56364 | F14: 56 | G14: 45406 | H14: 50 | I14: 0.4533563 | J14: 14 | K14: 8.8796323
A15: =NFFT_M7[[#This Row],[country]]& " "&NFFT_M7[[#This Row],[cluster]] -> Russia 2 | B15: Russia | C15: 2 | E15: 0 | F15: 0 | G15: 0 | H15: 0 | I15: 0 | J15: 0 | K15: 0
A16: =NFFT_M7[[#This Row],[country]]& " "&NFFT_M7[[#This Row],[cluster]] -> Russia 3 | B16: Russia | C16: 3 | E16: 0 | F16: 0 | G16: 0 | H16: 0 | I16: 0 | J16: 0 | K16: 0
A17: =NFFT_M7[[#This Row],[country]]& " "&NFFT_M7[[#This Row],[cluster]] -> China 1 | B17: China | C17: 1 | E17: 0 | F17: 0 | G17: 0 | H17: 0 | I17: 0 | J17: 0 | K17: 0
A18: =NFFT_M7[[#This Row],[country]]& " "&NFFT_M7[[#This Row],[cluster]] -> China 2 | B18: China | C18: 2 | E18: 0 | F18: 0 | G18: 0 | H18: 0 | I18: 0 | J18: 0 | K18: 0
A19: =NFFT_M7[[#This Row],[country]]& " "&NFFT_M7[[#This Row],[cluster]] -> India 1 | B19: India | C19: 1 | E19: 0 | F19: 0 | G19: 0 | H19: 0 | I19: 0 | J19: 0 | K19: 0
A20: =NFFT_M7[[#This Row],[country]]& " "&NFFT_M7[[#This Row],[cluster]] -> India 2 | B20: India | C20: 2 | E20: 0 | F20: 0 | G20: 0 | H20: 0 | I20: 0 | J20: 0 | K20: 0
A21: =NFFT_M7[[#This Row],[country]]& " "&NFFT_M7[[#This Row],[cluster]] -> Iran 1 | B21: Iran | C21: 1 | E21: 0 | F21: 0 | G21: 0 | H21: 0 | I21: 0 | J21: 0 | K21: 0
A22: =NFFT_M7[[#This Row],[country]]& " "&NFFT_M7[[#This Row],[cluster]] -> Iran 2 | B22: Iran | C22: 2 | E22: 0 | F22: 0 | G22: 0 | H22: 0 | I22: 0 | J22: 0 | K22: 0
A23: =NFFT_M7[[#This Row],[country]]& " "&NFFT_M7[[#This Row],[cluster]] -> Iran 3 | B23: Iran | C23: 3 | E23: 0 | F23: 1 | G23: 0 | H23: 0 | I23: 0 | J23: 0 | K23: 0
A24: =NFFT_M7[[#This Row],[country]]& " "&NFFT_M7[[#This Row],[cluster]] -> Nicaragua 1 | B24: Nicaragua | C24: 1 | E24: 0 | F24: 0 | G24: 0 | H24: 0 | I24: 0 | J24: 0 | K24: 0
A25: =NFFT_M7[[#This Row],[country]]& " "&NFFT_M7[[#This Row],[cluster]] -> El Salvador 1 | B25: El Salvador | C25: 1 | E25: 0 | F25: 0 | G25: 0 | H25: 0 | I25: 0 | J25: 0 | K25: 0
A26: =NFFT_M7[[#This Row],[country]]& " "&NFFT_M7[[#This Row],[cluster]] -> Costa Rica 1 | B26: Costa Rica | C26: 1 | E26: 4098.4 | F26: 11 | G26: 40984 | H26: 0 | I26: 0 | J26: 0 | K26: 0
A27: =NFFT_M7[[#This Row],[country]]& " "&NFFT_M7[[#This Row],[cluster]] -> Dominican 1 | B27: Dominican | C27: 1 | E27: 0 | F27: 0 | G27: 0 | H27: 0 | I27: 0 | J27: 0 | K27: 0
A28: =NFFT_M7[[#This Row],[country]]& " "&NFFT_M7[[#This Row],[cluster]] -> Chile 1 | B28: Chile | C28: 1 | D28: 6.623 | E28: 1022.1395 | F28: 44 | G28: 43952 | H28: 18.181818 | I28: 0.82056508 | J28: 4 | K28: 30.083504
A29: =NFFT_M7[[#This Row],[country]]& " "&NFFT_M7[[#This Row],[cluster]] -> Argentina 1 | B29: Argentina | C29: 1 | E29: 0 | F29: 0 | G29: 0 | H29: 0 | I29: 0 | J29: 0 | K29: 0
A30: =NFFT_M7[[#This Row],[country]]& " "&NFFT_M7[[#This Row],[cluster]] -> Argentina 2 | B30: Argentina | C30: 2 | E30: 0 | F30: 0 | G30: 0 | H30: 0 | I30: 0 | J30: 0 | K30: 0
A31: =NFFT_M7[[#This Row],[country]]& " "&NFFT_M7[[#This Row],[cluster]] -> Argentina 3 | B31: Argentina | C31: 3 | E31: 0 | F31: 0 | G31: 0 | H31: 0 | I31: 0 | J31: 0 | K31: 0
A32: =NFFT_M7[[#This Row],[country]]& " "&NFFT_M7[[#This Row],[cluster]] -> Peru 1 | B32: Peru | C32: 1 | D32: 3.142 | E32: 1344 | F32: 33 | G32: 43008 | H32: 37.5 | I32: 0.55247226 | J32: 6 | K32: 19.624914
A33: =NFFT_M7[[#This Row],[country]]& " "&NFFT_M7[[#This Row],[cluster]] -> Colombia 1 | B33: Colombia | C33: 1 | E33: 0 | F33: 0 | G33: 0 | H33: 0 | I33: 0 | J33: 0 | K33: 0
A34: =NFFT_M7[[#This Row],[country]]& " "&NFFT_M7[[#This Row],[cluster]] -> Colombia 2 | B34: Colombia | C34: 2 | E34: 0 | F34: 0 | G34: 0 | H34: 0 | I34: 0 | J34: 0 | K34: 0
A35: =NFFT_M7[[#This Row],[country]]& " "&NFFT_M7[[#This Row],[cluster]] -> Indonesia 1 | B35: Indonesia | C35: 1 | D35: 2.925 | E35: 523.94318 | F35: 89 | G35: 46107 | H35: 43.181818 | I35: 0.25249496 | J35: 19 | K35: 6.6438993
A36: =NFFT_M7[[#This Row],[country]]& " "&NFFT_M7[[#This Row],[cluster]] -> Timor Leste 1 | B36: Timor Leste | C36: 1 | E36: 0 | F36: 0 | G36: 0 | H36: 0 | I36: 0 | J36: 0 | K36: 0
A37: =NFFT_M7[[#This Row],[country]]& " "&NFFT_M7[[#This Row],[cluster]] -> Australia 3 | B37: Australia | C37: 3 | E37: 0 | F37: 0 | G37: 0 | H37: 0 | I37: 0 | J37: 0 | K37: 0
A38: =NFFT_M7[[#This Row],[country]]& " "&NFFT_M7[[#This Row],[cluster]] -> New Zealand 1 | B38: New Zealand | C38: 1 | D38: 4.798 | E38: 1211.9706 | F38: 35 | G38: 41207 | H38: 23.529412 | I38: 1.4968687 | J38: 4 | K38: 28.204654
A39: =NFFT_M7[[#This Row],[country]]& " "&NFFT_M7[[#This Row],[cluster]] -> New Zealand 2 | B39: New Zealand | C39: 2 | E39: 2577.9 | F39: 11 | G39: 25779 | H39: 0 | I39: 0 | J39: 0 | K39: 0
A40: =NFFT_M7[[#This Row],[country]]& " "&NFFT_M7[[#This Row],[cluster]] -> Algeria 1 | B40: Algeria | C40: 1 | E40: 0 | F40: 0 | G40: 0 | H40: 0 | I40: 0 | J40: 0 | K40: 0
...

Sheet NFFT_M8
B1: country | C1: cluster | D1: return_P_nomes | E1: avg_gap | F1: Number of record | G1: Number of the day | H1: percent | I1: highest_amplitude | J1: highest_frequency | K1: highest_years_not_normalised
A2: =NFFT_M8[[#This Row],[country]]& " "&NFFT_M8[[#This Row],[cluster]] -> Japan 1 | B2: Japan | C2: 1 | E2: 0 | F2: 0 | G2: 0 | H2: 0 | I2: 0 | J2: 0 | K2: 0
A3: =NFFT_M8[[#This Row],[country]]& " "&NFFT_M8[[#This Row],[cluster]] -> Japan 2 | B3: Japan | C3: 2 | E3: 0 | F3: 0 | G3: 0 | H3: 0 | I3: 0 | J3: 0 | K3: 0
A4: =NFFT_M8[[#This Row],[country]]& " "&NFFT_M8[[#This Row],[cluster]] -> Papua New Guinea 1 | B4: Papua New Guinea | C4: 1 | E4: 0 | F4: 0 | G4: 0 | H4: 0 | I4: 0 | J4: 0 | K4: 0
A5: =NFFT_M8[[#This Row],[country]]& " "&NFFT_M8[[#This Row],[cluster]] -> Philippines 1 | B5: Philippines | C5: 1 | E5: 0 | F5: 0 | G5: 0 | H5: 0 | I5: 0 | J5: 0 | K5: 0
A6: =NFFT_M8[[#This Row],[country]]& " "&NFFT_M8[[#This Row],[cluster]] -> Tonga 1 | B6: Tonga | C6: 1 | E6: 0 | F6: 0 | G6: 0 | H6: 0 | I6: 0 | J6: 0 | K6: 0
A7: =NFFT_M8[[#This Row],[country]]& " "&NFFT_M8[[#This Row],[cluster]] -> USA 1 | B7: USA | C7: 1 | E7: 0 | F7: 0 | G7: 0 | H7: 0 | I7: 0 | J7: 0 | K7: 0
A8: =NFFT_M8[[#This Row],[country]]& " "&NFFT_M8[[#This Row],[cluster]] -> Mexico 1 | B8: Mexico | C8: 1 | E8: 0 | F8: 0 | G8: 0 | H8: 0 | I8: 0 | J8: 0 | K8: 0
A9: =NFFT_M8[[#This Row],[country]]& " "&NFFT_M8[[#This Row],[cluster]] -> Canada 1 | B9: Canada | C9: 1 | E9: 0 | F9: 0 | G9: 0 | H9: 0 | I9: 0 | J9: 0 | K9: 0
A10: =NFFT_M8[[#This Row],[country]]& " "&NFFT_M8[[#This Row],[cluster]] -> Guatemala 1 | B10: Guatemala | C10: 1 | E10: 0 | F10: 0 | G10: 0 | H10: 0 | I10: 0 | J10: 0 | K10: 0
A11: =NFFT_M8[[#This Row],[country]]& " "&NFFT_M8[[#This Row],[cluster]] -> Russia 1 | B11: Russia | C11: 1 | E11: 0 | F11: 0 | G11: 0 | H11: 0 | I11: 0 | J11: 0 | K11: 0
A12: =NFFT_M8[[#This Row],[country]]& " "&NFFT_M8[[#This Row],[cluster]] -> China 1 | B12: China | C12: 1 | E12: 0 | F12: 0 | G12: 0 | H12: 0 | I12: 0 | J12: 0 | K12: 0
A13: =NFFT_M8[[#This Row],[country]]& " "&NFFT_M8[[#This Row],[cluster]] -> China 2 | B13: China | C13: 2 | E13: 0 | F13: 0 | G13: 0 | H13: 0 | I13: 0 | J13: 0 | K13: 0
... A41: =NFFT_M8[[#This Row],[country]]& " "&NFFT_M8[[#This Row],[cluster]] -> Saint Helena 1 | B41: Saint Helena | C41: 1 | E41: 0 | F41: 0 | G41: 0 | H41: 0 | I41: 0 | J41: 0 | K41: 0
